[2025-05-24T11:55:47.504+0000] {taskinstance.py:1956} INFO - Dependencies all met for dep_context=non-requeueable deps ti=<TaskInstance: marketing_data_pipeline.validate_contacts manual__2025-05-24T11:54:05.852402+00:00 [queued]>
[2025-05-24T11:55:47.560+0000] {taskinstance.py:1956} INFO - Dependencies all met for dep_context=requeueable deps ti=<TaskInstance: marketing_data_pipeline.validate_contacts manual__2025-05-24T11:54:05.852402+00:00 [queued]>
[2025-05-24T11:55:47.561+0000] {taskinstance.py:2170} INFO - Starting attempt 1 of 2
[2025-05-24T11:55:47.607+0000] {taskinstance.py:2191} INFO - Executing <Task(PythonOperator): validate_contacts> on 2025-05-24 11:54:05.852402+00:00
[2025-05-24T11:55:47.624+0000] {standard_task_runner.py:60} INFO - Started process 281 to run task
[2025-05-24T11:55:47.663+0000] {standard_task_runner.py:87} INFO - Running: ['***', 'tasks', 'run', 'marketing_data_pipeline', 'validate_contacts', 'manual__2025-05-24T11:54:05.852402+00:00', '--job-id', '9', '--raw', '--subdir', 'DAGS_FOLDER/main_pipeline_dag.py', '--cfg-path', '/tmp/tmp6il1k0zt']
[2025-05-24T11:55:47.675+0000] {standard_task_runner.py:88} INFO - Job 9: Subtask validate_contacts
[2025-05-24T11:55:48.119+0000] {task_command.py:423} INFO - Running <TaskInstance: marketing_data_pipeline.validate_contacts manual__2025-05-24T11:54:05.852402+00:00 [running]> on host 26b7ede39e62
[2025-05-24T11:55:48.593+0000] {taskinstance.py:2480} INFO - Exporting env vars: AIRFLOW_CTX_DAG_EMAIL='yashbhawsar872@gmail.com' AIRFLOW_CTX_DAG_OWNER='Yash' AIRFLOW_CTX_DAG_ID='marketing_data_pipeline' AIRFLOW_CTX_TASK_ID='validate_contacts' AIRFLOW_CTX_EXECUTION_DATE='2025-05-24T11:54:05.852402+00:00' AIRFLOW_CTX_TRY_NUMBER='1' AIRFLOW_CTX_DAG_RUN_ID='manual__2025-05-24T11:54:05.852402+00:00'
[2025-05-24T11:55:48.603+0000] {main_pipeline_dag.py:25} INFO - ▶️ Starting task: Validate Contacts
[2025-05-24T11:55:51.482+0000] {taskinstance.py:2698} ERROR - Task failed with exception
Traceback (most recent call last):
  File "/opt/airflow/scripts/data_validation.py", line 89, in _validate_generic
    validate_schema_and_format(df, required_cols, filename)
  File "/opt/airflow/scripts/data_validation.py", line 45, in validate_schema_and_format
    log_dq_result(filename, "schema_format", "PASS", f"Got cols {list(df.columns)}")
  File "/opt/airflow/scripts/metadata.py", line 139, in log_dq_result
    c.execute("""
sqlite3.OperationalError: 4 values for 5 columns

During handling of the above exception, another exception occurred:

Traceback (most recent call last):
  File "/home/airflow/.local/lib/python3.10/site-packages/airflow/models/taskinstance.py", line 433, in _execute_task
    result = execute_callable(context=context, **execute_callable_kwargs)
  File "/home/airflow/.local/lib/python3.10/site-packages/airflow/operators/python.py", line 199, in execute
    return_value = self.execute_callable()
  File "/home/airflow/.local/lib/python3.10/site-packages/airflow/operators/python.py", line 216, in execute_callable
    return self.python_callable(*self.op_args, **self.op_kwargs)
  File "/opt/airflow/dags/main_pipeline_dag.py", line 26, in _wrapped
    fn(**kwargs)
  File "/opt/airflow/scripts/utils.py", line 23, in wrapper
    result = func(*args, **kwargs)
  File "/opt/airflow/scripts/data_validation.py", line 179, in validate_contacts_if_needed
    return _validate_generic(
  File "/opt/airflow/scripts/data_validation.py", line 94, in _validate_generic
    log_dq_result(filename, 'file-level', "FAIL", file_fail_msg)
  File "/opt/airflow/scripts/metadata.py", line 139, in log_dq_result
    c.execute("""
sqlite3.OperationalError: 4 values for 5 columns
[2025-05-24T11:55:51.666+0000] {taskinstance.py:1138} INFO - Marking task as UP_FOR_RETRY. dag_id=marketing_data_pipeline, task_id=validate_contacts, execution_date=20250524T115405, start_date=20250524T115547, end_date=20250524T115551
[2025-05-24T11:55:51.741+0000] {standard_task_runner.py:107} ERROR - Failed to execute job 9 for task validate_contacts (4 values for 5 columns; 281)
[2025-05-24T11:55:51.818+0000] {local_task_job_runner.py:234} INFO - Task exited with return code 1
[2025-05-24T11:55:52.067+0000] {taskinstance.py:3280} INFO - 0 downstream tasks scheduled from follow-on schedule check
