[2025-05-24T07:31:22.285+0000] {taskinstance.py:1956} INFO - Dependencies all met for dep_context=non-requeueable deps ti=<TaskInstance: marketing_data_pipeline.generate_form_fills scheduled__2025-05-23T00:00:00+00:00 [queued]>
[2025-05-24T07:31:22.366+0000] {taskinstance.py:1956} INFO - Dependencies all met for dep_context=requeueable deps ti=<TaskInstance: marketing_data_pipeline.generate_form_fills scheduled__2025-05-23T00:00:00+00:00 [queued]>
[2025-05-24T07:31:22.369+0000] {taskinstance.py:2170} INFO - Starting attempt 2 of 2
[2025-05-24T07:31:22.539+0000] {taskinstance.py:2191} INFO - Executing <Task(PythonOperator): generate_form_fills> on 2025-05-23 00:00:00+00:00
[2025-05-24T07:31:22.556+0000] {standard_task_runner.py:60} INFO - Started process 806 to run task
[2025-05-24T07:31:22.580+0000] {standard_task_runner.py:87} INFO - Running: ['***', 'tasks', 'run', 'marketing_data_pipeline', 'generate_form_fills', 'scheduled__2025-05-23T00:00:00+00:00', '--job-id', '20', '--raw', '--subdir', 'DAGS_FOLDER/main_pipeline_dag.py', '--cfg-path', '/tmp/tmpzugw_jje']
[2025-05-24T07:31:22.600+0000] {standard_task_runner.py:88} INFO - Job 20: Subtask generate_form_fills
[2025-05-24T07:31:23.346+0000] {task_command.py:423} INFO - Running <TaskInstance: marketing_data_pipeline.generate_form_fills scheduled__2025-05-23T00:00:00+00:00 [running]> on host fcb3825e40cf
[2025-05-24T07:31:24.199+0000] {taskinstance.py:2480} INFO - Exporting env vars: AIRFLOW_CTX_DAG_EMAIL='yashbhawsar872@gmail.com' AIRFLOW_CTX_DAG_OWNER='Yash' AIRFLOW_CTX_DAG_ID='marketing_data_pipeline' AIRFLOW_CTX_TASK_ID='generate_form_fills' AIRFLOW_CTX_EXECUTION_DATE='2025-05-23T00:00:00+00:00' AIRFLOW_CTX_TRY_NUMBER='2' AIRFLOW_CTX_DAG_RUN_ID='scheduled__2025-05-23T00:00:00+00:00'
[2025-05-24T07:31:24.209+0000] {main_pipeline_dag.py:25} INFO - ‚ñ∂Ô∏è Starting task: Generate Form Fills
[2025-05-24T07:31:24.308+0000] {taskinstance.py:2698} ERROR - Task failed with exception
Traceback (most recent call last):
  File "/home/airflow/.local/lib/python3.10/site-packages/airflow/models/taskinstance.py", line 433, in _execute_task
    result = execute_callable(context=context, **execute_callable_kwargs)
  File "/home/airflow/.local/lib/python3.10/site-packages/airflow/operators/python.py", line 199, in execute
    return_value = self.execute_callable()
  File "/home/airflow/.local/lib/python3.10/site-packages/airflow/operators/python.py", line 216, in execute_callable
    return self.python_callable(*self.op_args, **self.op_kwargs)
  File "/opt/airflow/dags/main_pipeline_dag.py", line 26, in _wrapped
    fn(**kwargs)
  File "/opt/airflow/scripts/data_generation.py", line 33, in generate_form_fills_if_needed
    if not check_stage_complete(file_name, "generated"):
  File "/opt/airflow/scripts/metadata.py", line 119, in check_stage_complete
    c.execute(f"SELECT {stage}_at FROM file_metadata WHERE file_name = ?", (file_name,))
sqlite3.OperationalError: no such column: generated_at
[2025-05-24T07:31:24.437+0000] {taskinstance.py:1138} INFO - Marking task as FAILED. dag_id=marketing_data_pipeline, task_id=generate_form_fills, execution_date=20250523T000000, start_date=20250524T073122, end_date=20250524T073124
[2025-05-24T07:31:24.442+0000] {email_notification.py:54} WARNING - üìß Sending generic failure email [Airflow] Failure in marketing_data_pipeline.generate_form_fills (Attempt 3/1)
[2025-05-24T07:31:24.489+0000] {logging_mixin.py:188} WARNING - /home/***/.local/lib/python3.10/site-packages/***/utils/email.py:154 RemovedInAirflow3Warning: Fetching SMTP credentials from configuration variables will be deprecated in a future release. Please set credentials using a connection instead.
[2025-05-24T07:31:24.491+0000] {email.py:270} INFO - Email alerting: attempt 1
[2025-05-24T07:31:26.358+0000] {email.py:281} INFO - Sent an alert email to ['yashbhawsar872@gmail.com']
[2025-05-24T07:31:28.407+0000] {standard_task_runner.py:107} ERROR - Failed to execute job 20 for task generate_form_fills (no such column: generated_at; 806)
[2025-05-24T07:31:28.507+0000] {local_task_job_runner.py:234} INFO - Task exited with return code 1
[2025-05-24T07:31:28.781+0000] {taskinstance.py:3280} INFO - 0 downstream tasks scheduled from follow-on schedule check
