[2025-05-25T05:35:46.102+0000] {taskinstance.py:1956} INFO - Dependencies all met for dep_context=non-requeueable deps ti=<TaskInstance: marketing_data_pipeline.dbt_run_staging manual__2025-05-25T05:27:20.358267+00:00 [queued]>
[2025-05-25T05:35:46.164+0000] {taskinstance.py:1956} INFO - Dependencies all met for dep_context=requeueable deps ti=<TaskInstance: marketing_data_pipeline.dbt_run_staging manual__2025-05-25T05:27:20.358267+00:00 [queued]>
[2025-05-25T05:35:46.166+0000] {taskinstance.py:2170} INFO - Starting attempt 2 of 2
[2025-05-25T05:35:46.242+0000] {taskinstance.py:2191} INFO - Executing <Task(BashOperator): dbt_run_staging> on 2025-05-25 05:27:20.358267+00:00
[2025-05-25T05:35:46.258+0000] {standard_task_runner.py:60} INFO - Started process 3647 to run task
[2025-05-25T05:35:46.275+0000] {standard_task_runner.py:87} INFO - Running: ['***', 'tasks', 'run', 'marketing_data_pipeline', 'dbt_run_staging', 'manual__2025-05-25T05:27:20.358267+00:00', '--job-id', '16', '--raw', '--subdir', 'DAGS_FOLDER/main_pipeline_dag.py', '--cfg-path', '/tmp/tmpcr25ywk1']
[2025-05-25T05:35:46.280+0000] {standard_task_runner.py:88} INFO - Job 16: Subtask dbt_run_staging
[2025-05-25T05:35:46.466+0000] {task_command.py:423} INFO - Running <TaskInstance: marketing_data_pipeline.dbt_run_staging manual__2025-05-25T05:27:20.358267+00:00 [running]> on host 0b3688707aa0
[2025-05-25T05:35:46.904+0000] {taskinstance.py:2480} INFO - Exporting env vars: AIRFLOW_CTX_DAG_EMAIL='yashbhawsar872@gmail.com' AIRFLOW_CTX_DAG_OWNER='Yash' AIRFLOW_CTX_DAG_ID='marketing_data_pipeline' AIRFLOW_CTX_TASK_ID='dbt_run_staging' AIRFLOW_CTX_EXECUTION_DATE='2025-05-25T05:27:20.358267+00:00' AIRFLOW_CTX_TRY_NUMBER='2' AIRFLOW_CTX_DAG_RUN_ID='manual__2025-05-25T05:27:20.358267+00:00'
[2025-05-25T05:35:46.916+0000] {subprocess.py:63} INFO - Tmp dir root location: /tmp
[2025-05-25T05:35:46.936+0000] {subprocess.py:75} INFO - Running command: ['/usr/bin/bash', '-c', 'cd /opt/dbt/marketing_pipeline && dbt run --models staging --vars \'{"batch_date": "2025-05-25"}\'']
[2025-05-25T05:35:47.011+0000] {subprocess.py:86} INFO - Output:
[2025-05-25T05:35:52.264+0000] {subprocess.py:93} INFO - [0m05:35:52  Encountered an error:
[2025-05-25T05:35:52.266+0000] {subprocess.py:93} INFO - [Errno 30] Read-only file system: '/opt/dbt/marketing_pipeline/logs/dbt.log'
[2025-05-25T05:35:52.271+0000] {subprocess.py:93} INFO - [0m05:35:52  Traceback (most recent call last):
[2025-05-25T05:35:52.273+0000] {subprocess.py:93} INFO -   File "/home/***/.local/lib/python3.10/site-packages/dbt/cli/requires.py", line 153, in wrapper
[2025-05-25T05:35:52.275+0000] {subprocess.py:93} INFO -     result, success = func(*args, **kwargs)
[2025-05-25T05:35:52.276+0000] {subprocess.py:93} INFO -   File "/home/***/.local/lib/python3.10/site-packages/dbt/cli/requires.py", line 79, in wrapper
[2025-05-25T05:35:52.278+0000] {subprocess.py:93} INFO -     setup_event_logger(flags=flags, callbacks=callbacks)
[2025-05-25T05:35:52.280+0000] {subprocess.py:93} INFO -   File "/home/***/.local/lib/python3.10/site-packages/dbt/events/logging.py", line 100, in setup_event_logger
[2025-05-25T05:35:52.281+0000] {subprocess.py:93} INFO -     add_logger_to_manager(
[2025-05-25T05:35:52.282+0000] {subprocess.py:93} INFO -   File "/home/***/.local/lib/python3.10/site-packages/dbt_common/events/event_manager_client.py", line 15, in add_logger_to_manager
[2025-05-25T05:35:52.284+0000] {subprocess.py:93} INFO -     _EVENT_MANAGER.add_logger(logger)
[2025-05-25T05:35:52.285+0000] {subprocess.py:93} INFO -   File "/home/***/.local/lib/python3.10/site-packages/dbt_common/events/event_manager.py", line 88, in add_logger
[2025-05-25T05:35:52.287+0000] {subprocess.py:93} INFO -     _JsonLogger(config) if config.line_format == LineFormat.Json else _TextLogger(config)
[2025-05-25T05:35:52.288+0000] {subprocess.py:93} INFO -   File "/home/***/.local/lib/python3.10/site-packages/dbt_common/events/logger.py", line 147, in __init__
[2025-05-25T05:35:52.291+0000] {subprocess.py:93} INFO -     super().__init__(config)
[2025-05-25T05:35:52.292+0000] {subprocess.py:93} INFO -   File "/home/***/.local/lib/python3.10/site-packages/dbt_common/events/logger.py", line 107, in __init__
[2025-05-25T05:35:52.293+0000] {subprocess.py:93} INFO -     file_handler = RotatingFileHandler(
[2025-05-25T05:35:52.295+0000] {subprocess.py:93} INFO -   File "/usr/local/lib/python3.10/logging/handlers.py", line 155, in __init__
[2025-05-25T05:35:52.296+0000] {subprocess.py:93} INFO -     BaseRotatingHandler.__init__(self, filename, mode, encoding=encoding,
[2025-05-25T05:35:52.298+0000] {subprocess.py:93} INFO -   File "/usr/local/lib/python3.10/logging/handlers.py", line 58, in __init__
[2025-05-25T05:35:52.299+0000] {subprocess.py:93} INFO -     logging.FileHandler.__init__(self, filename, mode=mode,
[2025-05-25T05:35:52.301+0000] {subprocess.py:93} INFO -   File "/usr/local/lib/python3.10/logging/__init__.py", line 1169, in __init__
[2025-05-25T05:35:52.302+0000] {subprocess.py:93} INFO -     StreamHandler.__init__(self, self._open())
[2025-05-25T05:35:52.303+0000] {subprocess.py:93} INFO -   File "/usr/local/lib/python3.10/logging/__init__.py", line 1201, in _open
[2025-05-25T05:35:52.305+0000] {subprocess.py:93} INFO -     return open_func(self.baseFilename, self.mode,
[2025-05-25T05:35:52.307+0000] {subprocess.py:93} INFO - OSError: [Errno 30] Read-only file system: '/opt/dbt/marketing_pipeline/logs/dbt.log'
[2025-05-25T05:35:52.309+0000] {subprocess.py:93} INFO - 
[2025-05-25T05:35:52.769+0000] {subprocess.py:97} INFO - Command exited with return code 2
[2025-05-25T05:35:52.816+0000] {taskinstance.py:2698} ERROR - Task failed with exception
Traceback (most recent call last):
  File "/home/airflow/.local/lib/python3.10/site-packages/airflow/models/taskinstance.py", line 433, in _execute_task
    result = execute_callable(context=context, **execute_callable_kwargs)
  File "/home/airflow/.local/lib/python3.10/site-packages/airflow/operators/bash.py", line 212, in execute
    raise AirflowException(
airflow.exceptions.AirflowException: Bash command failed. The command returned a non-zero exit code 2.
[2025-05-25T05:35:52.825+0000] {taskinstance.py:1138} INFO - Marking task as FAILED. dag_id=marketing_data_pipeline, task_id=dbt_run_staging, execution_date=20250525T052720, start_date=20250525T053546, end_date=20250525T053552
[2025-05-25T05:35:52.826+0000] {taskinstance.py:1116} ERROR - Error when executing notify_failure callback
Traceback (most recent call last):
  File "/home/airflow/.local/lib/python3.10/site-packages/airflow/models/taskinstance.py", line 2334, in _run_raw_task
    self._execute_task_with_callbacks(context, test_mode, session=session)
  File "/home/airflow/.local/lib/python3.10/site-packages/airflow/models/taskinstance.py", line 2499, in _execute_task_with_callbacks
    result = self._execute_task(context, task_orig)
  File "/home/airflow/.local/lib/python3.10/site-packages/airflow/models/taskinstance.py", line 2516, in _execute_task
    return _execute_task(self, context, task_orig)
  File "/home/airflow/.local/lib/python3.10/site-packages/airflow/models/taskinstance.py", line 433, in _execute_task
    result = execute_callable(context=context, **execute_callable_kwargs)
  File "/home/airflow/.local/lib/python3.10/site-packages/airflow/operators/bash.py", line 212, in execute
    raise AirflowException(
airflow.exceptions.AirflowException: Bash command failed. The command returned a non-zero exit code 2.

During handling of the above exception, another exception occurred:

Traceback (most recent call last):
  File "/home/airflow/.local/lib/python3.10/site-packages/airflow/models/taskinstance.py", line 1113, in _run_finished_callback
    callback(context)
TypeError: notify_failure() takes 0 positional arguments but 1 was given
[2025-05-25T05:35:52.863+0000] {standard_task_runner.py:107} ERROR - Failed to execute job 16 for task dbt_run_staging (Bash command failed. The command returned a non-zero exit code 2.; 3647)
[2025-05-25T05:35:52.906+0000] {local_task_job_runner.py:234} INFO - Task exited with return code 1
[2025-05-25T05:35:52.965+0000] {taskinstance.py:3280} INFO - 0 downstream tasks scheduled from follow-on schedule check
