[2025-05-25T05:30:30.072+0000] {taskinstance.py:1956} INFO - Dependencies all met for dep_context=non-requeueable deps ti=<TaskInstance: marketing_data_pipeline.dbt_run_staging manual__2025-05-25T05:27:20.358267+00:00 [queued]>
[2025-05-25T05:30:30.108+0000] {taskinstance.py:1956} INFO - Dependencies all met for dep_context=requeueable deps ti=<TaskInstance: marketing_data_pipeline.dbt_run_staging manual__2025-05-25T05:27:20.358267+00:00 [queued]>
[2025-05-25T05:30:30.109+0000] {taskinstance.py:2170} INFO - Starting attempt 1 of 2
[2025-05-25T05:30:30.150+0000] {taskinstance.py:2191} INFO - Executing <Task(BashOperator): dbt_run_staging> on 2025-05-25 05:27:20.358267+00:00
[2025-05-25T05:30:30.168+0000] {standard_task_runner.py:60} INFO - Started process 3528 to run task
[2025-05-25T05:30:30.177+0000] {standard_task_runner.py:87} INFO - Running: ['***', 'tasks', 'run', 'marketing_data_pipeline', 'dbt_run_staging', 'manual__2025-05-25T05:27:20.358267+00:00', '--job-id', '15', '--raw', '--subdir', 'DAGS_FOLDER/main_pipeline_dag.py', '--cfg-path', '/tmp/tmptgm2v2b0']
[2025-05-25T05:30:30.183+0000] {standard_task_runner.py:88} INFO - Job 15: Subtask dbt_run_staging
[2025-05-25T05:30:30.354+0000] {task_command.py:423} INFO - Running <TaskInstance: marketing_data_pipeline.dbt_run_staging manual__2025-05-25T05:27:20.358267+00:00 [running]> on host 0b3688707aa0
[2025-05-25T05:30:31.156+0000] {taskinstance.py:2480} INFO - Exporting env vars: AIRFLOW_CTX_DAG_EMAIL='yashbhawsar872@gmail.com' AIRFLOW_CTX_DAG_OWNER='Yash' AIRFLOW_CTX_DAG_ID='marketing_data_pipeline' AIRFLOW_CTX_TASK_ID='dbt_run_staging' AIRFLOW_CTX_EXECUTION_DATE='2025-05-25T05:27:20.358267+00:00' AIRFLOW_CTX_TRY_NUMBER='1' AIRFLOW_CTX_DAG_RUN_ID='manual__2025-05-25T05:27:20.358267+00:00'
[2025-05-25T05:30:31.171+0000] {subprocess.py:63} INFO - Tmp dir root location: /tmp
[2025-05-25T05:30:31.174+0000] {subprocess.py:75} INFO - Running command: ['/usr/bin/bash', '-c', 'cd /opt/dbt/marketing_pipeline && dbt run --models staging --vars \'{"batch_date": "2025-05-25"}\'']
[2025-05-25T05:30:31.224+0000] {subprocess.py:86} INFO - Output:
[2025-05-25T05:30:38.953+0000] {subprocess.py:93} INFO - [0m05:30:38  Encountered an error:
[2025-05-25T05:30:38.955+0000] {subprocess.py:93} INFO - [Errno 30] Read-only file system: '/opt/dbt/marketing_pipeline/logs/dbt.log'
[2025-05-25T05:30:38.971+0000] {subprocess.py:93} INFO - [0m05:30:38  Traceback (most recent call last):
[2025-05-25T05:30:38.972+0000] {subprocess.py:93} INFO -   File "/home/***/.local/lib/python3.10/site-packages/dbt/cli/requires.py", line 153, in wrapper
[2025-05-25T05:30:38.973+0000] {subprocess.py:93} INFO -     result, success = func(*args, **kwargs)
[2025-05-25T05:30:38.974+0000] {subprocess.py:93} INFO -   File "/home/***/.local/lib/python3.10/site-packages/dbt/cli/requires.py", line 79, in wrapper
[2025-05-25T05:30:38.976+0000] {subprocess.py:93} INFO -     setup_event_logger(flags=flags, callbacks=callbacks)
[2025-05-25T05:30:38.977+0000] {subprocess.py:93} INFO -   File "/home/***/.local/lib/python3.10/site-packages/dbt/events/logging.py", line 100, in setup_event_logger
[2025-05-25T05:30:38.978+0000] {subprocess.py:93} INFO -     add_logger_to_manager(
[2025-05-25T05:30:38.979+0000] {subprocess.py:93} INFO -   File "/home/***/.local/lib/python3.10/site-packages/dbt_common/events/event_manager_client.py", line 15, in add_logger_to_manager
[2025-05-25T05:30:38.981+0000] {subprocess.py:93} INFO -     _EVENT_MANAGER.add_logger(logger)
[2025-05-25T05:30:38.985+0000] {subprocess.py:93} INFO -   File "/home/***/.local/lib/python3.10/site-packages/dbt_common/events/event_manager.py", line 88, in add_logger
[2025-05-25T05:30:38.991+0000] {subprocess.py:93} INFO -     _JsonLogger(config) if config.line_format == LineFormat.Json else _TextLogger(config)
[2025-05-25T05:30:38.993+0000] {subprocess.py:93} INFO -   File "/home/***/.local/lib/python3.10/site-packages/dbt_common/events/logger.py", line 147, in __init__
[2025-05-25T05:30:38.994+0000] {subprocess.py:93} INFO -     super().__init__(config)
[2025-05-25T05:30:38.995+0000] {subprocess.py:93} INFO -   File "/home/***/.local/lib/python3.10/site-packages/dbt_common/events/logger.py", line 107, in __init__
[2025-05-25T05:30:38.997+0000] {subprocess.py:93} INFO -     file_handler = RotatingFileHandler(
[2025-05-25T05:30:38.998+0000] {subprocess.py:93} INFO -   File "/usr/local/lib/python3.10/logging/handlers.py", line 155, in __init__
[2025-05-25T05:30:38.999+0000] {subprocess.py:93} INFO -     BaseRotatingHandler.__init__(self, filename, mode, encoding=encoding,
[2025-05-25T05:30:39.000+0000] {subprocess.py:93} INFO -   File "/usr/local/lib/python3.10/logging/handlers.py", line 58, in __init__
[2025-05-25T05:30:39.001+0000] {subprocess.py:93} INFO -     logging.FileHandler.__init__(self, filename, mode=mode,
[2025-05-25T05:30:39.002+0000] {subprocess.py:93} INFO -   File "/usr/local/lib/python3.10/logging/__init__.py", line 1169, in __init__
[2025-05-25T05:30:39.003+0000] {subprocess.py:93} INFO -     StreamHandler.__init__(self, self._open())
[2025-05-25T05:30:39.004+0000] {subprocess.py:93} INFO -   File "/usr/local/lib/python3.10/logging/__init__.py", line 1201, in _open
[2025-05-25T05:30:39.013+0000] {subprocess.py:93} INFO -     return open_func(self.baseFilename, self.mode,
[2025-05-25T05:30:39.014+0000] {subprocess.py:93} INFO - OSError: [Errno 30] Read-only file system: '/opt/dbt/marketing_pipeline/logs/dbt.log'
[2025-05-25T05:30:39.016+0000] {subprocess.py:93} INFO - 
[2025-05-25T05:30:39.647+0000] {subprocess.py:97} INFO - Command exited with return code 2
[2025-05-25T05:30:39.681+0000] {taskinstance.py:2698} ERROR - Task failed with exception
Traceback (most recent call last):
  File "/home/airflow/.local/lib/python3.10/site-packages/airflow/models/taskinstance.py", line 433, in _execute_task
    result = execute_callable(context=context, **execute_callable_kwargs)
  File "/home/airflow/.local/lib/python3.10/site-packages/airflow/operators/bash.py", line 212, in execute
    raise AirflowException(
airflow.exceptions.AirflowException: Bash command failed. The command returned a non-zero exit code 2.
[2025-05-25T05:30:39.687+0000] {taskinstance.py:1138} INFO - Marking task as UP_FOR_RETRY. dag_id=marketing_data_pipeline, task_id=dbt_run_staging, execution_date=20250525T052720, start_date=20250525T053030, end_date=20250525T053039
[2025-05-25T05:30:39.720+0000] {standard_task_runner.py:107} ERROR - Failed to execute job 15 for task dbt_run_staging (Bash command failed. The command returned a non-zero exit code 2.; 3528)
[2025-05-25T05:30:39.774+0000] {local_task_job_runner.py:234} INFO - Task exited with return code 1
[2025-05-25T05:30:39.845+0000] {taskinstance.py:3280} INFO - 0 downstream tasks scheduled from follow-on schedule check
