[2025-05-24T07:38:11.152+0000] {taskinstance.py:1956} INFO - Dependencies all met for dep_context=non-requeueable deps ti=<TaskInstance: marketing_data_pipeline.upload_to_minio scheduled__2025-05-23T00:00:00+00:00 [queued]>
[2025-05-24T07:38:11.171+0000] {taskinstance.py:1956} INFO - Dependencies all met for dep_context=requeueable deps ti=<TaskInstance: marketing_data_pipeline.upload_to_minio scheduled__2025-05-23T00:00:00+00:00 [queued]>
[2025-05-24T07:38:11.172+0000] {taskinstance.py:2170} INFO - Starting attempt 4 of 4
[2025-05-24T07:38:11.200+0000] {taskinstance.py:2191} INFO - Executing <Task(PythonOperator): upload_to_minio> on 2025-05-23 00:00:00+00:00
[2025-05-24T07:38:11.213+0000] {standard_task_runner.py:60} INFO - Started process 960 to run task
[2025-05-24T07:38:11.222+0000] {standard_task_runner.py:87} INFO - Running: ['***', 'tasks', 'run', 'marketing_data_pipeline', 'upload_to_minio', 'scheduled__2025-05-23T00:00:00+00:00', '--job-id', '25', '--raw', '--subdir', 'DAGS_FOLDER/main_pipeline_dag.py', '--cfg-path', '/tmp/tmp0whd5uog']
[2025-05-24T07:38:11.228+0000] {standard_task_runner.py:88} INFO - Job 25: Subtask upload_to_minio
[2025-05-24T07:38:11.365+0000] {task_command.py:423} INFO - Running <TaskInstance: marketing_data_pipeline.upload_to_minio scheduled__2025-05-23T00:00:00+00:00 [running]> on host fcb3825e40cf
[2025-05-24T07:38:11.714+0000] {taskinstance.py:2480} INFO - Exporting env vars: AIRFLOW_CTX_DAG_EMAIL='yashbhawsar872@gmail.com' AIRFLOW_CTX_DAG_OWNER='Yash' AIRFLOW_CTX_DAG_ID='marketing_data_pipeline' AIRFLOW_CTX_TASK_ID='upload_to_minio' AIRFLOW_CTX_EXECUTION_DATE='2025-05-23T00:00:00+00:00' AIRFLOW_CTX_TRY_NUMBER='4' AIRFLOW_CTX_DAG_RUN_ID='scheduled__2025-05-23T00:00:00+00:00'
[2025-05-24T07:38:11.718+0000] {main_pipeline_dag.py:25} INFO - ‚ñ∂Ô∏è Starting task: Upload to MinIO
[2025-05-24T07:38:11.730+0000] {taskinstance.py:2698} ERROR - Task failed with exception
Traceback (most recent call last):
  File "/home/airflow/.local/lib/python3.10/site-packages/airflow/models/taskinstance.py", line 433, in _execute_task
    result = execute_callable(context=context, **execute_callable_kwargs)
  File "/home/airflow/.local/lib/python3.10/site-packages/airflow/operators/python.py", line 199, in execute
    return_value = self.execute_callable()
  File "/home/airflow/.local/lib/python3.10/site-packages/airflow/operators/python.py", line 216, in execute_callable
    return self.python_callable(*self.op_args, **self.op_kwargs)
  File "/opt/airflow/dags/main_pipeline_dag.py", line 26, in _wrapped
    fn(**kwargs)
TypeError: upload_all_validated_files() got an unexpected keyword argument 'conf'
[2025-05-24T07:38:11.783+0000] {taskinstance.py:1138} INFO - Marking task as FAILED. dag_id=marketing_data_pipeline, task_id=upload_to_minio, execution_date=20250523T000000, start_date=20250524T073811, end_date=20250524T073811
[2025-05-24T07:38:11.785+0000] {email_notification.py:54} WARNING - üìß Sending generic failure email [Airflow] Failure in marketing_data_pipeline.upload_to_minio (Attempt 5/3)
[2025-05-24T07:38:11.825+0000] {logging_mixin.py:188} WARNING - /home/***/.local/lib/python3.10/site-packages/***/utils/email.py:154 RemovedInAirflow3Warning: Fetching SMTP credentials from configuration variables will be deprecated in a future release. Please set credentials using a connection instead.
[2025-05-24T07:38:11.829+0000] {email.py:270} INFO - Email alerting: attempt 1
[2025-05-24T07:38:13.384+0000] {email.py:281} INFO - Sent an alert email to ['yashbhawsar872@gmail.com']
[2025-05-24T07:38:15.214+0000] {standard_task_runner.py:107} ERROR - Failed to execute job 25 for task upload_to_minio (upload_all_validated_files() got an unexpected keyword argument 'conf'; 960)
[2025-05-24T07:38:15.279+0000] {local_task_job_runner.py:234} INFO - Task exited with return code 1
[2025-05-24T07:38:15.475+0000] {taskinstance.py:3280} INFO - 0 downstream tasks scheduled from follow-on schedule check
