[2025-05-24T07:33:50.787+0000] {taskinstance.py:1956} INFO - Dependencies all met for dep_context=non-requeueable deps ti=<TaskInstance: marketing_data_pipeline.upload_to_minio scheduled__2025-05-23T00:00:00+00:00 [queued]>
[2025-05-24T07:33:50.834+0000] {taskinstance.py:1956} INFO - Dependencies all met for dep_context=requeueable deps ti=<TaskInstance: marketing_data_pipeline.upload_to_minio scheduled__2025-05-23T00:00:00+00:00 [queued]>
[2025-05-24T07:33:50.836+0000] {taskinstance.py:2170} INFO - Starting attempt 2 of 4
[2025-05-24T07:33:50.886+0000] {taskinstance.py:2191} INFO - Executing <Task(PythonOperator): upload_to_minio> on 2025-05-23 00:00:00+00:00
[2025-05-24T07:33:50.912+0000] {standard_task_runner.py:60} INFO - Started process 866 to run task
[2025-05-24T07:33:50.929+0000] {standard_task_runner.py:87} INFO - Running: ['***', 'tasks', 'run', 'marketing_data_pipeline', 'upload_to_minio', 'scheduled__2025-05-23T00:00:00+00:00', '--job-id', '23', '--raw', '--subdir', 'DAGS_FOLDER/main_pipeline_dag.py', '--cfg-path', '/tmp/tmp6trbng2y']
[2025-05-24T07:33:50.934+0000] {standard_task_runner.py:88} INFO - Job 23: Subtask upload_to_minio
[2025-05-24T07:33:51.321+0000] {task_command.py:423} INFO - Running <TaskInstance: marketing_data_pipeline.upload_to_minio scheduled__2025-05-23T00:00:00+00:00 [running]> on host fcb3825e40cf
[2025-05-24T07:33:52.003+0000] {taskinstance.py:2480} INFO - Exporting env vars: AIRFLOW_CTX_DAG_EMAIL='yashbhawsar872@gmail.com' AIRFLOW_CTX_DAG_OWNER='Yash' AIRFLOW_CTX_DAG_ID='marketing_data_pipeline' AIRFLOW_CTX_TASK_ID='upload_to_minio' AIRFLOW_CTX_EXECUTION_DATE='2025-05-23T00:00:00+00:00' AIRFLOW_CTX_TRY_NUMBER='2' AIRFLOW_CTX_DAG_RUN_ID='scheduled__2025-05-23T00:00:00+00:00'
[2025-05-24T07:33:52.029+0000] {main_pipeline_dag.py:25} INFO - ▶️ Starting task: Upload to MinIO
[2025-05-24T07:33:52.071+0000] {taskinstance.py:2698} ERROR - Task failed with exception
Traceback (most recent call last):
  File "/home/airflow/.local/lib/python3.10/site-packages/airflow/models/taskinstance.py", line 433, in _execute_task
    result = execute_callable(context=context, **execute_callable_kwargs)
  File "/home/airflow/.local/lib/python3.10/site-packages/airflow/operators/python.py", line 199, in execute
    return_value = self.execute_callable()
  File "/home/airflow/.local/lib/python3.10/site-packages/airflow/operators/python.py", line 216, in execute_callable
    return self.python_callable(*self.op_args, **self.op_kwargs)
  File "/opt/airflow/dags/main_pipeline_dag.py", line 26, in _wrapped
    fn(**kwargs)
TypeError: upload_all_validated_files() got an unexpected keyword argument 'conf'
[2025-05-24T07:33:52.171+0000] {taskinstance.py:1138} INFO - Marking task as UP_FOR_RETRY. dag_id=marketing_data_pipeline, task_id=upload_to_minio, execution_date=20250523T000000, start_date=20250524T073350, end_date=20250524T073352
[2025-05-24T07:33:52.250+0000] {standard_task_runner.py:107} ERROR - Failed to execute job 23 for task upload_to_minio (upload_all_validated_files() got an unexpected keyword argument 'conf'; 866)
[2025-05-24T07:33:52.360+0000] {local_task_job_runner.py:234} INFO - Task exited with return code 1
[2025-05-24T07:33:52.530+0000] {taskinstance.py:3280} INFO - 0 downstream tasks scheduled from follow-on schedule check
