[2025-05-27T21:23:58.982+0000] {taskinstance.py:1956} INFO - Dependencies all met for dep_context=non-requeueable deps ti=<TaskInstance: Marketing_Data_Pipeline.init_metadata_db manual__2025-05-27T21:22:31.629653+00:00 [queued]>
[2025-05-27T21:23:59.107+0000] {taskinstance.py:1956} INFO - Dependencies all met for dep_context=requeueable deps ti=<TaskInstance: Marketing_Data_Pipeline.init_metadata_db manual__2025-05-27T21:22:31.629653+00:00 [queued]>
[2025-05-27T21:23:59.109+0000] {taskinstance.py:2170} INFO - Starting attempt 1 of 2
[2025-05-27T21:23:59.482+0000] {taskinstance.py:2191} INFO - Executing <Task(PythonOperator): init_metadata_db> on 2025-05-27 21:22:31.629653+00:00
[2025-05-27T21:23:59.823+0000] {standard_task_runner.py:60} INFO - Started process 290 to run task
[2025-05-27T21:24:02.980+0000] {standard_task_runner.py:87} INFO - Running: ['***', 'tasks', 'run', 'Marketing_Data_Pipeline', 'init_metadata_db', 'manual__2025-05-27T21:22:31.629653+00:00', '--job-id', '3', '--raw', '--subdir', 'DAGS_FOLDER/Marketing_Data_Pipeline.py', '--cfg-path', '/tmp/tmp0fvsodk7']
[2025-05-27T21:24:04.308+0000] {standard_task_runner.py:88} INFO - Job 3: Subtask init_metadata_db
[2025-05-27T21:24:08.850+0000] {standard_task_runner.py:107} ERROR - Failed to execute job 3 for task init_metadata_db (DagRun for Marketing_Data_Pipeline with run_id or execution_date of 'manual__2025-05-27T21:22:31.629653+00:00' not found; 290)
[2025-05-27T21:24:09.698+0000] {local_task_job_runner.py:234} INFO - Task exited with return code 1
