[2025-05-27T21:30:54.489+0000] {taskinstance.py:1956} INFO - Dependencies all met for dep_context=non-requeueable deps ti=<TaskInstance: Marketing_Data_Pipeline.dbt_run.dbt_test scheduled__2025-05-24T00:00:00+00:00 [queued]>
[2025-05-27T21:30:54.520+0000] {taskinstance.py:1956} INFO - Dependencies all met for dep_context=requeueable deps ti=<TaskInstance: Marketing_Data_Pipeline.dbt_run.dbt_test scheduled__2025-05-24T00:00:00+00:00 [queued]>
[2025-05-27T21:30:54.521+0000] {taskinstance.py:2170} INFO - Starting attempt 1 of 1
[2025-05-27T21:30:54.561+0000] {taskinstance.py:2191} INFO - Executing <Task(PythonOperator): dbt_run.dbt_test> on 2025-05-24 00:00:00+00:00
[2025-05-27T21:30:54.573+0000] {standard_task_runner.py:60} INFO - Started process 597 to run task
[2025-05-27T21:30:54.581+0000] {standard_task_runner.py:87} INFO - Running: ['***', 'tasks', 'run', 'Marketing_Data_Pipeline', 'dbt_run.dbt_test', 'scheduled__2025-05-24T00:00:00+00:00', '--job-id', '30', '--raw', '--subdir', 'DAGS_FOLDER/Marketing_Data_Pipeline.py', '--cfg-path', '/tmp/tmpq4c3o66w']
[2025-05-27T21:30:54.585+0000] {standard_task_runner.py:88} INFO - Job 30: Subtask dbt_run.dbt_test
[2025-05-27T21:30:54.703+0000] {task_command.py:423} INFO - Running <TaskInstance: Marketing_Data_Pipeline.dbt_run.dbt_test scheduled__2025-05-24T00:00:00+00:00 [running]> on host 485388d78c3d
[2025-05-27T21:30:54.906+0000] {taskinstance.py:2480} INFO - Exporting env vars: AIRFLOW_CTX_DAG_EMAIL='yashbhawsar872@gmail.com' AIRFLOW_CTX_DAG_OWNER='Yash' AIRFLOW_CTX_DAG_ID='Marketing_Data_Pipeline' AIRFLOW_CTX_TASK_ID='dbt_run.dbt_test' AIRFLOW_CTX_EXECUTION_DATE='2025-05-24T00:00:00+00:00' AIRFLOW_CTX_TRY_NUMBER='1' AIRFLOW_CTX_DAG_RUN_ID='scheduled__2025-05-24T00:00:00+00:00'
[2025-05-27T21:30:54.908+0000] {Marketing_Data_Pipeline.py:39} INFO - ‚ñ∂Ô∏è Starting task: Run all dbt tests
[2025-05-27T21:30:54.913+0000] {utils.py:86} INFO - Running dbt tests: cd /opt/dbt/marketing_pipeline && dbt test 
[2025-05-27T21:30:54.917+0000] {utils.py:65} INFO - Running dbt command: cd /opt/dbt/marketing_pipeline && dbt test 
[2025-05-27T21:30:58.388+0000] {utils.py:78} INFO - [0m21:30:58  Running with dbt=1.9.4
[2025-05-27T21:31:00.348+0000] {utils.py:78} INFO - [0m21:31:00  Registered adapter: snowflake=1.9.4
[2025-05-27T21:31:01.430+0000] {utils.py:78} INFO - [0m21:31:01  Unable to do partial parsing because config vars, config profile, or config target have changed
[2025-05-27T21:31:07.892+0000] {utils.py:78} INFO - [0m21:31:07  Found 12 models, 70 data tests, 6 sources, 479 macros
[2025-05-27T21:31:07.927+0000] {utils.py:78} INFO - [0m21:31:07
[2025-05-27T21:31:07.937+0000] {utils.py:78} INFO - [0m21:31:07  Concurrency: 4 threads (target='dev')
[2025-05-27T21:31:07.943+0000] {utils.py:78} INFO - [0m21:31:07
[2025-05-27T21:31:09.401+0000] {utils.py:78} INFO - [0m21:31:09  1 of 70 START test accepted_values_stg_contacts_email___ ....................... [RUN]
[2025-05-27T21:31:09.407+0000] {utils.py:78} INFO - [0m21:31:09  2 of 70 START test expression_is_true_stg_form_fills_fill_date__fill_date_current_timestamp_  [RUN]
[2025-05-27T21:31:09.413+0000] {utils.py:78} INFO - [0m21:31:09  3 of 70 START test expression_is_true_stg_pages_page_url__page_url_LIKE_http_ .. [RUN]
[2025-05-27T21:31:09.420+0000] {utils.py:78} INFO - [0m21:31:09  4 of 70 START test expression_is_true_stg_website_activity_pages_viewed__pages_viewed_0  [RUN]
[2025-05-27T21:31:09.626+0000] {utils.py:78} INFO - [0m21:31:09  4 of 70 ERROR expression_is_true_stg_website_activity_pages_viewed__pages_viewed_0  [[31mERROR[0m in 0.19s]
[2025-05-27T21:31:09.638+0000] {utils.py:78} INFO - [0m21:31:09  3 of 70 ERROR expression_is_true_stg_pages_page_url__page_url_LIKE_http_ ....... [[31mERROR[0m in 0.20s]
[2025-05-27T21:31:09.654+0000] {utils.py:78} INFO - [0m21:31:09  2 of 70 ERROR expression_is_true_stg_form_fills_fill_date__fill_date_current_timestamp_  [[31mERROR[0m in 0.22s]
[2025-05-27T21:31:09.846+0000] {utils.py:78} INFO - [0m21:31:09  5 of 70 START test mart_no_orphan_form_fills ................................... [RUN]
[2025-05-27T21:31:09.859+0000] {utils.py:78} INFO - [0m21:31:09  6 of 70 START test mart_pages_url_format ....................................... [RUN]
[2025-05-27T21:31:09.868+0000] {utils.py:78} INFO - [0m21:31:09  7 of 70 START test no_duplicate_form_fills_per_contact ......................... [RUN]
[2025-05-27T21:31:10.414+0000] {utils.py:78} INFO - [0m21:31:10  1 of 70 FAIL 998 accepted_values_stg_contacts_email___ ......................... [[31mFAIL 998[0m in 0.99s]
[2025-05-27T21:31:10.474+0000] {utils.py:78} INFO - [0m21:31:10  8 of 70 START test not_null_mart_campaigns_campaign_id ......................... [RUN]
[2025-05-27T21:31:10.495+0000] {utils.py:78} INFO - [0m21:31:10  7 of 70 FAIL 253 no_duplicate_form_fills_per_contact ........................... [[31mFAIL 253[0m in 0.56s]
[2025-05-27T21:31:10.577+0000] {utils.py:78} INFO - [0m21:31:10  9 of 70 START test not_null_mart_campaigns_campaign_name ....................... [RUN]
[2025-05-27T21:31:10.983+0000] {utils.py:78} INFO - [0m21:31:10  8 of 70 PASS not_null_mart_campaigns_campaign_id ............................... [[32mPASS[0m in 0.49s]
[2025-05-27T21:31:11.007+0000] {utils.py:78} INFO - [0m21:31:11  10 of 70 START test not_null_mart_campaigns_end_date ........................... [RUN]
[2025-05-27T21:31:11.048+0000] {utils.py:78} INFO - [0m21:31:11  9 of 70 PASS not_null_mart_campaigns_campaign_name ............................. [[32mPASS[0m in 0.45s]
[2025-05-27T21:31:11.102+0000] {utils.py:78} INFO - [0m21:31:11  11 of 70 START test not_null_mart_campaigns_start_date ......................... [RUN]
[2025-05-27T21:31:11.176+0000] {utils.py:78} INFO - [0m21:31:11  6 of 70 FAIL 4 mart_pages_url_format ........................................... [[31mFAIL 4[0m in 1.26s]
[2025-05-27T21:31:11.256+0000] {utils.py:78} INFO - [0m21:31:11  5 of 70 PASS mart_no_orphan_form_fills ......................................... [[32mPASS[0m in 1.36s]
[2025-05-27T21:31:11.335+0000] {utils.py:78} INFO - [0m21:31:11  12 of 70 START test not_null_mart_contacts_contact_id .......................... [RUN]
[2025-05-27T21:31:11.479+0000] {utils.py:78} INFO - [0m21:31:11  13 of 70 START test not_null_mart_contacts_email ............................... [RUN]
[2025-05-27T21:31:11.879+0000] {utils.py:78} INFO - [0m21:31:11  10 of 70 ERROR not_null_mart_campaigns_end_date ................................ [[31mERROR[0m in 0.85s]
[2025-05-27T21:31:11.980+0000] {utils.py:78} INFO - [0m21:31:11  11 of 70 ERROR not_null_mart_campaigns_start_date .............................. [[31mERROR[0m in 0.85s]
[2025-05-27T21:31:12.038+0000] {utils.py:78} INFO - [0m21:31:12  14 of 70 START test not_null_mart_contacts_signup_date ......................... [RUN]
[2025-05-27T21:31:12.085+0000] {utils.py:78} INFO - [0m21:31:12  15 of 70 START test not_null_mart_form_fills_contact_id ........................ [RUN]
[2025-05-27T21:31:12.246+0000] {utils.py:78} INFO - [0m21:31:12  12 of 70 PASS not_null_mart_contacts_contact_id ................................ [[32mPASS[0m in 0.86s]
[2025-05-27T21:31:12.341+0000] {utils.py:78} INFO - [0m21:31:12  13 of 70 PASS not_null_mart_contacts_email ..................................... [[32mPASS[0m in 0.83s]
[2025-05-27T21:31:12.422+0000] {utils.py:78} INFO - [0m21:31:12  16 of 70 START test not_null_mart_form_fills_estimated_value ................... [RUN]
[2025-05-27T21:31:12.469+0000] {utils.py:78} INFO - [0m21:31:12  17 of 70 START test not_null_mart_form_fills_fill_date ......................... [RUN]
[2025-05-27T21:31:12.653+0000] {utils.py:78} INFO - [0m21:31:12  14 of 70 PASS not_null_mart_contacts_signup_date ............................... [[32mPASS[0m in 0.58s]
[2025-05-27T21:31:12.725+0000] {utils.py:78} INFO - [0m21:31:12  18 of 70 START test not_null_mart_form_fills_fill_id ........................... [RUN]
[2025-05-27T21:31:12.855+0000] {utils.py:78} INFO - [0m21:31:12  15 of 70 PASS not_null_mart_form_fills_contact_id .............................. [[32mPASS[0m in 0.75s]
[2025-05-27T21:31:12.985+0000] {utils.py:78} INFO - [0m21:31:12  19 of 70 START test not_null_mart_form_fills_form_id ........................... [RUN]
[2025-05-27T21:31:43.320+0000] {utils.py:78} INFO - WARNING:snowflake.connector.vendored.urllib3.connectionpool:Retrying (Retry(total=0, connect=None, read=None, redirect=None, status=None)) after connection broken by 'NewConnectionError('<snowflake.connector.vendored.urllib3.connection.HTTPSConnection object at 0x7f03446b9360>: Failed to establish a new connection: [Errno -3] Temporary failure in name resolution')': /queries/v1/query-request?requestId=efcf9181-7063-4061-9a57-a0bd7ffcafb1&clientStartTime=1748381472810&retryCount=1&retryReason=None&request_guid=0a71ecaf-5c33-48f3-a698-93f26458a7fd
[2025-05-27T21:31:43.326+0000] {utils.py:78} INFO - WARNING:snowflake.connector.vendored.urllib3.connectionpool:Retrying (Retry(total=0, connect=None, read=None, redirect=None, status=None)) after connection broken by 'NewConnectionError('<snowflake.connector.vendored.urllib3.connection.HTTPSConnection object at 0x7f03446b9900>: Failed to establish a new connection: [Errno -3] Temporary failure in name resolution')': /queries/v1/query-request?requestId=f2758078-2b8e-46e0-a7d2-faf366acc5db&clientStartTime=1748381472965&retryCount=1&retryReason=None&request_guid=50acbbac-ea50-44b1-b797-616b36082420
[2025-05-27T21:31:44.357+0000] {utils.py:78} INFO - WARNING:snowflake.connector.vendored.urllib3.connectionpool:Retrying (Retry(total=0, connect=None, read=None, redirect=None, status=None)) after connection broken by 'NewConnectionError('<snowflake.connector.vendored.urllib3.connection.HTTPSConnection object at 0x7f03446b8bb0>: Failed to establish a new connection: [Errno -3] Temporary failure in name resolution')': /queries/v1/query-request?requestId=13ffa4e8-0dff-47dc-933c-a163ba8954ec&clientStartTime=1748381473915&retryCount=1&retryReason=None&request_guid=3ccd319b-77f8-42e2-bbea-0fe7d7baac29
[2025-05-27T21:31:44.389+0000] {utils.py:78} INFO - WARNING:snowflake.connector.vendored.urllib3.connectionpool:Retrying (Retry(total=0, connect=None, read=None, redirect=None, status=None)) after connection broken by 'NewConnectionError('<snowflake.connector.vendored.urllib3.connection.HTTPSConnection object at 0x7f035ca48370>: Failed to establish a new connection: [Errno -3] Temporary failure in name resolution')': /queries/v1/query-request?requestId=21ea1b2e-06d7-4bf7-a91a-b368df548183&clientStartTime=1748381473946&retryCount=1&retryReason=None&request_guid=f418a2f3-b6be-4a67-89e8-37be81ac7f73
[2025-05-27T21:31:51.147+0000] {job.py:213} ERROR - Job heartbeat got an exception
Traceback (most recent call last):
  File "/home/airflow/.local/lib/python3.10/site-packages/sqlalchemy/engine/base.py", line 3371, in _wrap_pool_connect
    return fn()
  File "/home/airflow/.local/lib/python3.10/site-packages/sqlalchemy/pool/base.py", line 327, in connect
    return _ConnectionFairy._checkout(self)
  File "/home/airflow/.local/lib/python3.10/site-packages/sqlalchemy/pool/base.py", line 894, in _checkout
    fairy = _ConnectionRecord.checkout(pool)
  File "/home/airflow/.local/lib/python3.10/site-packages/sqlalchemy/pool/base.py", line 493, in checkout
    rec = pool._do_get()
  File "/home/airflow/.local/lib/python3.10/site-packages/sqlalchemy/pool/impl.py", line 256, in _do_get
    return self._create_connection()
  File "/home/airflow/.local/lib/python3.10/site-packages/sqlalchemy/pool/base.py", line 273, in _create_connection
    return _ConnectionRecord(self)
  File "/home/airflow/.local/lib/python3.10/site-packages/sqlalchemy/pool/base.py", line 388, in __init__
    self.__connect()
  File "/home/airflow/.local/lib/python3.10/site-packages/sqlalchemy/pool/base.py", line 690, in __connect
    with util.safe_reraise():
  File "/home/airflow/.local/lib/python3.10/site-packages/sqlalchemy/util/langhelpers.py", line 70, in __exit__
    compat.raise_(
  File "/home/airflow/.local/lib/python3.10/site-packages/sqlalchemy/util/compat.py", line 211, in raise_
    raise exception
  File "/home/airflow/.local/lib/python3.10/site-packages/sqlalchemy/pool/base.py", line 686, in __connect
    self.dbapi_connection = connection = pool._invoke_creator(self)
  File "/home/airflow/.local/lib/python3.10/site-packages/sqlalchemy/engine/create.py", line 574, in connect
    return dialect.connect(*cargs, **cparams)
  File "/home/airflow/.local/lib/python3.10/site-packages/sqlalchemy/engine/default.py", line 598, in connect
    return self.dbapi.connect(*cargs, **cparams)
  File "/home/airflow/.local/lib/python3.10/site-packages/psycopg2/__init__.py", line 122, in connect
    conn = _connect(dsn, connection_factory=connection_factory, **kwasync)
psycopg2.OperationalError: could not translate host name "postgres" to address: Temporary failure in name resolution


The above exception was the direct cause of the following exception:

Traceback (most recent call last):
  File "/home/airflow/.local/lib/python3.10/site-packages/airflow/jobs/job.py", line 187, in heartbeat
    self._merge_from(Job._fetch_from_db(self, session))
  File "/home/airflow/.local/lib/python3.10/site-packages/airflow/api_internal/internal_api_call.py", line 114, in wrapper
    return func(*args, **kwargs)
  File "/home/airflow/.local/lib/python3.10/site-packages/airflow/utils/session.py", line 76, in wrapper
    return func(*args, **kwargs)
  File "/home/airflow/.local/lib/python3.10/site-packages/airflow/jobs/job.py", line 308, in _fetch_from_db
    session.merge(job)
  File "/home/airflow/.local/lib/python3.10/site-packages/sqlalchemy/orm/session.py", line 3056, in merge
    return self._merge(
  File "/home/airflow/.local/lib/python3.10/site-packages/sqlalchemy/orm/session.py", line 3136, in _merge
    merged = self.get(
  File "/home/airflow/.local/lib/python3.10/site-packages/sqlalchemy/orm/session.py", line 2853, in get
    return self._get_impl(
  File "/home/airflow/.local/lib/python3.10/site-packages/sqlalchemy/orm/session.py", line 2975, in _get_impl
    return db_load_fn(
  File "/home/airflow/.local/lib/python3.10/site-packages/sqlalchemy/orm/loading.py", line 530, in load_on_pk_identity
    session.execute(
  File "/home/airflow/.local/lib/python3.10/site-packages/sqlalchemy/orm/session.py", line 1716, in execute
    conn = self._connection_for_bind(bind)
  File "/home/airflow/.local/lib/python3.10/site-packages/sqlalchemy/orm/session.py", line 1555, in _connection_for_bind
    return self._transaction._connection_for_bind(
  File "/home/airflow/.local/lib/python3.10/site-packages/sqlalchemy/orm/session.py", line 750, in _connection_for_bind
    conn = bind.connect()
  File "/home/airflow/.local/lib/python3.10/site-packages/sqlalchemy/future/engine.py", line 412, in connect
    return super(Engine, self).connect()
  File "/home/airflow/.local/lib/python3.10/site-packages/sqlalchemy/engine/base.py", line 3325, in connect
    return self._connection_cls(self, close_with_result=close_with_result)
  File "/home/airflow/.local/lib/python3.10/site-packages/sqlalchemy/engine/base.py", line 96, in __init__
    else engine.raw_connection()
  File "/home/airflow/.local/lib/python3.10/site-packages/sqlalchemy/engine/base.py", line 3404, in raw_connection
    return self._wrap_pool_connect(self.pool.connect, _connection)
  File "/home/airflow/.local/lib/python3.10/site-packages/sqlalchemy/engine/base.py", line 3374, in _wrap_pool_connect
    Connection._handle_dbapi_exception_noconnection(
  File "/home/airflow/.local/lib/python3.10/site-packages/sqlalchemy/engine/base.py", line 2208, in _handle_dbapi_exception_noconnection
    util.raise_(
  File "/home/airflow/.local/lib/python3.10/site-packages/sqlalchemy/util/compat.py", line 211, in raise_
    raise exception
  File "/home/airflow/.local/lib/python3.10/site-packages/sqlalchemy/engine/base.py", line 3371, in _wrap_pool_connect
    return fn()
  File "/home/airflow/.local/lib/python3.10/site-packages/sqlalchemy/pool/base.py", line 327, in connect
    return _ConnectionFairy._checkout(self)
  File "/home/airflow/.local/lib/python3.10/site-packages/sqlalchemy/pool/base.py", line 894, in _checkout
    fairy = _ConnectionRecord.checkout(pool)
  File "/home/airflow/.local/lib/python3.10/site-packages/sqlalchemy/pool/base.py", line 493, in checkout
    rec = pool._do_get()
  File "/home/airflow/.local/lib/python3.10/site-packages/sqlalchemy/pool/impl.py", line 256, in _do_get
    return self._create_connection()
  File "/home/airflow/.local/lib/python3.10/site-packages/sqlalchemy/pool/base.py", line 273, in _create_connection
    return _ConnectionRecord(self)
  File "/home/airflow/.local/lib/python3.10/site-packages/sqlalchemy/pool/base.py", line 388, in __init__
    self.__connect()
  File "/home/airflow/.local/lib/python3.10/site-packages/sqlalchemy/pool/base.py", line 690, in __connect
    with util.safe_reraise():
  File "/home/airflow/.local/lib/python3.10/site-packages/sqlalchemy/util/langhelpers.py", line 70, in __exit__
    compat.raise_(
  File "/home/airflow/.local/lib/python3.10/site-packages/sqlalchemy/util/compat.py", line 211, in raise_
    raise exception
  File "/home/airflow/.local/lib/python3.10/site-packages/sqlalchemy/pool/base.py", line 686, in __connect
    self.dbapi_connection = connection = pool._invoke_creator(self)
  File "/home/airflow/.local/lib/python3.10/site-packages/sqlalchemy/engine/create.py", line 574, in connect
    return dialect.connect(*cargs, **cparams)
  File "/home/airflow/.local/lib/python3.10/site-packages/sqlalchemy/engine/default.py", line 598, in connect
    return self.dbapi.connect(*cargs, **cparams)
  File "/home/airflow/.local/lib/python3.10/site-packages/psycopg2/__init__.py", line 122, in connect
    conn = _connect(dsn, connection_factory=connection_factory, **kwasync)
sqlalchemy.exc.OperationalError: (psycopg2.OperationalError) could not translate host name "postgres" to address: Temporary failure in name resolution

(Background on this error at: https://sqlalche.me/e/14/e3q8)
[2025-05-27T21:31:53.154+0000] {job.py:221} ERROR - Job heartbeat failed with error. Scheduler is in unhealthy state
[2025-05-27T21:32:01.363+0000] {utils.py:78} INFO - WARNING:snowflake.connector.vendored.urllib3.connectionpool:Retrying (Retry(total=0, connect=None, read=None, redirect=None, status=None)) after connection broken by 'NewConnectionError('<snowflake.connector.vendored.urllib3.connection.HTTPSConnection object at 0x7f03446b8f70>: Failed to establish a new connection: [Errno -3] Temporary failure in name resolution')': /queries/v1/query-request?requestId=efcf9181-7063-4061-9a57-a0bd7ffcafb1&clientStartTime=1748381472810&retryCount=2&retryReason=None&request_guid=87928dde-c058-4a1f-92a2-82c6dad12704
[2025-05-27T21:32:02.544+0000] {utils.py:78} INFO - WARNING:snowflake.connector.vendored.urllib3.connectionpool:Retrying (Retry(total=0, connect=None, read=None, redirect=None, status=None)) after connection broken by 'NewConnectionError('<snowflake.connector.vendored.urllib3.connection.HTTPSConnection object at 0x7f03446bbf70>: Failed to establish a new connection: [Errno -3] Temporary failure in name resolution')': /queries/v1/query-request?requestId=21ea1b2e-06d7-4bf7-a91a-b368df548183&clientStartTime=1748381473946&retryCount=2&retryReason=None&request_guid=53035a15-b667-440e-83f8-56625851c969
[2025-05-27T21:32:03.353+0000] {utils.py:78} INFO - WARNING:snowflake.connector.vendored.urllib3.connectionpool:Retrying (Retry(total=0, connect=None, read=None, redirect=None, status=None)) after connection broken by 'NewConnectionError('<snowflake.connector.vendored.urllib3.connection.HTTPSConnection object at 0x7f03446babc0>: Failed to establish a new connection: [Errno -3] Temporary failure in name resolution')': /queries/v1/query-request?requestId=f2758078-2b8e-46e0-a7d2-faf366acc5db&clientStartTime=1748381472965&retryCount=2&retryReason=None&request_guid=1cdbf360-19eb-4161-a1e6-d5c9dd196e39
[2025-05-27T21:32:04.371+0000] {utils.py:78} INFO - WARNING:snowflake.connector.vendored.urllib3.connectionpool:Retrying (Retry(total=0, connect=None, read=None, redirect=None, status=None)) after connection broken by 'NewConnectionError('<snowflake.connector.vendored.urllib3.connection.HTTPSConnection object at 0x7f03446b9030>: Failed to establish a new connection: [Errno -2] Name or service not known')': /queries/v1/query-request?requestId=13ffa4e8-0dff-47dc-933c-a163ba8954ec&clientStartTime=1748381473915&retryCount=2&retryReason=None&request_guid=a678db39-47c2-405c-a45b-c587340b2cbc
[2025-05-27T21:32:09.198+0000] {utils.py:78} INFO - WARNING:snowflake.connector.vendored.urllib3.connectionpool:Retrying (Retry(total=0, connect=None, read=None, redirect=None, status=None)) after connection broken by 'NewConnectionError('<snowflake.connector.vendored.urllib3.connection.HTTPSConnection object at 0x7f03446b8520>: Failed to establish a new connection: [Errno -2] Name or service not known')': /queries/v1/query-request?requestId=f2758078-2b8e-46e0-a7d2-faf366acc5db&clientStartTime=1748381472965&retryCount=3&retryReason=None&request_guid=da97a09d-1e39-4b6c-92c4-f5083db19831
[2025-05-27T21:32:09.370+0000] {utils.py:78} INFO - WARNING:snowflake.connector.vendored.urllib3.connectionpool:Retrying (Retry(total=0, connect=None, read=None, redirect=None, status=None)) after connection broken by 'NewConnectionError('<snowflake.connector.vendored.urllib3.connection.HTTPSConnection object at 0x7f03446b8670>: Failed to establish a new connection: [Errno -2] Name or service not known')': /queries/v1/query-request?requestId=efcf9181-7063-4061-9a57-a0bd7ffcafb1&clientStartTime=1748381472810&retryCount=3&retryReason=None&request_guid=0d72bc13-ed05-4650-aa31-c8aaf3dab1a2
[2025-05-27T21:32:10.198+0000] {utils.py:78} INFO - WARNING:snowflake.connector.vendored.urllib3.connectionpool:Retrying (Retry(total=0, connect=None, read=None, redirect=None, status=None)) after connection broken by 'NewConnectionError('<snowflake.connector.vendored.urllib3.connection.HTTPSConnection object at 0x7f03446b98d0>: Failed to establish a new connection: [Errno -2] Name or service not known')': /queries/v1/query-request?requestId=13ffa4e8-0dff-47dc-933c-a163ba8954ec&clientStartTime=1748381473915&retryCount=3&retryReason=None&request_guid=2a38f476-3124-4696-b507-106a2d5f6ad6
[2025-05-27T21:32:12.195+0000] {utils.py:78} INFO - WARNING:snowflake.connector.vendored.urllib3.connectionpool:Retrying (Retry(total=0, connect=None, read=None, redirect=None, status=None)) after connection broken by 'NewConnectionError('<snowflake.connector.vendored.urllib3.connection.HTTPSConnection object at 0x7f03446b9d80>: Failed to establish a new connection: [Errno -2] Name or service not known')': /queries/v1/query-request?requestId=21ea1b2e-06d7-4bf7-a91a-b368df548183&clientStartTime=1748381473946&retryCount=3&retryReason=None&request_guid=678e6c49-cfc1-465f-93ab-7f4b102658c3
[2025-05-27T21:32:14.651+0000] {utils.py:78} INFO - WARNING:snowflake.connector.vendored.urllib3.connectionpool:Retrying (Retry(total=0, connect=None, read=None, redirect=None, status=None)) after connection broken by 'NewConnectionError('<snowflake.connector.vendored.urllib3.connection.HTTPSConnection object at 0x7f03446e3a00>: Failed to establish a new connection: [Errno -2] Name or service not known')': /queries/v1/query-request?requestId=21ea1b2e-06d7-4bf7-a91a-b368df548183&clientStartTime=1748381473946&retryCount=4&retryReason=None&request_guid=df6f9ec5-0706-4c51-888c-efaaf5922c9a
[2025-05-27T21:32:18.470+0000] {utils.py:78} INFO - WARNING:snowflake.connector.vendored.urllib3.connectionpool:Retrying (Retry(total=0, connect=None, read=None, redirect=None, status=None)) after connection broken by 'NewConnectionError('<snowflake.connector.vendored.urllib3.connection.HTTPSConnection object at 0x7f03446b9e10>: Failed to establish a new connection: [Errno -2] Name or service not known')': /queries/v1/query-request?requestId=13ffa4e8-0dff-47dc-933c-a163ba8954ec&clientStartTime=1748381473915&retryCount=4&retryReason=None&request_guid=5d39c0b7-cae5-4041-91e8-845e5d70fcb9
[2025-05-27T21:32:18.583+0000] {utils.py:78} INFO - WARNING:snowflake.connector.vendored.urllib3.connectionpool:Retrying (Retry(total=0, connect=None, read=None, redirect=None, status=None)) after connection broken by 'NewConnectionError('<snowflake.connector.vendored.urllib3.connection.HTTPSConnection object at 0x7f03446ba380>: Failed to establish a new connection: [Errno -2] Name or service not known')': /queries/v1/query-request?requestId=f2758078-2b8e-46e0-a7d2-faf366acc5db&clientStartTime=1748381472965&retryCount=4&retryReason=None&request_guid=0962cd83-0959-4a7e-b0b3-6b65f6e33edb
[2025-05-27T21:32:18.634+0000] {utils.py:78} INFO - WARNING:snowflake.connector.vendored.urllib3.connectionpool:Retrying (Retry(total=0, connect=None, read=None, redirect=None, status=None)) after connection broken by 'NewConnectionError('<snowflake.connector.vendored.urllib3.connection.HTTPSConnection object at 0x7f03446b8190>: Failed to establish a new connection: [Errno -2] Name or service not known')': /queries/v1/query-request?requestId=efcf9181-7063-4061-9a57-a0bd7ffcafb1&clientStartTime=1748381472810&retryCount=4&retryReason=None&request_guid=4121ec1b-1013-4311-be07-654ce43a5b63
[2025-05-27T21:32:19.692+0000] {utils.py:78} INFO - WARNING:snowflake.connector.vendored.urllib3.connectionpool:Retrying (Retry(total=0, connect=None, read=None, redirect=None, status=None)) after connection broken by 'NewConnectionError('<snowflake.connector.vendored.urllib3.connection.HTTPSConnection object at 0x7f03446e2830>: Failed to establish a new connection: [Errno -2] Name or service not known')': /queries/v1/query-request?requestId=21ea1b2e-06d7-4bf7-a91a-b368df548183&clientStartTime=1748381473946&retryCount=5&retryReason=None&request_guid=41913695-0d50-42eb-904e-e7665b30219f
[2025-05-27T21:32:22.639+0000] {utils.py:78} INFO - WARNING:snowflake.connector.vendored.urllib3.connectionpool:Retrying (Retry(total=0, connect=None, read=None, redirect=None, status=None)) after connection broken by 'NewConnectionError('<snowflake.connector.vendored.urllib3.connection.HTTPSConnection object at 0x7f03446e3c40>: Failed to establish a new connection: [Errno -2] Name or service not known')': /queries/v1/query-request?requestId=13ffa4e8-0dff-47dc-933c-a163ba8954ec&clientStartTime=1748381473915&retryCount=5&retryReason=None&request_guid=81330fa0-414d-4025-a33e-499ad436f564
[2025-05-27T21:32:27.660+0000] {utils.py:78} INFO - WARNING:snowflake.connector.vendored.urllib3.connectionpool:Retrying (Retry(total=0, connect=None, read=None, redirect=None, status=None)) after connection broken by 'NewConnectionError('<snowflake.connector.vendored.urllib3.connection.HTTPSConnection object at 0x7f03446e2fe0>: Failed to establish a new connection: [Errno -2] Name or service not known')': /queries/v1/query-request?requestId=f2758078-2b8e-46e0-a7d2-faf366acc5db&clientStartTime=1748381472965&retryCount=5&retryReason=None&request_guid=7bebc5a3-bbb4-4ee1-b0c4-d2ee9d0d92e7
[2025-05-27T21:32:29.723+0000] {utils.py:78} INFO - WARNING:snowflake.connector.vendored.urllib3.connectionpool:Retrying (Retry(total=0, connect=None, read=None, redirect=None, status=None)) after connection broken by 'NewConnectionError('<snowflake.connector.vendored.urllib3.connection.HTTPSConnection object at 0x7f03446b80d0>: Failed to establish a new connection: [Errno -2] Name or service not known')': /queries/v1/query-request?requestId=f2758078-2b8e-46e0-a7d2-faf366acc5db&clientStartTime=1748381472965&retryCount=6&retryReason=None&request_guid=674aa044-b7b6-4bc7-af7e-ff1b095ce569
[2025-05-27T21:32:33.695+0000] {utils.py:78} INFO - WARNING:snowflake.connector.vendored.urllib3.connectionpool:Retrying (Retry(total=0, connect=None, read=None, redirect=None, status=None)) after connection broken by 'NewConnectionError('<snowflake.connector.vendored.urllib3.connection.HTTPSConnection object at 0x7f03446e2bc0>: Failed to establish a new connection: [Errno -2] Name or service not known')': /queries/v1/query-request?requestId=13ffa4e8-0dff-47dc-933c-a163ba8954ec&clientStartTime=1748381473915&retryCount=6&retryReason=None&request_guid=034ba287-f78c-41f8-bc81-20912370741e
[2025-05-27T21:32:33.707+0000] {utils.py:78} INFO - WARNING:snowflake.connector.vendored.urllib3.connectionpool:Retrying (Retry(total=0, connect=None, read=None, redirect=None, status=None)) after connection broken by 'NewConnectionError('<snowflake.connector.vendored.urllib3.connection.HTTPSConnection object at 0x7f03446bb9d0>: Failed to establish a new connection: [Errno -2] Name or service not known')': /queries/v1/query-request?requestId=efcf9181-7063-4061-9a57-a0bd7ffcafb1&clientStartTime=1748381472810&retryCount=5&retryReason=None&request_guid=77a5e28c-aafb-4dfb-86b9-e4f238ff8faf
[2025-05-27T21:32:33.754+0000] {utils.py:78} INFO - WARNING:snowflake.connector.vendored.urllib3.connectionpool:Retrying (Retry(total=0, connect=None, read=None, redirect=None, status=None)) after connection broken by 'NewConnectionError('<snowflake.connector.vendored.urllib3.connection.HTTPSConnection object at 0x7f03446e1e70>: Failed to establish a new connection: [Errno -2] Name or service not known')': /queries/v1/query-request?requestId=21ea1b2e-06d7-4bf7-a91a-b368df548183&clientStartTime=1748381473946&retryCount=6&retryReason=None&request_guid=41c4a462-585b-46c0-86c1-b189c10fd248
[2025-05-27T21:32:42.715+0000] {utils.py:78} INFO - WARNING:snowflake.connector.vendored.urllib3.connectionpool:Retrying (Retry(total=0, connect=None, read=None, redirect=None, status=None)) after connection broken by 'NewConnectionError('<snowflake.connector.vendored.urllib3.connection.HTTPSConnection object at 0x7f03446e0460>: Failed to establish a new connection: [Errno -2] Name or service not known')': /queries/v1/query-request?requestId=13ffa4e8-0dff-47dc-933c-a163ba8954ec&clientStartTime=1748381473915&retryCount=7&retryReason=None&request_guid=52f0bbe5-1bb5-4c25-917d-e2b3f868bcf6
[2025-05-27T21:32:43.161+0000] {utils.py:78} INFO - WARNING:snowflake.connector.vendored.urllib3.connectionpool:Retrying (Retry(total=0, connect=None, read=None, redirect=None, status=None)) after connection broken by 'NewConnectionError('<snowflake.connector.vendored.urllib3.connection.HTTPSConnection object at 0x7f03446e0bb0>: Failed to establish a new connection: [Errno -2] Name or service not known')': /queries/v1/query-request?requestId=21ea1b2e-06d7-4bf7-a91a-b368df548183&clientStartTime=1748381473946&retryCount=7&retryReason=None&request_guid=30c99c75-aa33-4fb9-9c57-93d819005153
[2025-05-27T21:32:43.516+0000] {utils.py:78} INFO - WARNING:snowflake.connector.vendored.urllib3.connectionpool:Retrying (Retry(total=0, connect=None, read=None, redirect=None, status=None)) after connection broken by 'NewConnectionError('<snowflake.connector.vendored.urllib3.connection.HTTPSConnection object at 0x7f03446bb9d0>: Failed to establish a new connection: [Errno -2] Name or service not known')': /queries/v1/query-request?requestId=efcf9181-7063-4061-9a57-a0bd7ffcafb1&clientStartTime=1748381472810&retryCount=6&retryReason=None&request_guid=70ac372c-e9b7-47d2-af60-9fddfb9a154a
[2025-05-27T21:32:44.334+0000] {utils.py:78} INFO - WARNING:snowflake.connector.vendored.urllib3.connectionpool:Retrying (Retry(total=0, connect=None, read=None, redirect=None, status=None)) after connection broken by 'NewConnectionError('<snowflake.connector.vendored.urllib3.connection.HTTPSConnection object at 0x7f03446e3b50>: Failed to establish a new connection: [Errno -2] Name or service not known')': /queries/v1/query-request?requestId=f2758078-2b8e-46e0-a7d2-faf366acc5db&clientStartTime=1748381472965&retryCount=7&retryReason=None&request_guid=6faa1a90-d4b8-49dc-84d9-02246442ea86
[2025-05-27T21:32:49.722+0000] {utils.py:78} INFO - WARNING:snowflake.connector.vendored.urllib3.connectionpool:Retrying (Retry(total=0, connect=None, read=None, redirect=None, status=None)) after connection broken by 'NewConnectionError('<snowflake.connector.vendored.urllib3.connection.HTTPSConnection object at 0x7f03446e1900>: Failed to establish a new connection: [Errno -2] Name or service not known')': /queries/v1/query-request?requestId=f2758078-2b8e-46e0-a7d2-faf366acc5db&clientStartTime=1748381472965&retryCount=8&retryReason=None&request_guid=ae80e200-1a33-4300-96af-b37a86c9ebc1
[2025-05-27T21:32:53.422+0000] {utils.py:78} INFO - WARNING:snowflake.connector.vendored.urllib3.connectionpool:Retrying (Retry(total=0, connect=None, read=None, redirect=None, status=None)) after connection broken by 'NewConnectionError('<snowflake.connector.vendored.urllib3.connection.HTTPSConnection object at 0x7f0344679ea0>: Failed to establish a new connection: [Errno -2] Name or service not known')': /queries/v1/query-request?requestId=13ffa4e8-0dff-47dc-933c-a163ba8954ec&clientStartTime=1748381473915&retryCount=8&retryReason=None&request_guid=9751efb9-8362-434c-8512-a4dafc082fad
[2025-05-27T21:32:53.545+0000] {utils.py:78} INFO - WARNING:snowflake.connector.vendored.urllib3.connectionpool:Retrying (Retry(total=0, connect=None, read=None, redirect=None, status=None)) after connection broken by 'NewConnectionError('<snowflake.connector.vendored.urllib3.connection.HTTPSConnection object at 0x7f03446791b0>: Failed to establish a new connection: [Errno -2] Name or service not known')': /queries/v1/query-request?requestId=13ffa4e8-0dff-47dc-933c-a163ba8954ec&clientStartTime=1748381473915&retryCount=9&retryReason=None&request_guid=9688218a-aeb1-41db-937b-18551e67252f
[2025-05-27T21:32:54.045+0000] {utils.py:78} INFO - WARNING:snowflake.connector.vendored.urllib3.connectionpool:Retrying (Retry(total=0, connect=None, read=None, redirect=None, status=None)) after connection broken by 'NewConnectionError('<snowflake.connector.vendored.urllib3.connection.HTTPSConnection object at 0x7f03446e0310>: Failed to establish a new connection: [Errno -2] Name or service not known')': /queries/v1/query-request?requestId=f2758078-2b8e-46e0-a7d2-faf366acc5db&clientStartTime=1748381472965&retryCount=9&retryReason=None&request_guid=50d5d0ec-0b79-48c9-9389-5693aa18d8d0
[2025-05-27T21:32:55.571+0000] {utils.py:78} INFO - WARNING:snowflake.connector.vendored.urllib3.connectionpool:Retrying (Retry(total=0, connect=None, read=None, redirect=None, status=None)) after connection broken by 'NewConnectionError('<snowflake.connector.vendored.urllib3.connection.HTTPSConnection object at 0x7f03446e3400>: Failed to establish a new connection: [Errno -2] Name or service not known')': /queries/v1/query-request?requestId=efcf9181-7063-4061-9a57-a0bd7ffcafb1&clientStartTime=1748381472810&retryCount=7&retryReason=None&request_guid=d8a92410-bb6a-44cb-97bf-7894b1944db8
[2025-05-27T21:32:56.404+0000] {utils.py:78} INFO - WARNING:snowflake.connector.vendored.urllib3.connectionpool:Retrying (Retry(total=0, connect=None, read=None, redirect=None, status=None)) after connection broken by 'NewConnectionError('<snowflake.connector.vendored.urllib3.connection.HTTPSConnection object at 0x7f034467aad0>: Failed to establish a new connection: [Errno -2] Name or service not known')': /queries/v1/query-request?requestId=21ea1b2e-06d7-4bf7-a91a-b368df548183&clientStartTime=1748381473946&retryCount=8&retryReason=None&request_guid=a72815c8-1b54-453b-8712-469f8cdba8d5
[2025-05-27T21:32:57.847+0000] {utils.py:78} INFO - WARNING:snowflake.connector.vendored.urllib3.connectionpool:Retrying (Retry(total=0, connect=None, read=None, redirect=None, status=None)) after connection broken by 'NewConnectionError('<snowflake.connector.vendored.urllib3.connection.HTTPSConnection object at 0x7f0344678e80>: Failed to establish a new connection: [Errno -2] Name or service not known')': /queries/v1/query-request?requestId=efcf9181-7063-4061-9a57-a0bd7ffcafb1&clientStartTime=1748381472810&retryCount=8&retryReason=None&request_guid=36240618-5cfa-4f18-9740-8882f959b89e
[2025-05-27T21:32:59.024+0000] {utils.py:78} INFO - WARNING:snowflake.connector.vendored.urllib3.connectionpool:Retrying (Retry(total=0, connect=None, read=None, redirect=None, status=None)) after connection broken by 'NewConnectionError('<snowflake.connector.vendored.urllib3.connection.HTTPSConnection object at 0x7f03446781f0>: Failed to establish a new connection: [Errno -2] Name or service not known')': /queries/v1/query-request?requestId=f2758078-2b8e-46e0-a7d2-faf366acc5db&clientStartTime=1748381472965&retryCount=10&retryReason=None&request_guid=aa011f00-3b8f-45b7-b504-1f2960d56220
[2025-05-27T21:32:59.099+0000] {utils.py:78} INFO - WARNING:snowflake.connector.vendored.urllib3.connectionpool:Retrying (Retry(total=0, connect=None, read=None, redirect=None, status=None)) after connection broken by 'NewConnectionError('<snowflake.connector.vendored.urllib3.connection.HTTPSConnection object at 0x7f0344678f40>: Failed to establish a new connection: [Errno -2] Name or service not known')': /queries/v1/query-request?requestId=13ffa4e8-0dff-47dc-933c-a163ba8954ec&clientStartTime=1748381473915&retryCount=10&retryReason=None&request_guid=37c2120c-6576-41a2-b472-e7a3a3a1f549
[2025-05-27T21:33:00.195+0000] {utils.py:78} INFO - WARNING:snowflake.connector.vendored.urllib3.connectionpool:Retrying (Retry(total=0, connect=None, read=None, redirect=None, status=None)) after connection broken by 'NewConnectionError('<snowflake.connector.vendored.urllib3.connection.HTTPSConnection object at 0x7f03446e3fa0>: Failed to establish a new connection: [Errno -2] Name or service not known')': /queries/v1/query-request?requestId=efcf9181-7063-4061-9a57-a0bd7ffcafb1&clientStartTime=1748381472810&retryCount=9&retryReason=None&request_guid=9fb2a3ea-2a23-4da0-bbb0-9696d8b3ae1e
[2025-05-27T21:33:11.770+0000] {utils.py:78} INFO - WARNING:snowflake.connector.vendored.urllib3.connectionpool:Retrying (Retry(total=0, connect=None, read=None, redirect=None, status=None)) after connection broken by 'NewConnectionError('<snowflake.connector.vendored.urllib3.connection.HTTPSConnection object at 0x7f034467a410>: Failed to establish a new connection: [Errno -2] Name or service not known')': /queries/v1/query-request?requestId=21ea1b2e-06d7-4bf7-a91a-b368df548183&clientStartTime=1748381473946&retryCount=9&retryReason=None&request_guid=091fa46a-aed4-40b8-aa6f-0def5bb86f5f
[2025-05-27T21:33:12.390+0000] {utils.py:78} INFO - WARNING:snowflake.connector.vendored.urllib3.connectionpool:Retrying (Retry(total=0, connect=None, read=None, redirect=None, status=None)) after connection broken by 'NewConnectionError('<snowflake.connector.vendored.urllib3.connection.HTTPSConnection object at 0x7f034467bee0>: Failed to establish a new connection: [Errno -2] Name or service not known')': /queries/v1/query-request?requestId=f2758078-2b8e-46e0-a7d2-faf366acc5db&clientStartTime=1748381472965&retryCount=11&retryReason=None&request_guid=20887c56-dcb5-416e-bca8-e224d0da403a
[2025-05-27T21:33:12.402+0000] {utils.py:78} INFO - WARNING:snowflake.connector.vendored.urllib3.connectionpool:Retrying (Retry(total=0, connect=None, read=None, redirect=None, status=None)) after connection broken by 'NewConnectionError('<snowflake.connector.vendored.urllib3.connection.HTTPSConnection object at 0x7f03446e1900>: Failed to establish a new connection: [Errno -2] Name or service not known')': /queries/v1/query-request?requestId=13ffa4e8-0dff-47dc-933c-a163ba8954ec&clientStartTime=1748381473915&retryCount=11&retryReason=None&request_guid=a35d5c0c-31b5-4f95-8a78-f72a895266fa
[2025-05-27T21:33:21.334+0000] {utils.py:78} INFO - WARNING:snowflake.connector.vendored.urllib3.connectionpool:Retrying (Retry(total=0, connect=None, read=None, redirect=None, status=None)) after connection broken by 'NewConnectionError('<snowflake.connector.vendored.urllib3.connection.HTTPSConnection object at 0x7f0344678460>: Failed to establish a new connection: [Errno -3] Temporary failure in name resolution')': /queries/v1/query-request?requestId=efcf9181-7063-4061-9a57-a0bd7ffcafb1&clientStartTime=1748381472810&retryCount=10&retryReason=None&request_guid=1bd45ecc-9a9b-4b8b-bdc9-46ebc0c881c1
[2025-05-27T21:33:21.736+0000] {utils.py:78} INFO - WARNING:snowflake.connector.vendored.urllib3.connectionpool:Retrying (Retry(total=0, connect=None, read=None, redirect=None, status=None)) after connection broken by 'NewConnectionError('<snowflake.connector.vendored.urllib3.connection.HTTPSConnection object at 0x7f03467e74c0>: Failed to establish a new connection: [Errno -2] Name or service not known')': /queries/v1/query-request?requestId=f2758078-2b8e-46e0-a7d2-faf366acc5db&clientStartTime=1748381472965&retryCount=12&retryReason=None&request_guid=3e7cc46d-bac5-4a4c-84d8-7e679e04c6bf
[2025-05-27T21:33:24.004+0000] {utils.py:78} INFO - WARNING:snowflake.connector.vendored.urllib3.connectionpool:Retrying (Retry(total=0, connect=None, read=None, redirect=None, status=None)) after connection broken by 'NewConnectionError('<snowflake.connector.vendored.urllib3.connection.HTTPSConnection object at 0x7f034467a6b0>: Failed to establish a new connection: [Errno -2] Name or service not known')': /queries/v1/query-request?requestId=21ea1b2e-06d7-4bf7-a91a-b368df548183&clientStartTime=1748381473946&retryCount=10&retryReason=None&request_guid=2fc65d32-1c0e-497b-9a27-982c9a06e322
[2025-05-27T21:33:24.494+0000] {utils.py:78} INFO - WARNING:snowflake.connector.vendored.urllib3.connectionpool:Retrying (Retry(total=0, connect=None, read=None, redirect=None, status=None)) after connection broken by 'NewConnectionError('<snowflake.connector.vendored.urllib3.connection.HTTPSConnection object at 0x7f034467b850>: Failed to establish a new connection: [Errno -2] Name or service not known')': /queries/v1/query-request?requestId=13ffa4e8-0dff-47dc-933c-a163ba8954ec&clientStartTime=1748381473915&retryCount=12&retryReason=None&request_guid=3e7ae38a-6771-4dbf-893c-7549295ee738
[2025-05-27T21:33:26.840+0000] {utils.py:78} INFO - WARNING:snowflake.connector.vendored.urllib3.connectionpool:Retrying (Retry(total=0, connect=None, read=None, redirect=None, status=None)) after connection broken by 'NewConnectionError('<snowflake.connector.vendored.urllib3.connection.HTTPSConnection object at 0x7f0344678fa0>: Failed to establish a new connection: [Errno -2] Name or service not known')': /queries/v1/query-request?requestId=efcf9181-7063-4061-9a57-a0bd7ffcafb1&clientStartTime=1748381472810&retryCount=11&retryReason=None&request_guid=c68772f4-932e-45b8-8b9f-7f63787f81c4
[2025-05-27T21:33:28.585+0000] {utils.py:78} INFO - WARNING:snowflake.connector.vendored.urllib3.connectionpool:Retrying (Retry(total=0, connect=None, read=None, redirect=None, status=None)) after connection broken by 'NewConnectionError('<snowflake.connector.vendored.urllib3.connection.HTTPSConnection object at 0x7f03446792d0>: Failed to establish a new connection: [Errno -2] Name or service not known')': /queries/v1/query-request?requestId=13ffa4e8-0dff-47dc-933c-a163ba8954ec&clientStartTime=1748381473915&retryCount=13&retryReason=None&request_guid=00dd61cd-341d-45b0-ad1f-ceeaaf6f7bc2
[2025-05-27T21:33:28.745+0000] {utils.py:78} INFO - WARNING:snowflake.connector.vendored.urllib3.connectionpool:Retrying (Retry(total=0, connect=None, read=None, redirect=None, status=None)) after connection broken by 'NewConnectionError('<snowflake.connector.vendored.urllib3.connection.HTTPSConnection object at 0x7f034467a770>: Failed to establish a new connection: [Errno -2] Name or service not known')': /queries/v1/query-request?requestId=13ffa4e8-0dff-47dc-933c-a163ba8954ec&clientStartTime=1748381473915&retryCount=14&retryReason=None&request_guid=9e89ffe7-27aa-42c8-a751-705b301c6664
[2025-05-27T21:33:31.344+0000] {utils.py:78} INFO - WARNING:snowflake.connector.vendored.urllib3.connectionpool:Retrying (Retry(total=0, connect=None, read=None, redirect=None, status=None)) after connection broken by 'NewConnectionError('<snowflake.connector.vendored.urllib3.connection.HTTPSConnection object at 0x7f03446e3d60>: Failed to establish a new connection: [Errno -2] Name or service not known')': /queries/v1/query-request?requestId=21ea1b2e-06d7-4bf7-a91a-b368df548183&clientStartTime=1748381473946&retryCount=11&retryReason=None&request_guid=0f413e54-215c-4845-8e57-cd53c54dd13d
[2025-05-27T21:33:31.425+0000] {utils.py:78} INFO - WARNING:snowflake.connector.vendored.urllib3.connectionpool:Retrying (Retry(total=0, connect=None, read=None, redirect=None, status=None)) after connection broken by 'NewConnectionError('<snowflake.connector.vendored.urllib3.connection.HTTPSConnection object at 0x7f03446e0bb0>: Failed to establish a new connection: [Errno -2] Name or service not known')': /queries/v1/query-request?requestId=21ea1b2e-06d7-4bf7-a91a-b368df548183&clientStartTime=1748381473946&retryCount=12&retryReason=None&request_guid=6cb9ee94-89c8-4efc-a41c-3fef362b8d1d
[2025-05-27T21:33:37.917+0000] {utils.py:78} INFO - WARNING:snowflake.connector.vendored.urllib3.connectionpool:Retrying (Retry(total=0, connect=None, read=None, redirect=None, status=None)) after connection broken by 'NewConnectionError('<snowflake.connector.vendored.urllib3.connection.HTTPSConnection object at 0x7f035ca4aa70>: Failed to establish a new connection: [Errno -2] Name or service not known')': /queries/v1/query-request?requestId=efcf9181-7063-4061-9a57-a0bd7ffcafb1&clientStartTime=1748381472810&retryCount=12&retryReason=None&request_guid=e00e8394-ce00-4e81-9ef4-7972d0ac6eb5
[2025-05-27T21:33:38.073+0000] {utils.py:78} INFO - WARNING:snowflake.connector.vendored.urllib3.connectionpool:Retrying (Retry(total=0, connect=None, read=None, redirect=None, status=None)) after connection broken by 'NewConnectionError('<snowflake.connector.vendored.urllib3.connection.HTTPSConnection object at 0x7f03446793f0>: Failed to establish a new connection: [Errno -2] Name or service not known')': /queries/v1/query-request?requestId=f2758078-2b8e-46e0-a7d2-faf366acc5db&clientStartTime=1748381472965&retryCount=13&retryReason=None&request_guid=9afebd5c-5273-47d1-a027-d1795ca0be17
[2025-05-27T21:33:43.856+0000] {utils.py:78} INFO - WARNING:snowflake.connector.vendored.urllib3.connectionpool:Retrying (Retry(total=0, connect=None, read=None, redirect=None, status=None)) after connection broken by 'NewConnectionError('<snowflake.connector.vendored.urllib3.connection.HTTPSConnection object at 0x7f0344679990>: Failed to establish a new connection: [Errno -2] Name or service not known')': /queries/v1/query-request?requestId=13ffa4e8-0dff-47dc-933c-a163ba8954ec&clientStartTime=1748381473915&retryCount=15&retryReason=None&request_guid=21b2a152-ea21-4df3-bf01-75fb5299191b
[2025-05-27T21:33:44.149+0000] {utils.py:78} INFO - WARNING:snowflake.connector.vendored.urllib3.connectionpool:Retrying (Retry(total=0, connect=None, read=None, redirect=None, status=None)) after connection broken by 'NewConnectionError('<snowflake.connector.vendored.urllib3.connection.HTTPSConnection object at 0x7f034467aa70>: Failed to establish a new connection: [Errno -2] Name or service not known')': /queries/v1/query-request?requestId=f2758078-2b8e-46e0-a7d2-faf366acc5db&clientStartTime=1748381472965&retryCount=14&retryReason=None&request_guid=70d03eb8-f245-419f-ad23-7c1adf90da6c
[2025-05-27T21:33:45.500+0000] {utils.py:78} INFO - WARNING:snowflake.connector.vendored.urllib3.connectionpool:Retrying (Retry(total=0, connect=None, read=None, redirect=None, status=None)) after connection broken by 'NewConnectionError('<snowflake.connector.vendored.urllib3.connection.HTTPSConnection object at 0x7f0344679450>: Failed to establish a new connection: [Errno -2] Name or service not known')': /queries/v1/query-request?requestId=21ea1b2e-06d7-4bf7-a91a-b368df548183&clientStartTime=1748381473946&retryCount=13&retryReason=None&request_guid=8687c5b1-e9f0-4bdc-86d2-65287b9c5850
[2025-05-27T21:33:49.020+0000] {utils.py:78} INFO - WARNING:snowflake.connector.vendored.urllib3.connectionpool:Retrying (Retry(total=0, connect=None, read=None, redirect=None, status=None)) after connection broken by 'NewConnectionError('<snowflake.connector.vendored.urllib3.connection.HTTPSConnection object at 0x7f03446e1cf0>: Failed to establish a new connection: [Errno -2] Name or service not known')': /queries/v1/query-request?requestId=efcf9181-7063-4061-9a57-a0bd7ffcafb1&clientStartTime=1748381472810&retryCount=13&retryReason=None&request_guid=ca0bab65-2d55-4c9b-9e89-6c86c0439d96
[2025-05-27T21:33:49.256+0000] {utils.py:78} INFO - WARNING:snowflake.connector.vendored.urllib3.connectionpool:Retrying (Retry(total=0, connect=None, read=None, redirect=None, status=None)) after connection broken by 'NewConnectionError('<snowflake.connector.vendored.urllib3.connection.HTTPSConnection object at 0x7f03446e0cd0>: Failed to establish a new connection: [Errno -2] Name or service not known')': /queries/v1/query-request?requestId=f2758078-2b8e-46e0-a7d2-faf366acc5db&clientStartTime=1748381472965&retryCount=15&retryReason=None&request_guid=9203f5ea-20bd-4ee7-9dce-22bc78226045
[2025-05-27T21:33:51.940+0000] {utils.py:78} INFO - WARNING:snowflake.connector.vendored.urllib3.connectionpool:Retrying (Retry(total=0, connect=None, read=None, redirect=None, status=None)) after connection broken by 'NewConnectionError('<snowflake.connector.vendored.urllib3.connection.HTTPSConnection object at 0x7f03446e3f10>: Failed to establish a new connection: [Errno -2] Name or service not known')': /queries/v1/query-request?requestId=13ffa4e8-0dff-47dc-933c-a163ba8954ec&clientStartTime=1748381473915&retryCount=16&retryReason=None&request_guid=c4c02cd4-cd9e-47a7-be94-1990b2a5cb46
[2025-05-27T21:33:57.131+0000] {utils.py:78} INFO - WARNING:snowflake.connector.vendored.urllib3.connectionpool:Retrying (Retry(total=0, connect=None, read=None, redirect=None, status=None)) after connection broken by 'NewConnectionError('<snowflake.connector.vendored.urllib3.connection.HTTPSConnection object at 0x7f034467ad40>: Failed to establish a new connection: [Errno -2] Name or service not known')': /queries/v1/query-request?requestId=efcf9181-7063-4061-9a57-a0bd7ffcafb1&clientStartTime=1748381472810&retryCount=14&retryReason=None&request_guid=c67fe724-bba6-4cf6-844e-81d1fc2b7ad7
[2025-05-27T21:34:01.226+0000] {utils.py:78} INFO - WARNING:snowflake.connector.vendored.urllib3.connectionpool:Retrying (Retry(total=0, connect=None, read=None, redirect=None, status=None)) after connection broken by 'NewConnectionError('<snowflake.connector.vendored.urllib3.connection.HTTPSConnection object at 0x7f03446795d0>: Failed to establish a new connection: [Errno -2] Name or service not known')': /queries/v1/query-request?requestId=efcf9181-7063-4061-9a57-a0bd7ffcafb1&clientStartTime=1748381472810&retryCount=15&retryReason=None&request_guid=46ff311a-4686-4686-bff6-d7774ccc00ee
[2025-05-27T21:34:01.299+0000] {utils.py:78} INFO - WARNING:snowflake.connector.vendored.urllib3.connectionpool:Retrying (Retry(total=0, connect=None, read=None, redirect=None, status=None)) after connection broken by 'NewConnectionError('<snowflake.connector.vendored.urllib3.connection.HTTPSConnection object at 0x7f034467a4d0>: Failed to establish a new connection: [Errno -2] Name or service not known')': /queries/v1/query-request?requestId=efcf9181-7063-4061-9a57-a0bd7ffcafb1&clientStartTime=1748381472810&retryCount=16&retryReason=None&request_guid=88fec9e4-fa9d-479b-aa3e-b6b705966ef5
[2025-05-27T21:34:01.594+0000] {utils.py:78} INFO - WARNING:snowflake.connector.vendored.urllib3.connectionpool:Retrying (Retry(total=0, connect=None, read=None, redirect=None, status=None)) after connection broken by 'NewConnectionError('<snowflake.connector.vendored.urllib3.connection.HTTPSConnection object at 0x7f03446e0550>: Failed to establish a new connection: [Errno -2] Name or service not known')': /queries/v1/query-request?requestId=21ea1b2e-06d7-4bf7-a91a-b368df548183&clientStartTime=1748381473946&retryCount=14&retryReason=None&request_guid=2e046ea8-7b99-414d-9dca-f9e4910a9539
[2025-05-27T21:34:02.033+0000] {utils.py:78} INFO - WARNING:snowflake.connector.vendored.urllib3.connectionpool:Retrying (Retry(total=0, connect=None, read=None, redirect=None, status=None)) after connection broken by 'NewConnectionError('<snowflake.connector.vendored.urllib3.connection.HTTPSConnection object at 0x7f03446e36a0>: Failed to establish a new connection: [Errno -2] Name or service not known')': /queries/v1/query-request?requestId=13ffa4e8-0dff-47dc-933c-a163ba8954ec&clientStartTime=1748381473915&retryCount=17&retryReason=None&request_guid=c2cddefc-0545-4f53-9ff5-6dba4472fd67
[2025-05-27T21:34:04.120+0000] {utils.py:78} INFO - WARNING:snowflake.connector.vendored.urllib3.connectionpool:Retrying (Retry(total=0, connect=None, read=None, redirect=None, status=None)) after connection broken by 'NewConnectionError('<snowflake.connector.vendored.urllib3.connection.HTTPSConnection object at 0x7f03446e3f70>: Failed to establish a new connection: [Errno -2] Name or service not known')': /queries/v1/query-request?requestId=13ffa4e8-0dff-47dc-933c-a163ba8954ec&clientStartTime=1748381473915&retryCount=18&retryReason=None&request_guid=697b9faf-8053-4490-afb7-ddbadc15d379
[2025-05-27T21:34:04.361+0000] {utils.py:78} INFO - WARNING:snowflake.connector.vendored.urllib3.connectionpool:Retrying (Retry(total=0, connect=None, read=None, redirect=None, status=None)) after connection broken by 'NewConnectionError('<snowflake.connector.vendored.urllib3.connection.HTTPSConnection object at 0x7f0344679180>: Failed to establish a new connection: [Errno -2] Name or service not known')': /queries/v1/query-request?requestId=f2758078-2b8e-46e0-a7d2-faf366acc5db&clientStartTime=1748381472965&retryCount=16&retryReason=None&request_guid=11da0e8b-2a28-4e36-99da-7829a5c18624
[2025-05-27T21:34:05.200+0000] {utils.py:78} INFO - WARNING:snowflake.connector.vendored.urllib3.connectionpool:Retrying (Retry(total=0, connect=None, read=None, redirect=None, status=None)) after connection broken by 'NewConnectionError('<snowflake.connector.vendored.urllib3.connection.HTTPSConnection object at 0x7f034467aad0>: Failed to establish a new connection: [Errno -2] Name or service not known')': /queries/v1/query-request?requestId=13ffa4e8-0dff-47dc-933c-a163ba8954ec&clientStartTime=1748381473915&retryCount=19&retryReason=None&request_guid=41b990ca-08d6-4ae6-8613-9197add94092
[2025-05-27T21:34:05.420+0000] {utils.py:78} INFO - WARNING:snowflake.connector.vendored.urllib3.connectionpool:Retrying (Retry(total=0, connect=None, read=None, redirect=None, status=None)) after connection broken by 'NewConnectionError('<snowflake.connector.vendored.urllib3.connection.HTTPSConnection object at 0x7f03446e3550>: Failed to establish a new connection: [Errno -2] Name or service not known')': /queries/v1/query-request?requestId=f2758078-2b8e-46e0-a7d2-faf366acc5db&clientStartTime=1748381472965&retryCount=17&retryReason=None&request_guid=ff36aef9-4422-40cd-9a71-a27bb9c8dea5
[2025-05-27T21:34:08.273+0000] {utils.py:78} INFO - WARNING:snowflake.connector.vendored.urllib3.connectionpool:Retrying (Retry(total=0, connect=None, read=None, redirect=None, status=None)) after connection broken by 'NewConnectionError('<snowflake.connector.vendored.urllib3.connection.HTTPSConnection object at 0x7f03446e1fc0>: Failed to establish a new connection: [Errno -2] Name or service not known')': /queries/v1/query-request?requestId=13ffa4e8-0dff-47dc-933c-a163ba8954ec&clientStartTime=1748381473915&retryCount=20&retryReason=None&request_guid=2fbbbafc-c266-4dbe-956c-40143d34c499
[2025-05-27T21:34:10.340+0000] {utils.py:78} INFO - WARNING:snowflake.connector.vendored.urllib3.connectionpool:Retrying (Retry(total=0, connect=None, read=None, redirect=None, status=None)) after connection broken by 'NewConnectionError('<snowflake.connector.vendored.urllib3.connection.HTTPSConnection object at 0x7f03446e1630>: Failed to establish a new connection: [Errno -2] Name or service not known')': /queries/v1/query-request?requestId=13ffa4e8-0dff-47dc-933c-a163ba8954ec&clientStartTime=1748381473915&retryCount=21&retryReason=None&request_guid=9841c827-7b60-41e1-93ad-039d5a9b8d28
[2025-05-27T21:34:11.370+0000] {utils.py:78} INFO - WARNING:snowflake.connector.vendored.urllib3.connectionpool:Retrying (Retry(total=0, connect=None, read=None, redirect=None, status=None)) after connection broken by 'NewConnectionError('<snowflake.connector.vendored.urllib3.connection.HTTPSConnection object at 0x7f03446b9570>: Failed to establish a new connection: [Errno -2] Name or service not known')': /queries/v1/query-request?requestId=efcf9181-7063-4061-9a57-a0bd7ffcafb1&clientStartTime=1748381472810&retryCount=17&retryReason=None&request_guid=ac558418-a62c-4fc7-8978-a236ad28c1ce
[2025-05-27T21:34:11.510+0000] {utils.py:78} INFO - WARNING:snowflake.connector.vendored.urllib3.connectionpool:Retrying (Retry(total=0, connect=None, read=None, redirect=None, status=None)) after connection broken by 'NewConnectionError('<snowflake.connector.vendored.urllib3.connection.HTTPSConnection object at 0x7f03446b98d0>: Failed to establish a new connection: [Errno -2] Name or service not known')': /queries/v1/query-request?requestId=f2758078-2b8e-46e0-a7d2-faf366acc5db&clientStartTime=1748381472965&retryCount=18&retryReason=None&request_guid=8dbf9d98-5e77-4f9a-a147-d230d32d4b7e
[2025-05-27T21:34:13.439+0000] {utils.py:78} INFO - WARNING:snowflake.connector.vendored.urllib3.connectionpool:Retrying (Retry(total=0, connect=None, read=None, redirect=None, status=None)) after connection broken by 'NewConnectionError('<snowflake.connector.vendored.urllib3.connection.HTTPSConnection object at 0x7f03446e1fc0>: Failed to establish a new connection: [Errno -2] Name or service not known')': /queries/v1/query-request?requestId=efcf9181-7063-4061-9a57-a0bd7ffcafb1&clientStartTime=1748381472810&retryCount=18&retryReason=None&request_guid=fc97a3db-506c-484d-ba1f-d245b1a4ed7c
[2025-05-27T21:34:13.517+0000] {utils.py:78} INFO - WARNING:snowflake.connector.vendored.urllib3.connectionpool:Retrying (Retry(total=0, connect=None, read=None, redirect=None, status=None)) after connection broken by 'NewConnectionError('<snowflake.connector.vendored.urllib3.connection.HTTPSConnection object at 0x7f03446e1180>: Failed to establish a new connection: [Errno -2] Name or service not known')': /queries/v1/query-request?requestId=efcf9181-7063-4061-9a57-a0bd7ffcafb1&clientStartTime=1748381472810&retryCount=19&retryReason=None&request_guid=9fc47bc6-7d97-4d11-ba4e-8c5c61be711e
[2025-05-27T21:34:17.695+0000] {utils.py:78} INFO - WARNING:snowflake.connector.vendored.urllib3.connectionpool:Retrying (Retry(total=0, connect=None, read=None, redirect=None, status=None)) after connection broken by 'NewConnectionError('<snowflake.connector.vendored.urllib3.connection.HTTPSConnection object at 0x7f034467ad40>: Failed to establish a new connection: [Errno -2] Name or service not known')': /queries/v1/query-request?requestId=21ea1b2e-06d7-4bf7-a91a-b368df548183&clientStartTime=1748381473946&retryCount=15&retryReason=None&request_guid=79e4c53e-77e5-4394-b321-7a0aa2f8c984
[2025-05-27T21:34:19.603+0000] {utils.py:78} INFO - WARNING:snowflake.connector.vendored.urllib3.connectionpool:Retrying (Retry(total=0, connect=None, read=None, redirect=None, status=None)) after connection broken by 'NewConnectionError('<snowflake.connector.vendored.urllib3.connection.HTTPSConnection object at 0x7f0344678220>: Failed to establish a new connection: [Errno -2] Name or service not known')': /queries/v1/query-request?requestId=f2758078-2b8e-46e0-a7d2-faf366acc5db&clientStartTime=1748381472965&retryCount=19&retryReason=None&request_guid=99d752cb-39a1-4ca5-9e7d-218c9056549f
[2025-05-27T21:34:22.688+0000] {utils.py:78} INFO - WARNING:snowflake.connector.vendored.urllib3.connectionpool:Retrying (Retry(total=0, connect=None, read=None, redirect=None, status=None)) after connection broken by 'NewConnectionError('<snowflake.connector.vendored.urllib3.connection.HTTPSConnection object at 0x7f03446b8550>: Failed to establish a new connection: [Errno -2] Name or service not known')': /queries/v1/query-request?requestId=f2758078-2b8e-46e0-a7d2-faf366acc5db&clientStartTime=1748381472965&retryCount=20&retryReason=None&request_guid=ea45ddab-b49b-4ee6-ac74-ca2493eeaa9b
[2025-05-27T21:34:25.410+0000] {utils.py:78} INFO - WARNING:snowflake.connector.vendored.urllib3.connectionpool:Retrying (Retry(total=0, connect=None, read=None, redirect=None, status=None)) after connection broken by 'NewConnectionError('<snowflake.connector.vendored.urllib3.connection.HTTPSConnection object at 0x7f03446bbfa0>: Failed to establish a new connection: [Errno -2] Name or service not known')': /queries/v1/query-request?requestId=13ffa4e8-0dff-47dc-933c-a163ba8954ec&clientStartTime=1748381473915&retryCount=22&retryReason=None&request_guid=37f496d1-b9a3-4a83-82d9-e6a5d49157ff
[2025-05-27T21:34:28.605+0000] {utils.py:78} INFO - WARNING:snowflake.connector.vendored.urllib3.connectionpool:Retrying (Retry(total=0, connect=None, read=None, redirect=None, status=None)) after connection broken by 'NewConnectionError('<snowflake.connector.vendored.urllib3.connection.HTTPSConnection object at 0x7f03446ba770>: Failed to establish a new connection: [Errno -2] Name or service not known')': /queries/v1/query-request?requestId=efcf9181-7063-4061-9a57-a0bd7ffcafb1&clientStartTime=1748381472810&retryCount=20&retryReason=None&request_guid=7309c548-a7c3-4088-800e-3ff83170f2b7
[2025-05-27T21:34:28.657+0000] {utils.py:78} INFO - WARNING:snowflake.connector.vendored.urllib3.connectionpool:Retrying (Retry(total=0, connect=None, read=None, redirect=None, status=None)) after connection broken by 'NewConnectionError('<snowflake.connector.vendored.urllib3.connection.HTTPSConnection object at 0x7f034467b8e0>: Failed to establish a new connection: [Errno -2] Name or service not known')': /queries/v1/query-request?requestId=efcf9181-7063-4061-9a57-a0bd7ffcafb1&clientStartTime=1748381472810&retryCount=21&retryReason=None&request_guid=257c6bef-d3c8-43fd-9b7a-ff9d8246341b
[2025-05-27T21:34:31.707+0000] {utils.py:78} INFO - WARNING:snowflake.connector.vendored.urllib3.connectionpool:Retrying (Retry(total=0, connect=None, read=None, redirect=None, status=None)) after connection broken by 'NewConnectionError('<snowflake.connector.vendored.urllib3.connection.HTTPSConnection object at 0x7f03446e3eb0>: Failed to establish a new connection: [Errno -2] Name or service not known')': /queries/v1/query-request?requestId=efcf9181-7063-4061-9a57-a0bd7ffcafb1&clientStartTime=1748381472810&retryCount=22&retryReason=None&request_guid=e774052b-dd7b-4c87-9896-d4941315cd81
[2025-05-27T21:34:31.781+0000] {utils.py:78} INFO - WARNING:snowflake.connector.vendored.urllib3.connectionpool:Retrying (Retry(total=0, connect=None, read=None, redirect=None, status=None)) after connection broken by 'NewConnectionError('<snowflake.connector.vendored.urllib3.connection.HTTPSConnection object at 0x7f03446e1390>: Failed to establish a new connection: [Errno -2] Name or service not known')': /queries/v1/query-request?requestId=21ea1b2e-06d7-4bf7-a91a-b368df548183&clientStartTime=1748381473946&retryCount=16&retryReason=None&request_guid=13fe7e16-b41c-478d-879b-66431cb0e6b9
[2025-05-27T21:34:32.781+0000] {utils.py:78} INFO - WARNING:snowflake.connector.vendored.urllib3.connectionpool:Retrying (Retry(total=0, connect=None, read=None, redirect=None, status=None)) after connection broken by 'NewConnectionError('<snowflake.connector.vendored.urllib3.connection.HTTPSConnection object at 0x7f03446b8370>: Failed to establish a new connection: [Errno -2] Name or service not known')': /queries/v1/query-request?requestId=f2758078-2b8e-46e0-a7d2-faf366acc5db&clientStartTime=1748381472965&retryCount=21&retryReason=None&request_guid=877396ff-b55a-48a1-9047-2785c4ce083d
[2025-05-27T21:34:33.458+0000] {utils.py:78} INFO - WARNING:snowflake.connector.vendored.urllib3.connectionpool:Retrying (Retry(total=0, connect=None, read=None, redirect=None, status=None)) after connection broken by 'NewConnectionError('<snowflake.connector.vendored.urllib3.connection.HTTPSConnection object at 0x7f03467e76d0>: Failed to establish a new connection: [Errno -2] Name or service not known')': /queries/v1/query-request?requestId=13ffa4e8-0dff-47dc-933c-a163ba8954ec&clientStartTime=1748381473915&retryCount=23&retryReason=None&request_guid=2360c3a2-05eb-4f8b-b010-036012de05f1
[2025-05-27T21:34:33.888+0000] {utils.py:78} INFO - WARNING:snowflake.connector.vendored.urllib3.connectionpool:Retrying (Retry(total=0, connect=None, read=None, redirect=None, status=None)) after connection broken by 'NewConnectionError('<snowflake.connector.vendored.urllib3.connection.HTTPSConnection object at 0x7f03467e6fe0>: Failed to establish a new connection: [Errno -2] Name or service not known')': /queries/v1/query-request?requestId=f2758078-2b8e-46e0-a7d2-faf366acc5db&clientStartTime=1748381472965&retryCount=22&retryReason=None&request_guid=3fd2bd6a-96dc-4c4b-b179-11c41625ae3d
[2025-05-27T21:34:34.979+0000] {utils.py:78} INFO - WARNING:snowflake.connector.vendored.urllib3.connectionpool:Retrying (Retry(total=0, connect=None, read=None, redirect=None, status=None)) after connection broken by 'NewConnectionError('<snowflake.connector.vendored.urllib3.connection.HTTPSConnection object at 0x7f03446b94b0>: Failed to establish a new connection: [Errno -2] Name or service not known')': /queries/v1/query-request?requestId=f2758078-2b8e-46e0-a7d2-faf366acc5db&clientStartTime=1748381472965&retryCount=23&retryReason=None&request_guid=8fd2ccd3-319b-4a9e-ada3-425faa91a6f1
[2025-05-27T21:34:37.768+0000] {utils.py:78} INFO - WARNING:snowflake.connector.vendored.urllib3.connectionpool:Retrying (Retry(total=0, connect=None, read=None, redirect=None, status=None)) after connection broken by 'NewConnectionError('<snowflake.connector.vendored.urllib3.connection.HTTPSConnection object at 0x7f0344678280>: Failed to establish a new connection: [Errno -2] Name or service not known')': /queries/v1/query-request?requestId=efcf9181-7063-4061-9a57-a0bd7ffcafb1&clientStartTime=1748381472810&retryCount=23&retryReason=None&request_guid=876c39fb-f32f-47c4-bffd-422c52d66dd0
[2025-05-27T21:34:40.848+0000] {utils.py:78} INFO - WARNING:snowflake.connector.vendored.urllib3.connectionpool:Retrying (Retry(total=0, connect=None, read=None, redirect=None, status=None)) after connection broken by 'NewConnectionError('<snowflake.connector.vendored.urllib3.connection.HTTPSConnection object at 0x7f03467e4a30>: Failed to establish a new connection: [Errno -2] Name or service not known')': /queries/v1/query-request?requestId=21ea1b2e-06d7-4bf7-a91a-b368df548183&clientStartTime=1748381473946&retryCount=17&retryReason=None&request_guid=1dd85040-cded-445f-8c04-63d2f4189dbf
[2025-05-27T21:34:44.515+0000] {utils.py:78} INFO - WARNING:snowflake.connector.vendored.urllib3.connectionpool:Retrying (Retry(total=0, connect=None, read=None, redirect=None, status=None)) after connection broken by 'NewConnectionError('<snowflake.connector.vendored.urllib3.connection.HTTPSConnection object at 0x7f03467e5150>: Failed to establish a new connection: [Errno -2] Name or service not known')': /queries/v1/query-request?requestId=13ffa4e8-0dff-47dc-933c-a163ba8954ec&clientStartTime=1748381473915&retryCount=24&retryReason=None&request_guid=73d3ed19-fea0-47b8-aeb7-f838b43c7885
[2025-05-27T21:34:44.817+0000] {utils.py:78} INFO - WARNING:snowflake.connector.vendored.urllib3.connectionpool:Retrying (Retry(total=0, connect=None, read=None, redirect=None, status=None)) after connection broken by 'NewConnectionError('<snowflake.connector.vendored.urllib3.connection.HTTPSConnection object at 0x7f03467e48e0>: Failed to establish a new connection: [Errno -2] Name or service not known')': /queries/v1/query-request?requestId=efcf9181-7063-4061-9a57-a0bd7ffcafb1&clientStartTime=1748381472810&retryCount=24&retryReason=None&request_guid=2264d47f-d4f3-457f-a67b-bc383b91e303
[2025-05-27T21:34:47.885+0000] {utils.py:78} INFO - WARNING:snowflake.connector.vendored.urllib3.connectionpool:Retrying (Retry(total=0, connect=None, read=None, redirect=None, status=None)) after connection broken by 'NewConnectionError('<snowflake.connector.vendored.urllib3.connection.HTTPSConnection object at 0x7f03446795d0>: Failed to establish a new connection: [Errno -2] Name or service not known')': /queries/v1/query-request?requestId=efcf9181-7063-4061-9a57-a0bd7ffcafb1&clientStartTime=1748381472810&retryCount=25&retryReason=None&request_guid=b8bf6c21-942f-4c12-aeb0-b971efe23d6a
[2025-05-27T21:34:49.039+0000] {utils.py:78} INFO - WARNING:snowflake.connector.vendored.urllib3.connectionpool:Retrying (Retry(total=0, connect=None, read=None, redirect=None, status=None)) after connection broken by 'NewConnectionError('<snowflake.connector.vendored.urllib3.connection.HTTPSConnection object at 0x7f03467e7880>: Failed to establish a new connection: [Errno -2] Name or service not known')': /queries/v1/query-request?requestId=f2758078-2b8e-46e0-a7d2-faf366acc5db&clientStartTime=1748381472965&retryCount=24&retryReason=None&request_guid=67775fb1-4323-41ce-8300-9c6250066aa3
[2025-05-27T21:34:55.933+0000] {utils.py:78} INFO - WARNING:snowflake.connector.vendored.urllib3.connectionpool:Retrying (Retry(total=0, connect=None, read=None, redirect=None, status=None)) after connection broken by 'NewConnectionError('<snowflake.connector.vendored.urllib3.connection.HTTPSConnection object at 0x7f03467e5ea0>: Failed to establish a new connection: [Errno -2] Name or service not known')': /queries/v1/query-request?requestId=21ea1b2e-06d7-4bf7-a91a-b368df548183&clientStartTime=1748381473946&retryCount=18&retryReason=None&request_guid=7f57f4eb-ed68-40ec-91e0-6384e5f128f7
[2025-05-27T21:34:57.568+0000] {utils.py:78} INFO - WARNING:snowflake.connector.vendored.urllib3.connectionpool:Retrying (Retry(total=0, connect=None, read=None, redirect=None, status=None)) after connection broken by 'NewConnectionError('<snowflake.connector.vendored.urllib3.connection.HTTPSConnection object at 0x7f03467e7c10>: Failed to establish a new connection: [Errno -2] Name or service not known')': /queries/v1/query-request?requestId=13ffa4e8-0dff-47dc-933c-a163ba8954ec&clientStartTime=1748381473915&retryCount=25&retryReason=None&request_guid=50183ec0-8198-428a-b145-478a735a8d30
[2025-05-27T21:34:58.000+0000] {utils.py:78} INFO - WARNING:snowflake.connector.vendored.urllib3.connectionpool:Retrying (Retry(total=0, connect=None, read=None, redirect=None, status=None)) after connection broken by 'NewConnectionError('<snowflake.connector.vendored.urllib3.connection.HTTPSConnection object at 0x7f03467e5bd0>: Failed to establish a new connection: [Errno -2] Name or service not known')': /queries/v1/query-request?requestId=21ea1b2e-06d7-4bf7-a91a-b368df548183&clientStartTime=1748381473946&retryCount=19&retryReason=None&request_guid=372e5df0-9918-4434-9c28-6d57fbf101e9
[2025-05-27T21:34:58.141+0000] {utils.py:78} INFO - WARNING:snowflake.connector.vendored.urllib3.connectionpool:Retrying (Retry(total=0, connect=None, read=None, redirect=None, status=None)) after connection broken by 'NewConnectionError('<snowflake.connector.vendored.urllib3.connection.HTTPSConnection object at 0x7f03467e4670>: Failed to establish a new connection: [Errno -2] Name or service not known')': /queries/v1/query-request?requestId=f2758078-2b8e-46e0-a7d2-faf366acc5db&clientStartTime=1748381472965&retryCount=25&retryReason=None&request_guid=5cf4f4a6-73ca-4c95-bbcb-48c2acfa39f8
[2025-05-27T21:34:59.612+0000] {utils.py:78} INFO - WARNING:snowflake.connector.vendored.urllib3.connectionpool:Retrying (Retry(total=0, connect=None, read=None, redirect=None, status=None)) after connection broken by 'NewConnectionError('<snowflake.connector.vendored.urllib3.connection.HTTPSConnection object at 0x7f03467e4520>: Failed to establish a new connection: [Errno -2] Name or service not known')': /queries/v1/query-request?requestId=13ffa4e8-0dff-47dc-933c-a163ba8954ec&clientStartTime=1748381473915&retryCount=26&retryReason=None&request_guid=91336c13-986d-470e-b440-0dc0a5813831
[2025-05-27T21:34:59.956+0000] {utils.py:78} INFO - WARNING:snowflake.connector.vendored.urllib3.connectionpool:Retrying (Retry(total=0, connect=None, read=None, redirect=None, status=None)) after connection broken by 'NewConnectionError('<snowflake.connector.vendored.urllib3.connection.HTTPSConnection object at 0x7f03467e5480>: Failed to establish a new connection: [Errno -2] Name or service not known')': /queries/v1/query-request?requestId=efcf9181-7063-4061-9a57-a0bd7ffcafb1&clientStartTime=1748381472810&retryCount=26&retryReason=None&request_guid=b75ee8ab-7503-45aa-aaac-853b8cb95db6
[2025-05-27T21:35:07.756+0000] {utils.py:78} INFO - WARNING:snowflake.connector.vendored.urllib3.connectionpool:Retrying (Retry(total=0, connect=None, read=None, redirect=None, status=None)) after connection broken by 'NewConnectionError('<snowflake.connector.vendored.urllib3.connection.HTTPSConnection object at 0x7f035c99ab30>: Failed to establish a new connection: [Errno -2] Name or service not known')': /queries/v1/query-request?requestId=13ffa4e8-0dff-47dc-933c-a163ba8954ec&clientStartTime=1748381473915&retryCount=27&retryReason=None&request_guid=b6276827-d545-49af-ae5c-1bc1d7c2940d
[2025-05-27T21:35:11.075+0000] {utils.py:78} INFO - WARNING:snowflake.connector.vendored.urllib3.connectionpool:Retrying (Retry(total=0, connect=None, read=None, redirect=None, status=None)) after connection broken by 'NewConnectionError('<snowflake.connector.vendored.urllib3.connection.HTTPSConnection object at 0x7f036fcc3f70>: Failed to establish a new connection: [Errno -2] Name or service not known')': /queries/v1/query-request?requestId=21ea1b2e-06d7-4bf7-a91a-b368df548183&clientStartTime=1748381473946&retryCount=20&retryReason=None&request_guid=4a081e38-bfdf-4da6-ba5b-b26b81f1c199
[2025-05-27T21:35:12.181+0000] {utils.py:78} INFO - WARNING:snowflake.connector.vendored.urllib3.connectionpool:Retrying (Retry(total=0, connect=None, read=None, redirect=None, status=None)) after connection broken by 'NewConnectionError('<snowflake.connector.vendored.urllib3.connection.HTTPSConnection object at 0x7f036fcc2470>: Failed to establish a new connection: [Errno -2] Name or service not known')': /queries/v1/query-request?requestId=21ea1b2e-06d7-4bf7-a91a-b368df548183&clientStartTime=1748381473946&retryCount=21&retryReason=None&request_guid=1aa896ef-55f3-42b3-b3c0-a985a55fc99c
[2025-05-27T21:35:13.079+0000] {utils.py:78} INFO - WARNING:snowflake.connector.vendored.urllib3.connectionpool:Retrying (Retry(total=0, connect=None, read=None, redirect=None, status=None)) after connection broken by 'NewConnectionError('<snowflake.connector.vendored.urllib3.connection.HTTPSConnection object at 0x7f036fcc0be0>: Failed to establish a new connection: [Errno -2] Name or service not known')': /queries/v1/query-request?requestId=efcf9181-7063-4061-9a57-a0bd7ffcafb1&clientStartTime=1748381472810&retryCount=27&retryReason=None&request_guid=6999d497-b00b-4ac5-b513-35b7dc0c2ffd
[2025-05-27T21:35:13.143+0000] {utils.py:78} INFO - WARNING:snowflake.connector.vendored.urllib3.connectionpool:Retrying (Retry(total=0, connect=None, read=None, redirect=None, status=None)) after connection broken by 'NewConnectionError('<snowflake.connector.vendored.urllib3.connection.HTTPSConnection object at 0x7f035c99aaa0>: Failed to establish a new connection: [Errno -2] Name or service not known')': /queries/v1/query-request?requestId=efcf9181-7063-4061-9a57-a0bd7ffcafb1&clientStartTime=1748381472810&retryCount=28&retryReason=None&request_guid=b7e14b81-5247-47b6-beb4-e84c6d2fc21a
[2025-05-27T21:35:13.247+0000] {utils.py:78} INFO - WARNING:snowflake.connector.vendored.urllib3.connectionpool:Retrying (Retry(total=0, connect=None, read=None, redirect=None, status=None)) after connection broken by 'NewConnectionError('<snowflake.connector.vendored.urllib3.connection.HTTPSConnection object at 0x7f03467e5f00>: Failed to establish a new connection: [Errno -2] Name or service not known')': /queries/v1/query-request?requestId=f2758078-2b8e-46e0-a7d2-faf366acc5db&clientStartTime=1748381472965&retryCount=26&retryReason=None&request_guid=1f248b9a-30e3-4b5b-8d5c-60ada5b56708
[2025-05-27T21:35:16.891+0000] {utils.py:78} INFO - WARNING:snowflake.connector.vendored.urllib3.connectionpool:Retrying (Retry(total=0, connect=None, read=None, redirect=None, status=None)) after connection broken by 'NewConnectionError('<snowflake.connector.vendored.urllib3.connection.HTTPSConnection object at 0x7f035d0949a0>: Failed to establish a new connection: [Errno -2] Name or service not known')': /queries/v1/query-request?requestId=13ffa4e8-0dff-47dc-933c-a163ba8954ec&clientStartTime=1748381473915&retryCount=28&retryReason=None&request_guid=11091f65-8dbc-4762-bc21-bdf07c98ceb7
[2025-05-27T21:35:22.247+0000] {utils.py:78} INFO - WARNING:snowflake.connector.vendored.urllib3.connectionpool:Retrying (Retry(total=0, connect=None, read=None, redirect=None, status=None)) after connection broken by 'NewConnectionError('<snowflake.connector.vendored.urllib3.connection.HTTPSConnection object at 0x7f035d097f70>: Failed to establish a new connection: [Errno -2] Name or service not known')': /queries/v1/query-request?requestId=efcf9181-7063-4061-9a57-a0bd7ffcafb1&clientStartTime=1748381472810&retryCount=29&retryReason=None&request_guid=f915b39f-3e61-4a10-9d52-3cbdfc6303d2
[2025-05-27T21:35:28.516+0000] {utils.py:78} INFO - WARNING:snowflake.connector.vendored.urllib3.connectionpool:Retrying (Retry(total=0, connect=None, read=None, redirect=None, status=None)) after connection broken by 'NewConnectionError('<snowflake.connector.vendored.urllib3.connection.HTTPSConnection object at 0x7f035d095d20>: Failed to establish a new connection: [Errno -2] Name or service not known')': /queries/v1/query-request?requestId=efcf9181-7063-4061-9a57-a0bd7ffcafb1&clientStartTime=1748381472810&retryCount=30&retryReason=None&request_guid=ecce57ca-86ad-4596-91cf-0fc3ca24b864
[2025-05-27T21:35:28.587+0000] {utils.py:78} INFO - WARNING:snowflake.connector.vendored.urllib3.connectionpool:Retrying (Retry(total=0, connect=None, read=None, redirect=None, status=None)) after connection broken by 'NewConnectionError('<snowflake.connector.vendored.urllib3.connection.HTTPSConnection object at 0x7f035d096200>: Failed to establish a new connection: [Errno -2] Name or service not known')': /queries/v1/query-request?requestId=21ea1b2e-06d7-4bf7-a91a-b368df548183&clientStartTime=1748381473946&retryCount=22&retryReason=None&request_guid=d3dce500-b8b2-4b71-9ee1-1a9b9ff25752
[2025-05-27T21:35:28.717+0000] {utils.py:78} INFO - WARNING:snowflake.connector.vendored.urllib3.connectionpool:Retrying (Retry(total=0, connect=None, read=None, redirect=None, status=None)) after connection broken by 'NewConnectionError('<snowflake.connector.vendored.urllib3.connection.HTTPSConnection object at 0x7f03467e6c50>: Failed to establish a new connection: [Errno -2] Name or service not known')': /queries/v1/query-request?requestId=f2758078-2b8e-46e0-a7d2-faf366acc5db&clientStartTime=1748381472965&retryCount=27&retryReason=None&request_guid=a960f7a6-7f58-4195-a26b-2250e8f2ca6c
[2025-05-27T21:35:29.082+0000] {utils.py:78} INFO - WARNING:snowflake.connector.vendored.urllib3.connectionpool:Retrying (Retry(total=0, connect=None, read=None, redirect=None, status=None)) after connection broken by 'NewConnectionError('<snowflake.connector.vendored.urllib3.connection.HTTPSConnection object at 0x7f036fcc2830>: Failed to establish a new connection: [Errno -2] Name or service not known')': /queries/v1/query-request?requestId=f2758078-2b8e-46e0-a7d2-faf366acc5db&clientStartTime=1748381472965&retryCount=28&retryReason=None&request_guid=436b9dcc-a177-44df-90fc-697f458dd5ca
[2025-05-27T21:35:32.189+0000] {utils.py:78} INFO - WARNING:snowflake.connector.vendored.urllib3.connectionpool:Retrying (Retry(total=0, connect=None, read=None, redirect=None, status=None)) after connection broken by 'NewConnectionError('<snowflake.connector.vendored.urllib3.connection.HTTPSConnection object at 0x7f035d096fe0>: Failed to establish a new connection: [Errno -2] Name or service not known')': /queries/v1/query-request?requestId=13ffa4e8-0dff-47dc-933c-a163ba8954ec&clientStartTime=1748381473915&retryCount=29&retryReason=None&request_guid=2f6468c3-6e88-4e78-8702-3bfa49e694c3
[2025-05-27T21:35:32.336+0000] {utils.py:78} INFO - WARNING:snowflake.connector.vendored.urllib3.connectionpool:Retrying (Retry(total=0, connect=None, read=None, redirect=None, status=None)) after connection broken by 'NewConnectionError('<snowflake.connector.vendored.urllib3.connection.HTTPSConnection object at 0x7f035d097cd0>: Failed to establish a new connection: [Errno -2] Name or service not known')': /queries/v1/query-request?requestId=f2758078-2b8e-46e0-a7d2-faf366acc5db&clientStartTime=1748381472965&retryCount=29&retryReason=None&request_guid=8f4bbe21-f19d-4a15-b54c-48e99d8f6b77
[2025-05-27T21:35:34.871+0000] {utils.py:78} INFO - WARNING:snowflake.connector.vendored.urllib3.connectionpool:Retrying (Retry(total=0, connect=None, read=None, redirect=None, status=None)) after connection broken by 'NewConnectionError('<snowflake.connector.vendored.urllib3.connection.HTTPSConnection object at 0x7f035d097bb0>: Failed to establish a new connection: [Errno -2] Name or service not known')': /queries/v1/query-request?requestId=efcf9181-7063-4061-9a57-a0bd7ffcafb1&clientStartTime=1748381472810&retryCount=31&retryReason=None&request_guid=2c4740b4-be27-47e8-a8f7-26bf3810bb43
[2025-05-27T21:35:36.097+0000] {utils.py:78} INFO - WARNING:snowflake.connector.vendored.urllib3.connectionpool:Retrying (Retry(total=0, connect=None, read=None, redirect=None, status=None)) after connection broken by 'NewConnectionError('<snowflake.connector.vendored.urllib3.connection.HTTPSConnection object at 0x7f036fcc3ac0>: Failed to establish a new connection: [Errno -2] Name or service not known')': /queries/v1/query-request?requestId=21ea1b2e-06d7-4bf7-a91a-b368df548183&clientStartTime=1748381473946&retryCount=23&retryReason=None&request_guid=5162a229-16af-460a-8696-305d26d8ed98
[2025-05-27T21:35:37.436+0000] {utils.py:78} INFO - WARNING:snowflake.connector.vendored.urllib3.connectionpool:Retrying (Retry(total=0, connect=None, read=None, redirect=None, status=None)) after connection broken by 'NewConnectionError('<snowflake.connector.vendored.urllib3.connection.HTTPSConnection object at 0x7f035c9998d0>: Failed to establish a new connection: [Errno -2] Name or service not known')': /queries/v1/query-request?requestId=f2758078-2b8e-46e0-a7d2-faf366acc5db&clientStartTime=1748381472965&retryCount=30&retryReason=None&request_guid=f54a0e0c-e45a-44b8-b644-e71e9f01e838
[2025-05-27T21:35:39.315+0000] {utils.py:78} INFO - WARNING:snowflake.connector.vendored.urllib3.connectionpool:Retrying (Retry(total=0, connect=None, read=None, redirect=None, status=None)) after connection broken by 'NewConnectionError('<snowflake.connector.vendored.urllib3.connection.HTTPSConnection object at 0x7f03467e4ac0>: Failed to establish a new connection: [Errno -2] Name or service not known')': /queries/v1/query-request?requestId=13ffa4e8-0dff-47dc-933c-a163ba8954ec&clientStartTime=1748381473915&retryCount=30&retryReason=None&request_guid=1b365ffd-3095-4b18-8f69-ab58cebf6726
[2025-05-27T21:35:42.424+0000] {utils.py:78} INFO - WARNING:snowflake.connector.vendored.urllib3.connectionpool:Retrying (Retry(total=0, connect=None, read=None, redirect=None, status=None)) after connection broken by 'NewConnectionError('<snowflake.connector.vendored.urllib3.connection.HTTPSConnection object at 0x7f035d097520>: Failed to establish a new connection: [Errno -2] Name or service not known')': /queries/v1/query-request?requestId=13ffa4e8-0dff-47dc-933c-a163ba8954ec&clientStartTime=1748381473915&retryCount=31&retryReason=None&request_guid=8db52a82-fbc4-45f4-b703-1a6383d2487e
[2025-05-27T21:35:42.971+0000] {utils.py:78} INFO - WARNING:snowflake.connector.vendored.urllib3.connectionpool:Retrying (Retry(total=0, connect=None, read=None, redirect=None, status=None)) after connection broken by 'NewConnectionError('<snowflake.connector.vendored.urllib3.connection.HTTPSConnection object at 0x7f035d096560>: Failed to establish a new connection: [Errno -2] Name or service not known')': /queries/v1/query-request?requestId=efcf9181-7063-4061-9a57-a0bd7ffcafb1&clientStartTime=1748381472810&retryCount=32&retryReason=None&request_guid=5a350548-c04a-4777-b4ad-6389d6e88b79
[2025-05-27T21:35:43.523+0000] {utils.py:78} INFO - WARNING:snowflake.connector.vendored.urllib3.connectionpool:Retrying (Retry(total=0, connect=None, read=None, redirect=None, status=None)) after connection broken by 'NewConnectionError('<snowflake.connector.vendored.urllib3.connection.HTTPSConnection object at 0x7f035d0943a0>: Failed to establish a new connection: [Errno -2] Name or service not known')': /queries/v1/query-request?requestId=13ffa4e8-0dff-47dc-933c-a163ba8954ec&clientStartTime=1748381473915&retryCount=32&retryReason=None&request_guid=c6ad642a-1715-447a-9b7e-f302b0d178dc
[2025-05-27T21:35:46.570+0000] {utils.py:78} INFO - WARNING:snowflake.connector.vendored.urllib3.connectionpool:Retrying (Retry(total=0, connect=None, read=None, redirect=None, status=None)) after connection broken by 'NewConnectionError('<snowflake.connector.vendored.urllib3.connection.HTTPSConnection object at 0x7f035d094a90>: Failed to establish a new connection: [Errno -2] Name or service not known')': /queries/v1/query-request?requestId=f2758078-2b8e-46e0-a7d2-faf366acc5db&clientStartTime=1748381472965&retryCount=31&retryReason=None&request_guid=147d4928-bd81-4be3-81a4-c4333aef0a80
[2025-05-27T21:35:48.123+0000] {utils.py:78} INFO - WARNING:snowflake.connector.vendored.urllib3.connectionpool:Retrying (Retry(total=0, connect=None, read=None, redirect=None, status=None)) after connection broken by 'NewConnectionError('<snowflake.connector.vendored.urllib3.connection.HTTPSConnection object at 0x7f035d094b50>: Failed to establish a new connection: [Errno -2] Name or service not known')': /queries/v1/query-request?requestId=efcf9181-7063-4061-9a57-a0bd7ffcafb1&clientStartTime=1748381472810&retryCount=33&retryReason=None&request_guid=ca4f3ed1-e8a8-4edb-be60-857b5208729a
[2025-05-27T21:35:54.972+0000] {utils.py:78} INFO - WARNING:snowflake.connector.vendored.urllib3.connectionpool:Retrying (Retry(total=0, connect=None, read=None, redirect=None, status=None)) after connection broken by 'NewConnectionError('<snowflake.connector.vendored.urllib3.connection.HTTPSConnection object at 0x7f035d095060>: Failed to establish a new connection: [Errno -2] Name or service not known')': /queries/v1/query-request?requestId=21ea1b2e-06d7-4bf7-a91a-b368df548183&clientStartTime=1748381473946&retryCount=24&retryReason=None&request_guid=cd517656-b7ee-4491-ac53-f06a0be0184b
[2025-05-27T21:35:55.038+0000] {utils.py:78} INFO - WARNING:snowflake.connector.vendored.urllib3.connectionpool:Retrying (Retry(total=0, connect=None, read=None, redirect=None, status=None)) after connection broken by 'NewConnectionError('<snowflake.connector.vendored.urllib3.connection.HTTPSConnection object at 0x7f035d094ac0>: Failed to establish a new connection: [Errno -2] Name or service not known')': /queries/v1/query-request?requestId=efcf9181-7063-4061-9a57-a0bd7ffcafb1&clientStartTime=1748381472810&retryCount=34&retryReason=None&request_guid=2fc83b67-4855-42ab-bac9-31d08e385b06
[2025-05-27T21:35:55.840+0000] {utils.py:78} INFO - WARNING:snowflake.connector.vendored.urllib3.connectionpool:Retrying (Retry(total=0, connect=None, read=None, redirect=None, status=None)) after connection broken by 'NewConnectionError('<snowflake.connector.vendored.urllib3.connection.HTTPSConnection object at 0x7f035d094a00>: Failed to establish a new connection: [Errno -2] Name or service not known')': /queries/v1/query-request?requestId=13ffa4e8-0dff-47dc-933c-a163ba8954ec&clientStartTime=1748381473915&retryCount=33&retryReason=None&request_guid=89726b9f-9308-418f-8a3c-d75c42c0dcf6
[2025-05-27T21:35:57.682+0000] {utils.py:78} INFO - WARNING:snowflake.connector.vendored.urllib3.connectionpool:Retrying (Retry(total=0, connect=None, read=None, redirect=None, status=None)) after connection broken by 'NewConnectionError('<snowflake.connector.vendored.urllib3.connection.HTTPSConnection object at 0x7f036fcc3640>: Failed to establish a new connection: [Errno -2] Name or service not known')': /queries/v1/query-request?requestId=f2758078-2b8e-46e0-a7d2-faf366acc5db&clientStartTime=1748381472965&retryCount=32&retryReason=None&request_guid=54fb04d3-b049-4120-a4bd-917364539db0
[2025-05-27T21:36:01.969+0000] {utils.py:78} INFO - WARNING:snowflake.connector.vendored.urllib3.connectionpool:Retrying (Retry(total=0, connect=None, read=None, redirect=None, status=None)) after connection broken by 'NewConnectionError('<snowflake.connector.vendored.urllib3.connection.HTTPSConnection object at 0x7f035c99a410>: Failed to establish a new connection: [Errno -2] Name or service not known')': /queries/v1/query-request?requestId=f2758078-2b8e-46e0-a7d2-faf366acc5db&clientStartTime=1748381472965&retryCount=33&retryReason=None&request_guid=e38d0368-d7a5-44da-99d7-db409e20ffdc
[2025-05-27T21:36:04.163+0000] {utils.py:78} INFO - WARNING:snowflake.connector.vendored.urllib3.connectionpool:Retrying (Retry(total=0, connect=None, read=None, redirect=None, status=None)) after connection broken by 'NewConnectionError('<snowflake.connector.vendored.urllib3.connection.HTTPSConnection object at 0x7f035c99af50>: Failed to establish a new connection: [Errno -2] Name or service not known')': /queries/v1/query-request?requestId=21ea1b2e-06d7-4bf7-a91a-b368df548183&clientStartTime=1748381473946&retryCount=25&retryReason=None&request_guid=842f3deb-2da0-444a-8652-e8c60ced38bf
[2025-05-27T21:36:06.986+0000] {utils.py:78} INFO - WARNING:snowflake.connector.vendored.urllib3.connectionpool:Retrying (Retry(total=0, connect=None, read=None, redirect=None, status=None)) after connection broken by 'NewConnectionError('<snowflake.connector.vendored.urllib3.connection.HTTPSConnection object at 0x7f036fcc2710>: Failed to establish a new connection: [Errno -2] Name or service not known')': /queries/v1/query-request?requestId=13ffa4e8-0dff-47dc-933c-a163ba8954ec&clientStartTime=1748381473915&retryCount=34&retryReason=None&request_guid=2678a86a-546a-4275-a7ee-ca15ef9a08ad
[2025-05-27T21:36:08.109+0000] {utils.py:78} INFO - WARNING:snowflake.connector.vendored.urllib3.connectionpool:Retrying (Retry(total=0, connect=None, read=None, redirect=None, status=None)) after connection broken by 'NewConnectionError('<snowflake.connector.vendored.urllib3.connection.HTTPSConnection object at 0x7f035d096fe0>: Failed to establish a new connection: [Errno -2] Name or service not known')': /queries/v1/query-request?requestId=f2758078-2b8e-46e0-a7d2-faf366acc5db&clientStartTime=1748381472965&retryCount=34&retryReason=None&request_guid=c85ff66d-271e-483b-839c-958244927d85
[2025-05-27T21:36:11.155+0000] {utils.py:78} INFO - WARNING:snowflake.connector.vendored.urllib3.connectionpool:Retrying (Retry(total=0, connect=None, read=None, redirect=None, status=None)) after connection broken by 'NewConnectionError('<snowflake.connector.vendored.urllib3.connection.HTTPSConnection object at 0x7f035d096500>: Failed to establish a new connection: [Errno -2] Name or service not known')': /queries/v1/query-request?requestId=efcf9181-7063-4061-9a57-a0bd7ffcafb1&clientStartTime=1748381472810&retryCount=35&retryReason=None&request_guid=11fc4795-f224-4f4a-980a-a8bec683c9ed
[2025-05-27T21:36:13.115+0000] {utils.py:78} INFO - WARNING:snowflake.connector.vendored.urllib3.connectionpool:Retrying (Retry(total=0, connect=None, read=None, redirect=None, status=None)) after connection broken by 'NewConnectionError('<snowflake.connector.vendored.urllib3.connection.HTTPSConnection object at 0x7f0344570c10>: Failed to establish a new connection: [Errno -2] Name or service not known')': /queries/v1/query-request?requestId=13ffa4e8-0dff-47dc-933c-a163ba8954ec&clientStartTime=1748381473915&retryCount=35&retryReason=None&request_guid=335e49da-fd82-4305-807b-b0a3c3c0ca88
[2025-05-27T21:36:15.285+0000] {utils.py:78} INFO - WARNING:snowflake.connector.vendored.urllib3.connectionpool:Retrying (Retry(total=0, connect=None, read=None, redirect=None, status=None)) after connection broken by 'NewConnectionError('<snowflake.connector.vendored.urllib3.connection.HTTPSConnection object at 0x7f03467e5d20>: Failed to establish a new connection: [Errno -2] Name or service not known')': /queries/v1/query-request?requestId=21ea1b2e-06d7-4bf7-a91a-b368df548183&clientStartTime=1748381473946&retryCount=26&retryReason=None&request_guid=96f44ab2-cf78-423f-94c8-757587f376fa
[2025-05-27T21:36:16.211+0000] {utils.py:78} INFO - WARNING:snowflake.connector.vendored.urllib3.connectionpool:Retrying (Retry(total=0, connect=None, read=None, redirect=None, status=None)) after connection broken by 'NewConnectionError('<snowflake.connector.vendored.urllib3.connection.HTTPSConnection object at 0x7f03467e7fa0>: Failed to establish a new connection: [Errno -2] Name or service not known')': /queries/v1/query-request?requestId=f2758078-2b8e-46e0-a7d2-faf366acc5db&clientStartTime=1748381472965&retryCount=35&retryReason=None&request_guid=c3a44442-cebf-4331-be39-9a3dc1a5f48c
[2025-05-27T21:36:22.291+0000] {utils.py:78} INFO - WARNING:snowflake.connector.vendored.urllib3.connectionpool:Retrying (Retry(total=0, connect=None, read=None, redirect=None, status=None)) after connection broken by 'NewConnectionError('<snowflake.connector.vendored.urllib3.connection.HTTPSConnection object at 0x7f03467e7cd0>: Failed to establish a new connection: [Errno -2] Name or service not known')': /queries/v1/query-request?requestId=efcf9181-7063-4061-9a57-a0bd7ffcafb1&clientStartTime=1748381472810&retryCount=36&retryReason=None&request_guid=f4e7e4cd-de93-4f50-a73a-4829a5a45774
[2025-05-27T21:36:22.418+0000] {utils.py:78} INFO - WARNING:snowflake.connector.vendored.urllib3.connectionpool:Retrying (Retry(total=0, connect=None, read=None, redirect=None, status=None)) after connection broken by 'NewConnectionError('<snowflake.connector.vendored.urllib3.connection.HTTPSConnection object at 0x7f035d096500>: Failed to establish a new connection: [Errno -2] Name or service not known')': /queries/v1/query-request?requestId=21ea1b2e-06d7-4bf7-a91a-b368df548183&clientStartTime=1748381473946&retryCount=27&retryReason=None&request_guid=3fd7a67a-7bf3-43d1-94c3-ef8f307fdabf
[2025-05-27T21:36:24.246+0000] {utils.py:78} INFO - WARNING:snowflake.connector.vendored.urllib3.connectionpool:Retrying (Retry(total=0, connect=None, read=None, redirect=None, status=None)) after connection broken by 'NewConnectionError('<snowflake.connector.vendored.urllib3.connection.HTTPSConnection object at 0x7f035d096fe0>: Failed to establish a new connection: [Errno -2] Name or service not known')': /queries/v1/query-request?requestId=13ffa4e8-0dff-47dc-933c-a163ba8954ec&clientStartTime=1748381473915&retryCount=36&retryReason=None&request_guid=7e8d0a2a-5f66-45fa-ab19-8306c285f2ce
[2025-05-27T21:36:24.512+0000] {utils.py:78} INFO - WARNING:snowflake.connector.vendored.urllib3.connectionpool:Retrying (Retry(total=0, connect=None, read=None, redirect=None, status=None)) after connection broken by 'NewConnectionError('<snowflake.connector.vendored.urllib3.connection.HTTPSConnection object at 0x7f036fcc1930>: Failed to establish a new connection: [Errno -2] Name or service not known')': /queries/v1/query-request?requestId=21ea1b2e-06d7-4bf7-a91a-b368df548183&clientStartTime=1748381473946&retryCount=28&retryReason=None&request_guid=517c2ee2-36c6-4b96-8eea-bd856f582596
[2025-05-27T21:36:28.357+0000] {utils.py:78} INFO - WARNING:snowflake.connector.vendored.urllib3.connectionpool:Retrying (Retry(total=0, connect=None, read=None, redirect=None, status=None)) after connection broken by 'NewConnectionError('<snowflake.connector.vendored.urllib3.connection.HTTPSConnection object at 0x7f03467e4970>: Failed to establish a new connection: [Errno -2] Name or service not known')': /queries/v1/query-request?requestId=13ffa4e8-0dff-47dc-933c-a163ba8954ec&clientStartTime=1748381473915&retryCount=37&retryReason=None&request_guid=433e1016-d59d-40ea-ab84-1fd47c21d935
[2025-05-27T21:36:29.341+0000] {utils.py:78} INFO - WARNING:snowflake.connector.vendored.urllib3.connectionpool:Retrying (Retry(total=0, connect=None, read=None, redirect=None, status=None)) after connection broken by 'NewConnectionError('<snowflake.connector.vendored.urllib3.connection.HTTPSConnection object at 0x7f03467e7010>: Failed to establish a new connection: [Errno -2] Name or service not known')': /queries/v1/query-request?requestId=f2758078-2b8e-46e0-a7d2-faf366acc5db&clientStartTime=1748381472965&retryCount=36&retryReason=None&request_guid=1d8e3554-c0c8-480b-b77f-f0e5ad9ad8da
[2025-05-27T21:36:29.608+0000] {utils.py:78} INFO - WARNING:snowflake.connector.vendored.urllib3.connectionpool:Retrying (Retry(total=0, connect=None, read=None, redirect=None, status=None)) after connection broken by 'NewConnectionError('<snowflake.connector.vendored.urllib3.connection.HTTPSConnection object at 0x7f03467e6830>: Failed to establish a new connection: [Errno -2] Name or service not known')': /queries/v1/query-request?requestId=21ea1b2e-06d7-4bf7-a91a-b368df548183&clientStartTime=1748381473946&retryCount=29&retryReason=None&request_guid=f03ca8e4-571c-413e-b9a3-57eab62efe82
[2025-05-27T21:36:29.709+0000] {utils.py:78} INFO - WARNING:snowflake.connector.vendored.urllib3.connectionpool:Retrying (Retry(total=0, connect=None, read=None, redirect=None, status=None)) after connection broken by 'NewConnectionError('<snowflake.connector.vendored.urllib3.connection.HTTPSConnection object at 0x7f03467e7460>: Failed to establish a new connection: [Errno -2] Name or service not known')': /queries/v1/query-request?requestId=21ea1b2e-06d7-4bf7-a91a-b368df548183&clientStartTime=1748381473946&retryCount=30&retryReason=None&request_guid=6fe3d90d-ceaf-4e92-ba01-57515c39a18d
[2025-05-27T21:36:33.490+0000] {utils.py:78} INFO - WARNING:snowflake.connector.vendored.urllib3.connectionpool:Retrying (Retry(total=0, connect=None, read=None, redirect=None, status=None)) after connection broken by 'NewConnectionError('<snowflake.connector.vendored.urllib3.connection.HTTPSConnection object at 0x7f035d097790>: Failed to establish a new connection: [Errno -2] Name or service not known')': /queries/v1/query-request?requestId=efcf9181-7063-4061-9a57-a0bd7ffcafb1&clientStartTime=1748381472810&retryCount=37&retryReason=None&request_guid=8ead00a2-0980-4d0c-ae14-4905f06fd3c4
[2025-05-27T21:36:34.820+0000] {utils.py:78} INFO - WARNING:snowflake.connector.vendored.urllib3.connectionpool:Retrying (Retry(total=0, connect=None, read=None, redirect=None, status=None)) after connection broken by 'NewConnectionError('<snowflake.connector.vendored.urllib3.connection.HTTPSConnection object at 0x7f035d095150>: Failed to establish a new connection: [Errno -2] Name or service not known')': /queries/v1/query-request?requestId=21ea1b2e-06d7-4bf7-a91a-b368df548183&clientStartTime=1748381473946&retryCount=31&retryReason=None&request_guid=125080ed-ec77-4ee0-92b5-8c920c2aaa23
[2025-05-27T21:36:34.931+0000] {utils.py:78} INFO - WARNING:snowflake.connector.vendored.urllib3.connectionpool:Retrying (Retry(total=0, connect=None, read=None, redirect=None, status=None)) after connection broken by 'NewConnectionError('<snowflake.connector.vendored.urllib3.connection.HTTPSConnection object at 0x7f03467e4fd0>: Failed to establish a new connection: [Errno -2] Name or service not known')': /queries/v1/query-request?requestId=21ea1b2e-06d7-4bf7-a91a-b368df548183&clientStartTime=1748381473946&retryCount=32&retryReason=None&request_guid=34441bbd-5c4f-4913-a02f-38e5a23398b2
[2025-05-27T21:36:41.467+0000] {utils.py:78} INFO - WARNING:snowflake.connector.vendored.urllib3.connectionpool:Retrying (Retry(total=0, connect=None, read=None, redirect=None, status=None)) after connection broken by 'NewConnectionError('<snowflake.connector.vendored.urllib3.connection.HTTPSConnection object at 0x7f03467e5a20>: Failed to establish a new connection: [Errno -2] Name or service not known')': /queries/v1/query-request?requestId=13ffa4e8-0dff-47dc-933c-a163ba8954ec&clientStartTime=1748381473915&retryCount=38&retryReason=None&request_guid=72abd97e-bd45-4b8c-b2e2-7c5a4279c706
[2025-05-27T21:36:44.040+0000] {utils.py:78} INFO - WARNING:snowflake.connector.vendored.urllib3.connectionpool:Retrying (Retry(total=0, connect=None, read=None, redirect=None, status=None)) after connection broken by 'NewConnectionError('<snowflake.connector.vendored.urllib3.connection.HTTPSConnection object at 0x7f03467e5420>: Failed to establish a new connection: [Errno -2] Name or service not known')': /queries/v1/query-request?requestId=21ea1b2e-06d7-4bf7-a91a-b368df548183&clientStartTime=1748381473946&retryCount=33&retryReason=None&request_guid=a078f0ce-eff4-4139-a115-4e23bc6ad73a
[2025-05-27T21:36:44.567+0000] {utils.py:78} INFO - WARNING:snowflake.connector.vendored.urllib3.connectionpool:Retrying (Retry(total=0, connect=None, read=None, redirect=None, status=None)) after connection broken by 'NewConnectionError('<snowflake.connector.vendored.urllib3.connection.HTTPSConnection object at 0x7f03446bbc70>: Failed to establish a new connection: [Errno -2] Name or service not known')': /queries/v1/query-request?requestId=13ffa4e8-0dff-47dc-933c-a163ba8954ec&clientStartTime=1748381473915&retryCount=39&retryReason=None&request_guid=9fbaefeb-00de-45af-ac52-23e0d019e671
[2025-05-27T21:36:45.447+0000] {utils.py:78} INFO - WARNING:snowflake.connector.vendored.urllib3.connectionpool:Retrying (Retry(total=0, connect=None, read=None, redirect=None, status=None)) after connection broken by 'NewConnectionError('<snowflake.connector.vendored.urllib3.connection.HTTPSConnection object at 0x7f035d0959f0>: Failed to establish a new connection: [Errno -2] Name or service not known')': /queries/v1/query-request?requestId=f2758078-2b8e-46e0-a7d2-faf366acc5db&clientStartTime=1748381472965&retryCount=37&retryReason=None&request_guid=9bc7fc91-363a-4b8f-80a5-b827b617f40f
[2025-05-27T21:36:46.849+0000] {utils.py:78} INFO - WARNING:snowflake.connector.vendored.urllib3.connectionpool:Retrying (Retry(total=0, connect=None, read=None, redirect=None, status=None)) after connection broken by 'NewConnectionError('<snowflake.connector.vendored.urllib3.connection.HTTPSConnection object at 0x7f035d095e10>: Failed to establish a new connection: [Errno -2] Name or service not known')': /queries/v1/query-request?requestId=efcf9181-7063-4061-9a57-a0bd7ffcafb1&clientStartTime=1748381472810&retryCount=38&retryReason=None&request_guid=d4e63e22-cbb8-4946-bc5d-adba7b0823b5
[2025-05-27T21:36:47.557+0000] {utils.py:78} INFO - WARNING:snowflake.connector.vendored.urllib3.connectionpool:Retrying (Retry(total=0, connect=None, read=None, redirect=None, status=None)) after connection broken by 'NewConnectionError('<snowflake.connector.vendored.urllib3.connection.HTTPSConnection object at 0x7f03467e6560>: Failed to establish a new connection: [Errno -2] Name or service not known')': /queries/v1/query-request?requestId=f2758078-2b8e-46e0-a7d2-faf366acc5db&clientStartTime=1748381472965&retryCount=38&retryReason=None&request_guid=ea1b69da-5449-483b-b513-ec602acca7e9
[2025-05-27T21:36:49.647+0000] {utils.py:78} INFO - WARNING:snowflake.connector.vendored.urllib3.connectionpool:Retrying (Retry(total=0, connect=None, read=None, redirect=None, status=None)) after connection broken by 'NewConnectionError('<snowflake.connector.vendored.urllib3.connection.HTTPSConnection object at 0x7f03467e4d60>: Failed to establish a new connection: [Errno -2] Name or service not known')': /queries/v1/query-request?requestId=f2758078-2b8e-46e0-a7d2-faf366acc5db&clientStartTime=1748381472965&retryCount=39&retryReason=None&request_guid=8a3d47ba-34be-47ae-bb32-52b4e173329c
[2025-05-27T21:36:49.743+0000] {utils.py:78} INFO - WARNING:snowflake.connector.vendored.urllib3.connectionpool:Retrying (Retry(total=0, connect=None, read=None, redirect=None, status=None)) after connection broken by 'NewConnectionError('<snowflake.connector.vendored.urllib3.connection.HTTPSConnection object at 0x7f03446b8640>: Failed to establish a new connection: [Errno -2] Name or service not known')': /queries/v1/query-request?requestId=f2758078-2b8e-46e0-a7d2-faf366acc5db&clientStartTime=1748381472965&retryCount=40&retryReason=None&request_guid=157cfcf3-1be9-4e35-9b68-8157e4fb9d94
[2025-05-27T21:36:53.214+0000] {utils.py:78} INFO - WARNING:snowflake.connector.vendored.urllib3.connectionpool:Retrying (Retry(total=0, connect=None, read=None, redirect=None, status=None)) after connection broken by 'NewConnectionError('<snowflake.connector.vendored.urllib3.connection.HTTPSConnection object at 0x7f03446b8d00>: Failed to establish a new connection: [Errno -2] Name or service not known')': /queries/v1/query-request?requestId=21ea1b2e-06d7-4bf7-a91a-b368df548183&clientStartTime=1748381473946&retryCount=34&retryReason=None&request_guid=b1bb2fbc-965c-4ecb-a362-30b51dafa06e
[2025-05-27T21:36:53.671+0000] {utils.py:78} INFO - WARNING:snowflake.connector.vendored.urllib3.connectionpool:Retrying (Retry(total=0, connect=None, read=None, redirect=None, status=None)) after connection broken by 'NewConnectionError('<snowflake.connector.vendored.urllib3.connection.HTTPSConnection object at 0x7f03446bb250>: Failed to establish a new connection: [Errno -2] Name or service not known')': /queries/v1/query-request?requestId=13ffa4e8-0dff-47dc-933c-a163ba8954ec&clientStartTime=1748381473915&retryCount=40&retryReason=None&request_guid=97dcad33-9feb-4023-906a-a700f5285dda
[2025-05-27T21:36:55.843+0000] {utils.py:78} INFO - WARNING:snowflake.connector.vendored.urllib3.connectionpool:Retrying (Retry(total=0, connect=None, read=None, redirect=None, status=None)) after connection broken by 'NewConnectionError('<snowflake.connector.vendored.urllib3.connection.HTTPSConnection object at 0x7f03467e4d60>: Failed to establish a new connection: [Errno -2] Name or service not known')': /queries/v1/query-request?requestId=f2758078-2b8e-46e0-a7d2-faf366acc5db&clientStartTime=1748381472965&retryCount=41&retryReason=None&request_guid=f18c49d8-8d58-4909-97ed-e41787be229b
[2025-05-27T21:36:55.928+0000] {utils.py:78} INFO - WARNING:snowflake.connector.vendored.urllib3.connectionpool:Retrying (Retry(total=0, connect=None, read=None, redirect=None, status=None)) after connection broken by 'NewConnectionError('<snowflake.connector.vendored.urllib3.connection.HTTPSConnection object at 0x7f03467e6560>: Failed to establish a new connection: [Errno -2] Name or service not known')': /queries/v1/query-request?requestId=f2758078-2b8e-46e0-a7d2-faf366acc5db&clientStartTime=1748381472965&retryCount=42&retryReason=None&request_guid=3dd3ffb1-c7c8-4d12-b2df-24e22879d96c
[2025-05-27T21:36:56.312+0000] {utils.py:78} INFO - WARNING:snowflake.connector.vendored.urllib3.connectionpool:Retrying (Retry(total=0, connect=None, read=None, redirect=None, status=None)) after connection broken by 'NewConnectionError('<snowflake.connector.vendored.urllib3.connection.HTTPSConnection object at 0x7f035d0966e0>: Failed to establish a new connection: [Errno -2] Name or service not known')': /queries/v1/query-request?requestId=21ea1b2e-06d7-4bf7-a91a-b368df548183&clientStartTime=1748381473946&retryCount=35&retryReason=None&request_guid=41c26555-0e79-4bc6-b030-14a28c251ee7
[2025-05-27T21:36:57.020+0000] {utils.py:78} INFO - WARNING:snowflake.connector.vendored.urllib3.connectionpool:Retrying (Retry(total=0, connect=None, read=None, redirect=None, status=None)) after connection broken by 'NewConnectionError('<snowflake.connector.vendored.urllib3.connection.HTTPSConnection object at 0x7f03446bb010>: Failed to establish a new connection: [Errno -2] Name or service not known')': /queries/v1/query-request?requestId=f2758078-2b8e-46e0-a7d2-faf366acc5db&clientStartTime=1748381472965&retryCount=43&retryReason=None&request_guid=57f79eba-4a7d-44fb-bec3-f3892dbcb0d4
[2025-05-27T21:37:01.832+0000] {utils.py:78} INFO - WARNING:snowflake.connector.vendored.urllib3.connectionpool:Retrying (Retry(total=0, connect=None, read=None, redirect=None, status=None)) after connection broken by 'NewConnectionError('<snowflake.connector.vendored.urllib3.connection.HTTPSConnection object at 0x7f03446b99f0>: Failed to establish a new connection: [Errno -2] Name or service not known')': /queries/v1/query-request?requestId=13ffa4e8-0dff-47dc-933c-a163ba8954ec&clientStartTime=1748381473915&retryCount=41&retryReason=None&request_guid=03b1b3e5-fb1d-423f-8c90-2e30b9bc5c5d
[2025-05-27T21:37:02.003+0000] {utils.py:78} INFO - WARNING:snowflake.connector.vendored.urllib3.connectionpool:Retrying (Retry(total=0, connect=None, read=None, redirect=None, status=None)) after connection broken by 'NewConnectionError('<snowflake.connector.vendored.urllib3.connection.HTTPSConnection object at 0x7f03446e25c0>: Failed to establish a new connection: [Errno -2] Name or service not known')': /queries/v1/query-request?requestId=efcf9181-7063-4061-9a57-a0bd7ffcafb1&clientStartTime=1748381472810&retryCount=39&retryReason=None&request_guid=874064f4-d678-4fe2-bbae-f729fa3de81e
[2025-05-27T21:37:03.031+0000] {utils.py:78} INFO - WARNING:snowflake.connector.vendored.urllib3.connectionpool:Retrying (Retry(total=0, connect=None, read=None, redirect=None, status=None)) after connection broken by 'NewConnectionError('<snowflake.connector.vendored.urllib3.connection.HTTPSConnection object at 0x7f03446e2f50>: Failed to establish a new connection: [Errno -2] Name or service not known')': /queries/v1/query-request?requestId=13ffa4e8-0dff-47dc-933c-a163ba8954ec&clientStartTime=1748381473915&retryCount=42&retryReason=None&request_guid=f9af36e1-3a96-4b81-9310-29268737208e
[2025-05-27T21:37:03.134+0000] {utils.py:78} INFO - WARNING:snowflake.connector.vendored.urllib3.connectionpool:Retrying (Retry(total=0, connect=None, read=None, redirect=None, status=None)) after connection broken by 'NewConnectionError('<snowflake.connector.vendored.urllib3.connection.HTTPSConnection object at 0x7f035d0960b0>: Failed to establish a new connection: [Errno -2] Name or service not known')': /queries/v1/query-request?requestId=13ffa4e8-0dff-47dc-933c-a163ba8954ec&clientStartTime=1748381473915&retryCount=43&retryReason=None&request_guid=c8163082-b197-412c-b127-120e10834d96
[2025-05-27T21:37:04.110+0000] {utils.py:78} INFO - WARNING:snowflake.connector.vendored.urllib3.connectionpool:Retrying (Retry(total=0, connect=None, read=None, redirect=None, status=None)) after connection broken by 'NewConnectionError('<snowflake.connector.vendored.urllib3.connection.HTTPSConnection object at 0x7f03467e5780>: Failed to establish a new connection: [Errno -2] Name or service not known')': /queries/v1/query-request?requestId=f2758078-2b8e-46e0-a7d2-faf366acc5db&clientStartTime=1748381472965&retryCount=44&retryReason=None&request_guid=45f0d345-ab2f-467f-9ea5-d1741f0b09fc
[2025-05-27T21:37:05.242+0000] {utils.py:78} INFO - WARNING:snowflake.connector.vendored.urllib3.connectionpool:Retrying (Retry(total=0, connect=None, read=None, redirect=None, status=None)) after connection broken by 'NewConnectionError('<snowflake.connector.vendored.urllib3.connection.HTTPSConnection object at 0x7f03446e2560>: Failed to establish a new connection: [Errno -2] Name or service not known')': /queries/v1/query-request?requestId=f2758078-2b8e-46e0-a7d2-faf366acc5db&clientStartTime=1748381472965&retryCount=45&retryReason=None&request_guid=50f31957-7315-4b0d-952e-17611f7a6b96
[2025-05-27T21:37:09.164+0000] {utils.py:78} INFO - WARNING:snowflake.connector.vendored.urllib3.connectionpool:Retrying (Retry(total=0, connect=None, read=None, redirect=None, status=None)) after connection broken by 'NewConnectionError('<snowflake.connector.vendored.urllib3.connection.HTTPSConnection object at 0x7f03446e3610>: Failed to establish a new connection: [Errno -2] Name or service not known')': /queries/v1/query-request?requestId=efcf9181-7063-4061-9a57-a0bd7ffcafb1&clientStartTime=1748381472810&retryCount=40&retryReason=None&request_guid=01f2ebe7-258b-4fbf-a170-cc30d1472884
[2025-05-27T21:37:09.412+0000] {utils.py:78} INFO - WARNING:snowflake.connector.vendored.urllib3.connectionpool:Retrying (Retry(total=0, connect=None, read=None, redirect=None, status=None)) after connection broken by 'NewConnectionError('<snowflake.connector.vendored.urllib3.connection.HTTPSConnection object at 0x7f03446e3c40>: Failed to establish a new connection: [Errno -2] Name or service not known')': /queries/v1/query-request?requestId=21ea1b2e-06d7-4bf7-a91a-b368df548183&clientStartTime=1748381473946&retryCount=36&retryReason=None&request_guid=8038f023-d0ad-45bf-8080-786301eb9b44
[2025-05-27T21:37:11.279+0000] {utils.py:78} INFO - WARNING:snowflake.connector.vendored.urllib3.connectionpool:Retrying (Retry(total=0, connect=None, read=None, redirect=None, status=None)) after connection broken by 'NewConnectionError('<snowflake.connector.vendored.urllib3.connection.HTTPSConnection object at 0x7f03446e1e10>: Failed to establish a new connection: [Errno -2] Name or service not known')': /queries/v1/query-request?requestId=efcf9181-7063-4061-9a57-a0bd7ffcafb1&clientStartTime=1748381472810&retryCount=41&retryReason=None&request_guid=8c0ce33c-e477-4a70-90c5-85f4109bf8de
[2025-05-27T21:37:13.386+0000] {utils.py:78} INFO - WARNING:snowflake.connector.vendored.urllib3.connectionpool:Retrying (Retry(total=0, connect=None, read=None, redirect=None, status=None)) after connection broken by 'NewConnectionError('<snowflake.connector.vendored.urllib3.connection.HTTPSConnection object at 0x7f03467e58d0>: Failed to establish a new connection: [Errno -2] Name or service not known')': /queries/v1/query-request?requestId=13ffa4e8-0dff-47dc-933c-a163ba8954ec&clientStartTime=1748381473915&retryCount=44&retryReason=None&request_guid=f40ed2df-3f12-4ae1-8f5c-6e911e15c304
[2025-05-27T21:37:13.587+0000] {utils.py:78} INFO - WARNING:snowflake.connector.vendored.urllib3.connectionpool:Retrying (Retry(total=0, connect=None, read=None, redirect=None, status=None)) after connection broken by 'NewConnectionError('<snowflake.connector.vendored.urllib3.connection.HTTPSConnection object at 0x7f03467e6440>: Failed to establish a new connection: [Errno -2] Name or service not known')': /queries/v1/query-request?requestId=13ffa4e8-0dff-47dc-933c-a163ba8954ec&clientStartTime=1748381473915&retryCount=45&retryReason=None&request_guid=56a01e44-e15e-4696-8009-6bb503c72736
[2025-05-27T21:37:16.359+0000] {utils.py:78} INFO - WARNING:snowflake.connector.vendored.urllib3.connectionpool:Retrying (Retry(total=0, connect=None, read=None, redirect=None, status=None)) after connection broken by 'NewConnectionError('<snowflake.connector.vendored.urllib3.connection.HTTPSConnection object at 0x7f03446ba110>: Failed to establish a new connection: [Errno -2] Name or service not known')': /queries/v1/query-request?requestId=f2758078-2b8e-46e0-a7d2-faf366acc5db&clientStartTime=1748381472965&retryCount=46&retryReason=None&request_guid=4ec9023d-001b-4d03-a5c6-5da26df00f45
[2025-05-27T21:37:17.483+0000] {utils.py:78} INFO - WARNING:snowflake.connector.vendored.urllib3.connectionpool:Retrying (Retry(total=0, connect=None, read=None, redirect=None, status=None)) after connection broken by 'NewConnectionError('<snowflake.connector.vendored.urllib3.connection.HTTPSConnection object at 0x7f03446e1630>: Failed to establish a new connection: [Errno -2] Name or service not known')': /queries/v1/query-request?requestId=f2758078-2b8e-46e0-a7d2-faf366acc5db&clientStartTime=1748381472965&retryCount=47&retryReason=None&request_guid=e3b5a2e9-df78-49c4-8d3c-51c0362c3d65
[2025-05-27T21:37:17.577+0000] {utils.py:78} INFO - WARNING:snowflake.connector.vendored.urllib3.connectionpool:Retrying (Retry(total=0, connect=None, read=None, redirect=None, status=None)) after connection broken by 'NewConnectionError('<snowflake.connector.vendored.urllib3.connection.HTTPSConnection object at 0x7f03446e1cf0>: Failed to establish a new connection: [Errno -2] Name or service not known')': /queries/v1/query-request?requestId=f2758078-2b8e-46e0-a7d2-faf366acc5db&clientStartTime=1748381472965&retryCount=48&retryReason=None&request_guid=e09c3bf0-fe30-408b-b2d8-b451bef3caaf
[2025-05-27T21:37:17.699+0000] {utils.py:78} INFO - WARNING:snowflake.connector.vendored.urllib3.connectionpool:Retrying (Retry(total=0, connect=None, read=None, redirect=None, status=None)) after connection broken by 'NewConnectionError('<snowflake.connector.vendored.urllib3.connection.HTTPSConnection object at 0x7f03446e37f0>: Failed to establish a new connection: [Errno -2] Name or service not known')': /queries/v1/query-request?requestId=13ffa4e8-0dff-47dc-933c-a163ba8954ec&clientStartTime=1748381473915&retryCount=46&retryReason=None&request_guid=d38c8460-9db2-4520-9106-970db1e64947
[2025-05-27T21:37:18.547+0000] {utils.py:78} INFO - WARNING:snowflake.connector.vendored.urllib3.connectionpool:Retrying (Retry(total=0, connect=None, read=None, redirect=None, status=None)) after connection broken by 'NewConnectionError('<snowflake.connector.vendored.urllib3.connection.HTTPSConnection object at 0x7f03446e3100>: Failed to establish a new connection: [Errno -2] Name or service not known')': /queries/v1/query-request?requestId=efcf9181-7063-4061-9a57-a0bd7ffcafb1&clientStartTime=1748381472810&retryCount=42&retryReason=None&request_guid=90afec5c-fb34-40fa-bddf-290eac810545
[2025-05-27T21:37:18.556+0000] {utils.py:78} INFO - WARNING:snowflake.connector.vendored.urllib3.connectionpool:Retrying (Retry(total=0, connect=None, read=None, redirect=None, status=None)) after connection broken by 'NewConnectionError('<snowflake.connector.vendored.urllib3.connection.HTTPSConnection object at 0x7f03446e1960>: Failed to establish a new connection: [Errno -2] Name or service not known')': /queries/v1/query-request?requestId=21ea1b2e-06d7-4bf7-a91a-b368df548183&clientStartTime=1748381473946&retryCount=37&retryReason=None&request_guid=84ef0960-199a-4c7b-b8af-f6e151109eb2
[2025-05-27T21:37:23.692+0000] {utils.py:78} INFO - WARNING:snowflake.connector.vendored.urllib3.connectionpool:Retrying (Retry(total=0, connect=None, read=None, redirect=None, status=None)) after connection broken by 'NewConnectionError('<snowflake.connector.vendored.urllib3.connection.HTTPSConnection object at 0x7f03467e6650>: Failed to establish a new connection: [Errno -2] Name or service not known')': /queries/v1/query-request?requestId=21ea1b2e-06d7-4bf7-a91a-b368df548183&clientStartTime=1748381473946&retryCount=38&retryReason=None&request_guid=4036f2df-f509-4471-ad53-c6993c61d880
[2025-05-27T21:37:25.662+0000] {utils.py:78} INFO - WARNING:snowflake.connector.vendored.urllib3.connectionpool:Retrying (Retry(total=0, connect=None, read=None, redirect=None, status=None)) after connection broken by 'NewConnectionError('<snowflake.connector.vendored.urllib3.connection.HTTPSConnection object at 0x7f03467e7070>: Failed to establish a new connection: [Errno -2] Name or service not known')': /queries/v1/query-request?requestId=efcf9181-7063-4061-9a57-a0bd7ffcafb1&clientStartTime=1748381472810&retryCount=43&retryReason=None&request_guid=905aff71-b841-41fc-bd5d-c979c6213658
[2025-05-27T21:37:25.692+0000] {utils.py:78} INFO - WARNING:snowflake.connector.vendored.urllib3.connectionpool:Retrying (Retry(total=0, connect=None, read=None, redirect=None, status=None)) after connection broken by 'NewConnectionError('<snowflake.connector.vendored.urllib3.connection.HTTPSConnection object at 0x7f03446e16c0>: Failed to establish a new connection: [Errno -2] Name or service not known')': /queries/v1/query-request?requestId=f2758078-2b8e-46e0-a7d2-faf366acc5db&clientStartTime=1748381472965&retryCount=49&retryReason=None&request_guid=c0399e95-aab4-42e9-8d2b-aea99efb7d00
[2025-05-27T21:37:25.796+0000] {utils.py:78} INFO - WARNING:snowflake.connector.vendored.urllib3.connectionpool:Retrying (Retry(total=0, connect=None, read=None, redirect=None, status=None)) after connection broken by 'NewConnectionError('<snowflake.connector.vendored.urllib3.connection.HTTPSConnection object at 0x7f03446e09d0>: Failed to establish a new connection: [Errno -2] Name or service not known')': /queries/v1/query-request?requestId=f2758078-2b8e-46e0-a7d2-faf366acc5db&clientStartTime=1748381472965&retryCount=50&retryReason=None&request_guid=7242e42c-be44-4383-97e3-67097b523a5f
[2025-05-27T21:37:26.891+0000] {utils.py:78} INFO - WARNING:snowflake.connector.vendored.urllib3.connectionpool:Retrying (Retry(total=0, connect=None, read=None, redirect=None, status=None)) after connection broken by 'NewConnectionError('<snowflake.connector.vendored.urllib3.connection.HTTPSConnection object at 0x7f0344679180>: Failed to establish a new connection: [Errno -2] Name or service not known')': /queries/v1/query-request?requestId=f2758078-2b8e-46e0-a7d2-faf366acc5db&clientStartTime=1748381472965&retryCount=51&retryReason=None&request_guid=159ea37f-57bd-4fbb-9c9b-00882f95ec80
[2025-05-27T21:37:30.912+0000] {utils.py:78} INFO - WARNING:snowflake.connector.vendored.urllib3.connectionpool:Retrying (Retry(total=0, connect=None, read=None, redirect=None, status=None)) after connection broken by 'NewConnectionError('<snowflake.connector.vendored.urllib3.connection.HTTPSConnection object at 0x7f034467a080>: Failed to establish a new connection: [Errno -2] Name or service not known')': /queries/v1/query-request?requestId=efcf9181-7063-4061-9a57-a0bd7ffcafb1&clientStartTime=1748381472810&retryCount=44&retryReason=None&request_guid=8bf94d32-344c-4f13-8187-39d68b39ceb4
[2025-05-27T21:37:30.924+0000] {utils.py:78} INFO - WARNING:snowflake.connector.vendored.urllib3.connectionpool:Retrying (Retry(total=0, connect=None, read=None, redirect=None, status=None)) after connection broken by 'NewConnectionError('<snowflake.connector.vendored.urllib3.connection.HTTPSConnection object at 0x7f03467e7520>: Failed to establish a new connection: [Errno -2] Name or service not known')': /queries/v1/query-request?requestId=21ea1b2e-06d7-4bf7-a91a-b368df548183&clientStartTime=1748381473946&retryCount=39&retryReason=None&request_guid=10d20bae-0170-4c6a-8013-f95c3299876a
[2025-05-27T21:37:32.800+0000] {utils.py:78} INFO - WARNING:snowflake.connector.vendored.urllib3.connectionpool:Retrying (Retry(total=0, connect=None, read=None, redirect=None, status=None)) after connection broken by 'NewConnectionError('<snowflake.connector.vendored.urllib3.connection.HTTPSConnection object at 0x7f03446e07f0>: Failed to establish a new connection: [Errno -2] Name or service not known')': /queries/v1/query-request?requestId=13ffa4e8-0dff-47dc-933c-a163ba8954ec&clientStartTime=1748381473915&retryCount=47&retryReason=None&request_guid=151549ed-7607-4bcc-9a44-637399fc765d
[2025-05-27T21:37:35.079+0000] {utils.py:78} INFO - WARNING:snowflake.connector.vendored.urllib3.connectionpool:Retrying (Retry(total=0, connect=None, read=None, redirect=None, status=None)) after connection broken by 'NewConnectionError('<snowflake.connector.vendored.urllib3.connection.HTTPSConnection object at 0x7f03446e3a90>: Failed to establish a new connection: [Errno -2] Name or service not known')': /queries/v1/query-request?requestId=efcf9181-7063-4061-9a57-a0bd7ffcafb1&clientStartTime=1748381472810&retryCount=45&retryReason=None&request_guid=72534fb5-6466-4e1a-855c-6714c571b0e7
[2025-05-27T21:37:38.125+0000] {utils.py:78} INFO - WARNING:snowflake.connector.vendored.urllib3.connectionpool:Retrying (Retry(total=0, connect=None, read=None, redirect=None, status=None)) after connection broken by 'NewConnectionError('<snowflake.connector.vendored.urllib3.connection.HTTPSConnection object at 0x7f03446e0bb0>: Failed to establish a new connection: [Errno -2] Name or service not known')': /queries/v1/query-request?requestId=21ea1b2e-06d7-4bf7-a91a-b368df548183&clientStartTime=1748381473946&retryCount=40&retryReason=None&request_guid=a13101b9-65aa-4949-a236-9e1c56bb533b
[2025-05-27T21:37:39.002+0000] {utils.py:78} INFO - WARNING:snowflake.connector.vendored.urllib3.connectionpool:Retrying (Retry(total=0, connect=None, read=None, redirect=None, status=None)) after connection broken by 'NewConnectionError('<snowflake.connector.vendored.urllib3.connection.HTTPSConnection object at 0x7f03446e3e20>: Failed to establish a new connection: [Errno -2] Name or service not known')': /queries/v1/query-request?requestId=f2758078-2b8e-46e0-a7d2-faf366acc5db&clientStartTime=1748381472965&retryCount=52&retryReason=None&request_guid=eeba5a42-2c1f-4560-ab2d-09ce92461738
[2025-05-27T21:37:40.912+0000] {utils.py:78} INFO - WARNING:snowflake.connector.vendored.urllib3.connectionpool:Retrying (Retry(total=0, connect=None, read=None, redirect=None, status=None)) after connection broken by 'NewConnectionError('<snowflake.connector.vendored.urllib3.connection.HTTPSConnection object at 0x7f0344679f00>: Failed to establish a new connection: [Errno -2] Name or service not known')': /queries/v1/query-request?requestId=13ffa4e8-0dff-47dc-933c-a163ba8954ec&clientStartTime=1748381473915&retryCount=48&retryReason=None&request_guid=9c331ee8-5d83-4ca2-b586-09fd6b4642f9
[2025-05-27T21:37:45.202+0000] {utils.py:78} INFO - WARNING:snowflake.connector.vendored.urllib3.connectionpool:Retrying (Retry(total=0, connect=None, read=None, redirect=None, status=None)) after connection broken by 'NewConnectionError('<snowflake.connector.vendored.urllib3.connection.HTTPSConnection object at 0x7f034467a7a0>: Failed to establish a new connection: [Errno -2] Name or service not known')': /queries/v1/query-request?requestId=f2758078-2b8e-46e0-a7d2-faf366acc5db&clientStartTime=1748381472965&retryCount=53&retryReason=None&request_guid=5a06f7ed-1b53-47ec-88f2-d2af95c7b589
[2025-05-27T21:37:45.258+0000] {utils.py:78} INFO - WARNING:snowflake.connector.vendored.urllib3.connectionpool:Retrying (Retry(total=0, connect=None, read=None, redirect=None, status=None)) after connection broken by 'NewConnectionError('<snowflake.connector.vendored.urllib3.connection.HTTPSConnection object at 0x7f03446b8610>: Failed to establish a new connection: [Errno -2] Name or service not known')': /queries/v1/query-request?requestId=efcf9181-7063-4061-9a57-a0bd7ffcafb1&clientStartTime=1748381472810&retryCount=46&retryReason=None&request_guid=857cb7f0-cf43-4331-b9c9-29967461430e
[2025-05-27T21:37:48.249+0000] {utils.py:78} INFO - WARNING:snowflake.connector.vendored.urllib3.connectionpool:Retrying (Retry(total=0, connect=None, read=None, redirect=None, status=None)) after connection broken by 'NewConnectionError('<snowflake.connector.vendored.urllib3.connection.HTTPSConnection object at 0x7f03446e1120>: Failed to establish a new connection: [Errno -2] Name or service not known')': /queries/v1/query-request?requestId=21ea1b2e-06d7-4bf7-a91a-b368df548183&clientStartTime=1748381473946&retryCount=41&retryReason=None&request_guid=1298802c-6a18-4d06-8045-a0c35729c098
[2025-05-27T21:37:49.365+0000] {utils.py:78} INFO - WARNING:snowflake.connector.vendored.urllib3.connectionpool:Retrying (Retry(total=0, connect=None, read=None, redirect=None, status=None)) after connection broken by 'NewConnectionError('<snowflake.connector.vendored.urllib3.connection.HTTPSConnection object at 0x7f035d094dc0>: Failed to establish a new connection: [Errno -2] Name or service not known')': /queries/v1/query-request?requestId=efcf9181-7063-4061-9a57-a0bd7ffcafb1&clientStartTime=1748381472810&retryCount=47&retryReason=None&request_guid=0f2a6b7b-1b97-44c3-9a7b-a3f00f50cd79
[2025-05-27T21:37:51.121+0000] {utils.py:78} INFO - WARNING:snowflake.connector.vendored.urllib3.connectionpool:Retrying (Retry(total=0, connect=None, read=None, redirect=None, status=None)) after connection broken by 'NewConnectionError('<snowflake.connector.vendored.urllib3.connection.HTTPSConnection object at 0x7f03467e5ba0>: Failed to establish a new connection: [Errno -2] Name or service not known')': /queries/v1/query-request?requestId=13ffa4e8-0dff-47dc-933c-a163ba8954ec&clientStartTime=1748381473915&retryCount=49&retryReason=None&request_guid=d4a64c86-ae64-4918-981f-9f339de95376
[2025-05-27T21:37:56.247+0000] {utils.py:78} INFO - WARNING:snowflake.connector.vendored.urllib3.connectionpool:Retrying (Retry(total=0, connect=None, read=None, redirect=None, status=None)) after connection broken by 'NewConnectionError('<snowflake.connector.vendored.urllib3.connection.HTTPSConnection object at 0x7f03446798d0>: Failed to establish a new connection: [Errno -2] Name or service not known')': /queries/v1/query-request?requestId=13ffa4e8-0dff-47dc-933c-a163ba8954ec&clientStartTime=1748381473915&retryCount=50&retryReason=None&request_guid=aa385c0a-2b0e-420e-abea-a9d794d7b8bd
[2025-05-27T21:37:58.343+0000] {utils.py:78} INFO - WARNING:snowflake.connector.vendored.urllib3.connectionpool:Retrying (Retry(total=0, connect=None, read=None, redirect=None, status=None)) after connection broken by 'NewConnectionError('<snowflake.connector.vendored.urllib3.connection.HTTPSConnection object at 0x7f0344678d90>: Failed to establish a new connection: [Errno -2] Name or service not known')': /queries/v1/query-request?requestId=13ffa4e8-0dff-47dc-933c-a163ba8954ec&clientStartTime=1748381473915&retryCount=51&retryReason=None&request_guid=b2fbbd83-c5e5-4f30-9979-d6795f84dba0
[2025-05-27T21:37:58.356+0000] {utils.py:78} INFO - WARNING:snowflake.connector.vendored.urllib3.connectionpool:Retrying (Retry(total=0, connect=None, read=None, redirect=None, status=None)) after connection broken by 'NewConnectionError('<snowflake.connector.vendored.urllib3.connection.HTTPSConnection object at 0x7f034467ada0>: Failed to establish a new connection: [Errno -2] Name or service not known')': /queries/v1/query-request?requestId=21ea1b2e-06d7-4bf7-a91a-b368df548183&clientStartTime=1748381473946&retryCount=42&retryReason=None&request_guid=beadf15e-6539-4c3a-89b0-3605b5c24d61
[2025-05-27T21:37:59.391+0000] {utils.py:78} INFO - WARNING:snowflake.connector.vendored.urllib3.connectionpool:Retrying (Retry(total=0, connect=None, read=None, redirect=None, status=None)) after connection broken by 'NewConnectionError('<snowflake.connector.vendored.urllib3.connection.HTTPSConnection object at 0x7f03467e5930>: Failed to establish a new connection: [Errno -2] Name or service not known')': /queries/v1/query-request?requestId=f2758078-2b8e-46e0-a7d2-faf366acc5db&clientStartTime=1748381472965&retryCount=54&retryReason=None&request_guid=c671d718-68e6-4f01-a8a3-cc36ff9760b0
[2025-05-27T21:37:59.551+0000] {utils.py:78} INFO - WARNING:snowflake.connector.vendored.urllib3.connectionpool:Retrying (Retry(total=0, connect=None, read=None, redirect=None, status=None)) after connection broken by 'NewConnectionError('<snowflake.connector.vendored.urllib3.connection.HTTPSConnection object at 0x7f03446798d0>: Failed to establish a new connection: [Errno -2] Name or service not known')': /queries/v1/query-request?requestId=21ea1b2e-06d7-4bf7-a91a-b368df548183&clientStartTime=1748381473946&retryCount=43&retryReason=None&request_guid=13cdabb1-adf1-474d-b784-ce5dabd217d4
[2025-05-27T21:38:05.490+0000] {utils.py:78} INFO - WARNING:snowflake.connector.vendored.urllib3.connectionpool:Retrying (Retry(total=0, connect=None, read=None, redirect=None, status=None)) after connection broken by 'NewConnectionError('<snowflake.connector.vendored.urllib3.connection.HTTPSConnection object at 0x7f03446e36a0>: Failed to establish a new connection: [Errno -2] Name or service not known')': /queries/v1/query-request?requestId=efcf9181-7063-4061-9a57-a0bd7ffcafb1&clientStartTime=1748381472810&retryCount=48&retryReason=None&request_guid=28697a6a-9407-4515-9794-c64cdac5b6c1
[2025-05-27T21:38:06.578+0000] {utils.py:78} INFO - WARNING:snowflake.connector.vendored.urllib3.connectionpool:Retrying (Retry(total=0, connect=None, read=None, redirect=None, status=None)) after connection broken by 'NewConnectionError('<snowflake.connector.vendored.urllib3.connection.HTTPSConnection object at 0x7f03446bb4f0>: Failed to establish a new connection: [Errno -2] Name or service not known')': /queries/v1/query-request?requestId=efcf9181-7063-4061-9a57-a0bd7ffcafb1&clientStartTime=1748381472810&retryCount=49&retryReason=None&request_guid=d259afd0-1d5a-4f9c-9797-7b1935f81d36
[2025-05-27T21:38:07.437+0000] {utils.py:78} INFO - WARNING:snowflake.connector.vendored.urllib3.connectionpool:Retrying (Retry(total=0, connect=None, read=None, redirect=None, status=None)) after connection broken by 'NewConnectionError('<snowflake.connector.vendored.urllib3.connection.HTTPSConnection object at 0x7f035d0821a0>: Failed to establish a new connection: [Errno -2] Name or service not known')': /queries/v1/query-request?requestId=13ffa4e8-0dff-47dc-933c-a163ba8954ec&clientStartTime=1748381473915&retryCount=52&retryReason=None&request_guid=a943d41d-1a53-4d20-8256-c7f66a079075
[2025-05-27T21:38:08.844+0000] {utils.py:78} INFO - WARNING:snowflake.connector.vendored.urllib3.connectionpool:Retrying (Retry(total=0, connect=None, read=None, redirect=None, status=None)) after connection broken by 'NewConnectionError('<snowflake.connector.vendored.urllib3.connection.HTTPSConnection object at 0x7f035d083220>: Failed to establish a new connection: [Errno -2] Name or service not known')': /queries/v1/query-request?requestId=efcf9181-7063-4061-9a57-a0bd7ffcafb1&clientStartTime=1748381472810&retryCount=50&retryReason=None&request_guid=d729f850-0af1-43c7-9d0f-d691ba08bd03
[2025-05-27T21:38:10.605+0000] {utils.py:78} INFO - WARNING:snowflake.connector.vendored.urllib3.connectionpool:Retrying (Retry(total=0, connect=None, read=None, redirect=None, status=None)) after connection broken by 'NewConnectionError('<snowflake.connector.vendored.urllib3.connection.HTTPSConnection object at 0x7f034467b790>: Failed to establish a new connection: [Errno -2] Name or service not known')': /queries/v1/query-request?requestId=f2758078-2b8e-46e0-a7d2-faf366acc5db&clientStartTime=1748381472965&retryCount=55&retryReason=None&request_guid=64fd0a53-62b4-4864-af07-76769880daf6
[2025-05-27T21:38:11.532+0000] {utils.py:78} INFO - WARNING:snowflake.connector.vendored.urllib3.connectionpool:Retrying (Retry(total=0, connect=None, read=None, redirect=None, status=None)) after connection broken by 'NewConnectionError('<snowflake.connector.vendored.urllib3.connection.HTTPSConnection object at 0x7f0344678d90>: Failed to establish a new connection: [Errno -2] Name or service not known')': /queries/v1/query-request?requestId=13ffa4e8-0dff-47dc-933c-a163ba8954ec&clientStartTime=1748381473915&retryCount=53&retryReason=None&request_guid=8d32ef74-5cfd-47b0-b0af-7ed8c66eb78c
[2025-05-27T21:38:13.654+0000] {utils.py:78} INFO - WARNING:snowflake.connector.vendored.urllib3.connectionpool:Retrying (Retry(total=0, connect=None, read=None, redirect=None, status=None)) after connection broken by 'NewConnectionError('<snowflake.connector.vendored.urllib3.connection.HTTPSConnection object at 0x7f03446793f0>: Failed to establish a new connection: [Errno -2] Name or service not known')': /queries/v1/query-request?requestId=21ea1b2e-06d7-4bf7-a91a-b368df548183&clientStartTime=1748381473946&retryCount=44&retryReason=None&request_guid=9df867d2-1a6c-4748-ba2e-3f656e37053b
[2025-05-27T21:38:17.098+0000] {utils.py:78} INFO - [0m21:38:17  16 of 70 PASS not_null_mart_form_fills_estimated_value ......................... [[32mPASS[0m in 424.65s]
[2025-05-27T21:38:17.120+0000] {utils.py:78} INFO - [0m21:38:17  20 of 70 START test not_null_mart_forms_form_id ................................ [RUN]
[2025-05-27T21:38:17.555+0000] {utils.py:78} INFO - [0m21:38:17  17 of 70 PASS not_null_mart_form_fills_fill_date ............................... [[32mPASS[0m in 425.05s]
[2025-05-27T21:38:17.611+0000] {utils.py:78} INFO - [0m21:38:17  21 of 70 START test not_null_mart_forms_form_type .............................. [RUN]
[2025-05-27T21:38:18.030+0000] {utils.py:78} INFO - [0m21:38:18  20 of 70 PASS not_null_mart_forms_form_id ...................................... [[32mPASS[0m in 0.89s]
[2025-05-27T21:38:18.076+0000] {utils.py:78} INFO - [0m21:38:18  22 of 70 START test not_null_mart_pages_page_id ................................ [RUN]
[2025-05-27T21:38:18.250+0000] {utils.py:78} INFO - [0m21:38:18  18 of 70 PASS not_null_mart_form_fills_fill_id ................................. [[32mPASS[0m in 425.50s]
[2025-05-27T21:38:18.387+0000] {utils.py:78} INFO - [0m21:38:18  23 of 70 START test not_null_mart_pages_page_title ............................. [RUN]
[2025-05-27T21:38:18.468+0000] {utils.py:78} INFO - [0m21:38:18  21 of 70 PASS not_null_mart_forms_form_type .................................... [[32mPASS[0m in 0.83s]
[2025-05-27T21:38:18.540+0000] {utils.py:78} INFO - [0m21:38:18  24 of 70 START test not_null_mart_pages_page_url ............................... [RUN]
[2025-05-27T21:38:21.669+0000] {utils.py:78} INFO - [0m21:38:21  22 of 70 PASS not_null_mart_pages_page_id ...................................... [[32mPASS[0m in 3.57s]
[2025-05-27T21:38:21.756+0000] {utils.py:78} INFO - [0m21:38:21  23 of 70 PASS not_null_mart_pages_page_title ................................... [[32mPASS[0m in 3.26s]
[2025-05-27T21:38:21.883+0000] {utils.py:78} INFO - [0m21:38:21  24 of 70 PASS not_null_mart_pages_page_url ..................................... [[32mPASS[0m in 3.31s]
[2025-05-27T21:38:21.919+0000] {utils.py:78} INFO - [0m21:38:21  25 of 70 START test not_null_mart_website_activity_bounce ...................... [RUN]
[2025-05-27T21:38:21.993+0000] {utils.py:78} INFO - [0m21:38:21  26 of 70 START test not_null_mart_website_activity_contact_id .................. [RUN]
[2025-05-27T21:38:22.024+0000] {utils.py:78} INFO - [0m21:38:22  27 of 70 START test not_null_mart_website_activity_event_date .................. [RUN]
[2025-05-27T21:38:24.238+0000] {utils.py:78} INFO - [0m21:38:24  26 of 70 PASS not_null_mart_website_activity_contact_id ........................ [[32mPASS[0m in 2.20s]
[2025-05-27T21:38:24.532+0000] {utils.py:78} INFO - [0m21:38:24  28 of 70 START test not_null_mart_website_activity_pages_viewed ................ [RUN]
[2025-05-27T21:38:24.882+0000] {utils.py:78} INFO - [0m21:38:24  25 of 70 PASS not_null_mart_website_activity_bounce ............................ [[32mPASS[0m in 2.90s]
[2025-05-27T21:38:24.951+0000] {utils.py:78} INFO - [0m21:38:24  27 of 70 PASS not_null_mart_website_activity_event_date ........................ [[32mPASS[0m in 2.88s]
[2025-05-27T21:38:25.109+0000] {utils.py:78} INFO - [0m21:38:25  30 of 70 START test not_null_mart_website_activity_session_id .................. [RUN]
[2025-05-27T21:38:25.153+0000] {utils.py:78} INFO - [0m21:38:25  29 of 70 START test not_null_mart_website_activity_session_duration ............ [RUN]
[2025-05-27T21:38:27.387+0000] {utils.py:78} INFO - [0m21:38:27  28 of 70 PASS not_null_mart_website_activity_pages_viewed ...................... [[32mPASS[0m in 2.76s]
[2025-05-27T21:38:27.655+0000] {utils.py:78} INFO - [0m21:38:27  31 of 70 START test not_null_stg_campaigns_campaign_id ......................... [RUN]
[2025-05-27T21:38:27.871+0000] {utils.py:78} INFO - [0m21:38:27  29 of 70 PASS not_null_mart_website_activity_session_duration .................. [[32mPASS[0m in 2.71s]
[2025-05-27T21:38:27.941+0000] {utils.py:78} INFO - [0m21:38:27  30 of 70 PASS not_null_mart_website_activity_session_id ........................ [[32mPASS[0m in 2.70s]
[2025-05-27T21:38:27.993+0000] {utils.py:78} INFO - [0m21:38:27  32 of 70 START test not_null_stg_campaigns_campaign_name ....................... [RUN]
[2025-05-27T21:38:28.007+0000] {utils.py:78} INFO - [0m21:38:27  33 of 70 START test not_null_stg_campaigns_dim_date ............................ [RUN]
[2025-05-27T21:38:29.334+0000] {utils.py:78} INFO - [0m21:38:29  31 of 70 PASS not_null_stg_campaigns_campaign_id ............................... [[32mPASS[0m in 1.64s]
[2025-05-27T21:38:29.536+0000] {utils.py:78} INFO - [0m21:38:29  32 of 70 PASS not_null_stg_campaigns_campaign_name ............................. [[32mPASS[0m in 1.52s]
[2025-05-27T21:38:29.655+0000] {utils.py:78} INFO - [0m21:38:29  33 of 70 PASS not_null_stg_campaigns_dim_date .................................. [[32mPASS[0m in 1.63s]
[2025-05-27T21:38:29.682+0000] {utils.py:78} INFO - [0m21:38:29  34 of 70 START test not_null_stg_contacts_contact_id ........................... [RUN]
[2025-05-27T21:38:29.749+0000] {utils.py:78} INFO - [0m21:38:29  35 of 70 START test not_null_stg_contacts_email ................................ [RUN]
[2025-05-27T21:38:29.826+0000] {utils.py:78} INFO - [0m21:38:29  36 of 70 START test not_null_stg_contacts_signup_date .......................... [RUN]
[2025-05-27T21:38:29.970+0000] {utils.py:78} INFO - [0m21:38:29  19 of 70 PASS not_null_mart_form_fills_form_id ................................. [[32mPASS[0m in 436.97s]
[2025-05-27T21:38:30.551+0000] {utils.py:78} INFO - [0m21:38:30  37 of 70 START test not_null_stg_form_fills_contact_id ......................... [RUN]
[2025-05-27T21:38:31.438+0000] {utils.py:78} INFO - [0m21:38:31  34 of 70 PASS not_null_stg_contacts_contact_id ................................. [[32mPASS[0m in 1.70s]
[2025-05-27T21:38:31.507+0000] {utils.py:78} INFO - [0m21:38:31  35 of 70 PASS not_null_stg_contacts_email ...................................... [[32mPASS[0m in 1.64s]
[2025-05-27T21:38:31.671+0000] {utils.py:78} INFO - [0m21:38:31  36 of 70 PASS not_null_stg_contacts_signup_date ................................ [[32mPASS[0m in 1.66s]
[2025-05-27T21:38:31.722+0000] {utils.py:78} INFO - [0m21:38:31  39 of 70 START test not_null_stg_form_fills_fill_id ............................ [RUN]
[2025-05-27T21:38:31.764+0000] {utils.py:78} INFO - [0m21:38:31  38 of 70 START test not_null_stg_form_fills_fill_date .......................... [RUN]
[2025-05-27T21:38:31.857+0000] {utils.py:78} INFO - [0m21:38:31  40 of 70 START test not_null_stg_form_fills_form_id ............................ [RUN]
[2025-05-27T21:38:32.371+0000] {utils.py:78} INFO - [0m21:38:32  37 of 70 PASS not_null_stg_form_fills_contact_id ............................... [[32mPASS[0m in 1.72s]
[2025-05-27T21:38:32.771+0000] {utils.py:78} INFO - [0m21:38:32  41 of 70 START test not_null_stg_forms_form_id ................................. [RUN]
[2025-05-27T21:38:33.312+0000] {utils.py:78} INFO - [0m21:38:33  38 of 70 PASS not_null_stg_form_fills_fill_date ................................ [[32mPASS[0m in 1.50s]
[2025-05-27T21:38:33.400+0000] {utils.py:78} INFO - [0m21:38:33  42 of 70 START test not_null_stg_forms_form_type ............................... [RUN]
[2025-05-27T21:38:33.478+0000] {utils.py:78} INFO - [0m21:38:33  41 of 70 PASS not_null_stg_forms_form_id ....................................... [[32mPASS[0m in 0.70s]
[2025-05-27T21:38:33.524+0000] {utils.py:78} INFO - [0m21:38:33  43 of 70 START test not_null_stg_pages_page_id ................................. [RUN]
[2025-05-27T21:38:33.602+0000] {utils.py:78} INFO - [0m21:38:33  40 of 70 PASS not_null_stg_form_fills_form_id .................................. [[32mPASS[0m in 1.58s]
[2025-05-27T21:38:33.738+0000] {utils.py:78} INFO - [0m21:38:33  39 of 70 PASS not_null_stg_form_fills_fill_id .................................. [[32mPASS[0m in 1.93s]
[2025-05-27T21:38:33.920+0000] {utils.py:78} INFO - [0m21:38:33  44 of 70 START test not_null_stg_pages_page_title .............................. [RUN]
[2025-05-27T21:38:34.139+0000] {utils.py:78} INFO - [0m21:38:34  45 of 70 START test not_null_stg_pages_page_url ................................ [RUN]
[2025-05-27T21:38:34.928+0000] {utils.py:78} INFO - [0m21:38:34  42 of 70 PASS not_null_stg_forms_form_type ..................................... [[32mPASS[0m in 1.51s]
[2025-05-27T21:38:35.847+0000] {utils.py:78} INFO - [0m21:38:35  43 of 70 PASS not_null_stg_pages_page_id ....................................... [[32mPASS[0m in 2.30s]
[2025-05-27T21:38:35.964+0000] {utils.py:78} INFO - [0m21:38:35  46 of 70 START test not_null_stg_website_activity_contact_id ................... [RUN]
[2025-05-27T21:38:36.146+0000] {utils.py:78} INFO - [0m21:38:36  47 of 70 START test not_null_stg_website_activity_event_date ................... [RUN]
[2025-05-27T21:38:36.352+0000] {utils.py:78} INFO - [0m21:38:36  44 of 70 PASS not_null_stg_pages_page_title .................................... [[32mPASS[0m in 2.38s]
[2025-05-27T21:38:36.564+0000] {utils.py:78} INFO - [0m21:38:36  45 of 70 PASS not_null_stg_pages_page_url ...................................... [[32mPASS[0m in 2.20s]
[2025-05-27T21:38:36.572+0000] {utils.py:78} INFO - [0m21:38:36  48 of 70 START test not_null_stg_website_activity_pages_viewed ................. [RUN]
[2025-05-27T21:38:36.610+0000] {utils.py:78} INFO - [0m21:38:36  49 of 70 START test not_null_stg_website_activity_session_duration ............. [RUN]
[2025-05-27T21:38:38.480+0000] {utils.py:78} INFO - [0m21:38:38  46 of 70 PASS not_null_stg_website_activity_contact_id ......................... [[32mPASS[0m in 2.47s]
[2025-05-27T21:38:38.981+0000] {utils.py:78} INFO - [0m21:38:38  47 of 70 PASS not_null_stg_website_activity_event_date ......................... [[32mPASS[0m in 2.81s]
[2025-05-27T21:38:39.990+0000] {utils.py:78} INFO - [0m21:38:39  50 of 70 START test not_null_stg_website_activity_session_id ................... [RUN]
[2025-05-27T21:38:40.898+0000] {utils.py:78} INFO - [0m21:38:40  51 of 70 START test relationships_mart_form_fills_contact_id__contact_id__ref_mart_contacts_  [RUN]
[2025-05-27T21:38:41.928+0000] {utils.py:78} INFO - [0m21:38:41  49 of 70 PASS not_null_stg_website_activity_session_duration ................... [[32mPASS[0m in 5.30s]
[2025-05-27T21:38:41.964+0000] {utils.py:78} INFO - [0m21:38:41  48 of 70 PASS not_null_stg_website_activity_pages_viewed ....................... [[32mPASS[0m in 5.42s]
[2025-05-27T21:38:41.987+0000] {utils.py:78} INFO - [0m21:38:41  50 of 70 PASS not_null_stg_website_activity_session_id ......................... [[32mPASS[0m in 1.42s]
[2025-05-27T21:38:42.048+0000] {utils.py:78} INFO - [0m21:38:42  52 of 70 START test relationships_mart_website_activity_contact_id__contact_id__ref_mart_contacts_  [RUN]
[2025-05-27T21:38:42.088+0000] {utils.py:78} INFO - [0m21:38:42  53 of 70 START test relationships_stg_campaigns_campaign_name__campaign_id__ref_stg_campaigns_  [RUN]
[2025-05-27T21:38:42.109+0000] {utils.py:78} INFO - [0m21:38:42  54 of 70 START test relationships_stg_form_fills_contact_id__contact_id__ref_stg_contacts_  [RUN]
[2025-05-27T21:38:42.842+0000] {utils.py:78} INFO - [0m21:38:42  51 of 70 PASS relationships_mart_form_fills_contact_id__contact_id__ref_mart_contacts_  [[32mPASS[0m in 1.75s]
[2025-05-27T21:38:43.137+0000] {utils.py:78} INFO - [0m21:38:43  55 of 70 START test relationships_stg_website_activity_contact_id__contact_id__ref_stg_contacts_  [RUN]
[2025-05-27T21:38:43.777+0000] {utils.py:78} INFO - [0m21:38:43  53 of 70 FAIL 3 relationships_stg_campaigns_campaign_name__campaign_id__ref_stg_campaigns_  [[31mFAIL 3[0m in 1.36s]
[2025-05-27T21:38:43.858+0000] {utils.py:78} INFO - [0m21:38:43  56 of 70 START test unique_mart_campaigns_campaign_id .......................... [RUN]
[2025-05-27T21:38:43.949+0000] {utils.py:78} INFO - [0m21:38:43  52 of 70 PASS relationships_mart_website_activity_contact_id__contact_id__ref_mart_contacts_  [[32mPASS[0m in 1.86s]
[2025-05-27T21:38:44.092+0000] {utils.py:78} INFO - [0m21:38:44  57 of 70 START test unique_mart_contacts_contact_id ............................ [RUN]
[2025-05-27T21:38:44.218+0000] {utils.py:78} INFO - [0m21:38:44  54 of 70 PASS relationships_stg_form_fills_contact_id__contact_id__ref_stg_contacts_  [[32mPASS[0m in 1.60s]
[2025-05-27T21:38:45.022+0000] {local_task_job_runner.py:302} WARNING - State of this instance has been externally set to restarting. Terminating instance.
[2025-05-27T21:38:44.826+0000] {utils.py:78} INFO - [0m21:38:44  55 of 70 PASS relationships_stg_website_activity_contact_id__contact_id__ref_stg_contacts_  [[32mPASS[0m in 1.65s]
[2025-05-27T21:38:45.461+0000] {process_utils.py:131} INFO - Sending 15 to group 597. PIDs of all processes in the group: [598, 599, 605, 597]
[2025-05-27T21:38:45.491+0000] {process_utils.py:86} INFO - Sending the signal 15 to group 597
[2025-05-27T21:38:45.535+0000] {taskinstance.py:2450} ERROR - Received SIGTERM. Terminating subprocesses.
[2025-05-27T21:38:45.968+0000] {taskinstance.py:2698} ERROR - Task failed with exception
Traceback (most recent call last):
  File "/home/airflow/.local/lib/python3.10/site-packages/airflow/models/taskinstance.py", line 433, in _execute_task
    result = execute_callable(context=context, **execute_callable_kwargs)
  File "/home/airflow/.local/lib/python3.10/site-packages/airflow/operators/python.py", line 199, in execute
    return_value = self.execute_callable()
  File "/home/airflow/.local/lib/python3.10/site-packages/airflow/operators/python.py", line 216, in execute_callable
    return self.python_callable(*self.op_args, **self.op_kwargs)
  File "/opt/airflow/dags/Marketing_Data_Pipeline.py", line 40, in _wrapped
    fn(**kwargs)
  File "/opt/airflow/scripts/utils.py", line 88, in run_dbt_test
    run_dbt(cmd)
  File "/opt/airflow/scripts/utils.py", line 77, in run_dbt
    for line in process.stdout:
  File "/home/airflow/.local/lib/python3.10/site-packages/airflow/models/taskinstance.py", line 2452, in signal_handler
    raise AirflowException("Task received SIGTERM signal")
airflow.exceptions.AirflowException: Task received SIGTERM signal
[2025-05-27T21:38:46.372+0000] {taskinstance.py:1138} INFO - Marking task as UP_FOR_RETRY. dag_id=Marketing_Data_Pipeline, task_id=dbt_run.dbt_test, execution_date=20250524T000000, start_date=20250527T213054, end_date=20250527T213846
[2025-05-27T21:38:46.712+0000] {standard_task_runner.py:107} ERROR - Failed to execute job 30 for task dbt_run.dbt_test (Task received SIGTERM signal; 597)
[2025-05-27T21:38:46.801+0000] {process_utils.py:79} INFO - Process psutil.Process(pid=597, status='terminated', exitcode=1, started='21:30:54') (597) terminated with exit code 1
[2025-05-27T21:39:45.527+0000] {process_utils.py:149} WARNING - process psutil.Process(pid=605, name='python', status='zombie', started='21:31:00') did not respond to SIGTERM. Trying SIGKILL
[2025-05-27T21:39:45.981+0000] {process_utils.py:149} WARNING - process psutil.Process(pid=598, name='sh', status='zombie', started='21:30:54') did not respond to SIGTERM. Trying SIGKILL
[2025-05-27T21:39:45.982+0000] {process_utils.py:149} WARNING - process psutil.Process(pid=599, name='dbt', status='zombie', started='21:30:54') did not respond to SIGTERM. Trying SIGKILL
[2025-05-27T21:39:45.985+0000] {process_utils.py:86} INFO - Sending the signal 9 to group 597
[2025-05-27T21:40:46.020+0000] {process_utils.py:160} ERROR - Process psutil.Process(pid=605, name='python', status='zombie', started='21:31:00') (605) could not be killed. Giving up.
[2025-05-27T21:40:46.021+0000] {process_utils.py:160} ERROR - Process psutil.Process(pid=598, name='sh', status='zombie', started='21:30:54') (598) could not be killed. Giving up.
[2025-05-27T21:40:46.022+0000] {process_utils.py:160} ERROR - Process psutil.Process(pid=599, name='dbt', status='zombie', started='21:30:54') (599) could not be killed. Giving up.
