[2025-05-24T07:24:00.431+0000] {taskinstance.py:1956} INFO - Dependencies all met for dep_context=non-requeueable deps ti=<TaskInstance: marketing_data_pipeline.generate_contacts scheduled__2025-05-23T00:00:00+00:00 [queued]>
[2025-05-24T07:24:00.482+0000] {taskinstance.py:1956} INFO - Dependencies all met for dep_context=requeueable deps ti=<TaskInstance: marketing_data_pipeline.generate_contacts scheduled__2025-05-23T00:00:00+00:00 [queued]>
[2025-05-24T07:24:00.492+0000] {taskinstance.py:2170} INFO - Starting attempt 1 of 2
[2025-05-24T07:24:00.681+0000] {taskinstance.py:2191} INFO - Executing <Task(PythonOperator): generate_contacts> on 2025-05-23 00:00:00+00:00
[2025-05-24T07:24:00.710+0000] {standard_task_runner.py:60} INFO - Started process 643 to run task
[2025-05-24T07:24:00.739+0000] {standard_task_runner.py:87} INFO - Running: ['***', 'tasks', 'run', 'marketing_data_pipeline', 'generate_contacts', 'scheduled__2025-05-23T00:00:00+00:00', '--job-id', '12', '--raw', '--subdir', 'DAGS_FOLDER/main_pipeline_dag.py', '--cfg-path', '/tmp/tmpgmpfk5p5']
[2025-05-24T07:24:00.745+0000] {standard_task_runner.py:88} INFO - Job 12: Subtask generate_contacts
[2025-05-24T07:24:01.125+0000] {task_command.py:423} INFO - Running <TaskInstance: marketing_data_pipeline.generate_contacts scheduled__2025-05-23T00:00:00+00:00 [running]> on host fcb3825e40cf
[2025-05-24T07:24:01.607+0000] {taskinstance.py:2480} INFO - Exporting env vars: AIRFLOW_CTX_DAG_EMAIL='yashbhawsar872@gmail.com' AIRFLOW_CTX_DAG_OWNER='Yash' AIRFLOW_CTX_DAG_ID='marketing_data_pipeline' AIRFLOW_CTX_TASK_ID='generate_contacts' AIRFLOW_CTX_EXECUTION_DATE='2025-05-23T00:00:00+00:00' AIRFLOW_CTX_TRY_NUMBER='1' AIRFLOW_CTX_DAG_RUN_ID='scheduled__2025-05-23T00:00:00+00:00'
[2025-05-24T07:24:01.663+0000] {main_pipeline_dag.py:25} INFO - ‚ñ∂Ô∏è Starting task: Generate Contacts
[2025-05-24T07:24:01.771+0000] {taskinstance.py:2698} ERROR - Task failed with exception
Traceback (most recent call last):
  File "/home/airflow/.local/lib/python3.10/site-packages/airflow/models/taskinstance.py", line 433, in _execute_task
    result = execute_callable(context=context, **execute_callable_kwargs)
  File "/home/airflow/.local/lib/python3.10/site-packages/airflow/operators/python.py", line 199, in execute
    return_value = self.execute_callable()
  File "/home/airflow/.local/lib/python3.10/site-packages/airflow/operators/python.py", line 216, in execute_callable
    return self.python_callable(*self.op_args, **self.op_kwargs)
  File "/opt/airflow/dags/main_pipeline_dag.py", line 26, in _wrapped
    fn(**kwargs)
TypeError: generate_contacts_if_needed() got an unexpected keyword argument 'conf'
[2025-05-24T07:24:02.008+0000] {taskinstance.py:1138} INFO - Marking task as UP_FOR_RETRY. dag_id=marketing_data_pipeline, task_id=generate_contacts, execution_date=20250523T000000, start_date=20250524T072400, end_date=20250524T072402
[2025-05-24T07:24:02.230+0000] {standard_task_runner.py:107} ERROR - Failed to execute job 12 for task generate_contacts (generate_contacts_if_needed() got an unexpected keyword argument 'conf'; 643)
[2025-05-24T07:24:02.972+0000] {local_task_job_runner.py:234} INFO - Task exited with return code 1
[2025-05-24T07:24:03.403+0000] {taskinstance.py:3280} INFO - 0 downstream tasks scheduled from follow-on schedule check
[2025-05-24T07:26:02.339+0000] {taskinstance.py:1956} INFO - Dependencies all met for dep_context=non-requeueable deps ti=<TaskInstance: marketing_data_pipeline.generate_contacts scheduled__2025-05-23T00:00:00+00:00 [queued]>
[2025-05-24T07:26:02.368+0000] {taskinstance.py:1956} INFO - Dependencies all met for dep_context=requeueable deps ti=<TaskInstance: marketing_data_pipeline.generate_contacts scheduled__2025-05-23T00:00:00+00:00 [queued]>
[2025-05-24T07:26:02.370+0000] {taskinstance.py:2170} INFO - Starting attempt 1 of 2
[2025-05-24T07:26:02.442+0000] {taskinstance.py:2191} INFO - Executing <Task(PythonOperator): generate_contacts> on 2025-05-23 00:00:00+00:00
[2025-05-24T07:26:02.463+0000] {standard_task_runner.py:60} INFO - Started process 695 to run task
[2025-05-24T07:26:02.484+0000] {standard_task_runner.py:87} INFO - Running: ['***', 'tasks', 'run', 'marketing_data_pipeline', 'generate_contacts', 'scheduled__2025-05-23T00:00:00+00:00', '--job-id', '15', '--raw', '--subdir', 'DAGS_FOLDER/main_pipeline_dag.py', '--cfg-path', '/tmp/tmpt_nrdnut']
[2025-05-24T07:26:02.494+0000] {standard_task_runner.py:88} INFO - Job 15: Subtask generate_contacts
[2025-05-24T07:26:02.945+0000] {task_command.py:423} INFO - Running <TaskInstance: marketing_data_pipeline.generate_contacts scheduled__2025-05-23T00:00:00+00:00 [running]> on host fcb3825e40cf
[2025-05-24T07:26:03.964+0000] {taskinstance.py:2480} INFO - Exporting env vars: AIRFLOW_CTX_DAG_EMAIL='yashbhawsar872@gmail.com' AIRFLOW_CTX_DAG_OWNER='Yash' AIRFLOW_CTX_DAG_ID='marketing_data_pipeline' AIRFLOW_CTX_TASK_ID='generate_contacts' AIRFLOW_CTX_EXECUTION_DATE='2025-05-23T00:00:00+00:00' AIRFLOW_CTX_TRY_NUMBER='1' AIRFLOW_CTX_DAG_RUN_ID='scheduled__2025-05-23T00:00:00+00:00'
[2025-05-24T07:26:03.975+0000] {main_pipeline_dag.py:25} INFO - ‚ñ∂Ô∏è Starting task: Generate Contacts
[2025-05-24T07:26:03.994+0000] {taskinstance.py:2698} ERROR - Task failed with exception
Traceback (most recent call last):
  File "/home/airflow/.local/lib/python3.10/site-packages/airflow/models/taskinstance.py", line 433, in _execute_task
    result = execute_callable(context=context, **execute_callable_kwargs)
  File "/home/airflow/.local/lib/python3.10/site-packages/airflow/operators/python.py", line 199, in execute
    return_value = self.execute_callable()
  File "/home/airflow/.local/lib/python3.10/site-packages/airflow/operators/python.py", line 216, in execute_callable
    return self.python_callable(*self.op_args, **self.op_kwargs)
  File "/opt/airflow/dags/main_pipeline_dag.py", line 26, in _wrapped
    fn(**kwargs)
TypeError: generate_contacts_if_needed() got an unexpected keyword argument 'conf'
[2025-05-24T07:26:04.229+0000] {taskinstance.py:1138} INFO - Marking task as UP_FOR_RETRY. dag_id=marketing_data_pipeline, task_id=generate_contacts, execution_date=20250523T000000, start_date=20250524T072602, end_date=20250524T072604
[2025-05-24T07:26:04.323+0000] {standard_task_runner.py:107} ERROR - Failed to execute job 15 for task generate_contacts (generate_contacts_if_needed() got an unexpected keyword argument 'conf'; 695)
[2025-05-24T07:26:04.425+0000] {local_task_job_runner.py:234} INFO - Task exited with return code 1
[2025-05-24T07:26:04.732+0000] {taskinstance.py:3280} INFO - 0 downstream tasks scheduled from follow-on schedule check
[2025-05-24T08:18:27.866+0000] {taskinstance.py:1956} INFO - Dependencies all met for dep_context=non-requeueable deps ti=<TaskInstance: marketing_data_pipeline.generate_contacts scheduled__2025-05-23T00:00:00+00:00 [queued]>
[2025-05-24T08:18:27.946+0000] {taskinstance.py:1956} INFO - Dependencies all met for dep_context=requeueable deps ti=<TaskInstance: marketing_data_pipeline.generate_contacts scheduled__2025-05-23T00:00:00+00:00 [queued]>
[2025-05-24T08:18:27.976+0000] {taskinstance.py:2170} INFO - Starting attempt 1 of 2
[2025-05-24T08:18:28.146+0000] {taskinstance.py:2191} INFO - Executing <Task(PythonOperator): generate_contacts> on 2025-05-23 00:00:00+00:00
[2025-05-24T08:18:28.221+0000] {standard_task_runner.py:60} INFO - Started process 317 to run task
[2025-05-24T08:18:28.241+0000] {standard_task_runner.py:87} INFO - Running: ['***', 'tasks', 'run', 'marketing_data_pipeline', 'generate_contacts', 'scheduled__2025-05-23T00:00:00+00:00', '--job-id', '6', '--raw', '--subdir', 'DAGS_FOLDER/main_pipeline_dag.py', '--cfg-path', '/tmp/tmp0xfyzwcc']
[2025-05-24T08:18:28.417+0000] {standard_task_runner.py:88} INFO - Job 6: Subtask generate_contacts
[2025-05-24T08:18:29.349+0000] {task_command.py:423} INFO - Running <TaskInstance: marketing_data_pipeline.generate_contacts scheduled__2025-05-23T00:00:00+00:00 [running]> on host e6492150ec46
[2025-05-24T08:18:30.516+0000] {taskinstance.py:2480} INFO - Exporting env vars: AIRFLOW_CTX_DAG_EMAIL='yashbhawsar872@gmail.com' AIRFLOW_CTX_DAG_OWNER='Yash' AIRFLOW_CTX_DAG_ID='marketing_data_pipeline' AIRFLOW_CTX_TASK_ID='generate_contacts' AIRFLOW_CTX_EXECUTION_DATE='2025-05-23T00:00:00+00:00' AIRFLOW_CTX_TRY_NUMBER='1' AIRFLOW_CTX_DAG_RUN_ID='scheduled__2025-05-23T00:00:00+00:00'
[2025-05-24T08:18:30.538+0000] {main_pipeline_dag.py:25} INFO - ‚ñ∂Ô∏è Starting task: Generate Contacts
[2025-05-24T08:18:39.880+0000] {data_generation.py:73} INFO - ‚úÖ contacts_2025-05-23.csv file generated
[2025-05-24T08:18:40.208+0000] {metadata.py:107} INFO - üìù Logged stage 'generated' for contacts_2025-05-23.csv at 2025-05-24T08:18:39.911886
[2025-05-24T08:18:40.213+0000] {main_pipeline_dag.py:27} INFO - ‚úÖ Completed task: Generate Contacts
[2025-05-24T08:18:40.218+0000] {python.py:201} INFO - Done. Returned value was: None
[2025-05-24T08:18:40.270+0000] {taskinstance.py:1138} INFO - Marking task as SUCCESS. dag_id=marketing_data_pipeline, task_id=generate_contacts, execution_date=20250523T000000, start_date=20250524T081827, end_date=20250524T081840
[2025-05-24T08:18:40.355+0000] {local_task_job_runner.py:234} INFO - Task exited with return code 0
[2025-05-24T08:18:40.446+0000] {taskinstance.py:3280} INFO - 1 downstream tasks scheduled from follow-on schedule check
[2025-05-24T10:16:57.230+0000] {taskinstance.py:1956} INFO - Dependencies all met for dep_context=non-requeueable deps ti=<TaskInstance: marketing_data_pipeline.generate_contacts scheduled__2025-05-23T00:00:00+00:00 [queued]>
[2025-05-24T10:16:57.329+0000] {taskinstance.py:1956} INFO - Dependencies all met for dep_context=requeueable deps ti=<TaskInstance: marketing_data_pipeline.generate_contacts scheduled__2025-05-23T00:00:00+00:00 [queued]>
[2025-05-24T10:16:57.330+0000] {taskinstance.py:2170} INFO - Starting attempt 1 of 2
[2025-05-24T10:16:57.406+0000] {taskinstance.py:2191} INFO - Executing <Task(PythonOperator): generate_contacts> on 2025-05-23 00:00:00+00:00
[2025-05-24T10:16:57.416+0000] {standard_task_runner.py:60} INFO - Started process 344 to run task
[2025-05-24T10:16:57.467+0000] {standard_task_runner.py:87} INFO - Running: ['***', 'tasks', 'run', 'marketing_data_pipeline', 'generate_contacts', 'scheduled__2025-05-23T00:00:00+00:00', '--job-id', '5', '--raw', '--subdir', 'DAGS_FOLDER/main_pipeline_dag.py', '--cfg-path', '/tmp/tmpxmqgu6pd']
[2025-05-24T10:16:57.471+0000] {standard_task_runner.py:88} INFO - Job 5: Subtask generate_contacts
[2025-05-24T10:17:09.374+0000] {task_command.py:423} INFO - Running <TaskInstance: marketing_data_pipeline.generate_contacts scheduled__2025-05-23T00:00:00+00:00 [running]> on host 8c3b47b76f3b
[2025-05-24T10:17:11.726+0000] {taskinstance.py:2480} INFO - Exporting env vars: AIRFLOW_CTX_DAG_EMAIL='yashbhawsar872@gmail.com' AIRFLOW_CTX_DAG_OWNER='Yash' AIRFLOW_CTX_DAG_ID='marketing_data_pipeline' AIRFLOW_CTX_TASK_ID='generate_contacts' AIRFLOW_CTX_EXECUTION_DATE='2025-05-23T00:00:00+00:00' AIRFLOW_CTX_TRY_NUMBER='1' AIRFLOW_CTX_DAG_RUN_ID='scheduled__2025-05-23T00:00:00+00:00'
[2025-05-24T10:17:11.735+0000] {main_pipeline_dag.py:25} INFO - ‚ñ∂Ô∏è Starting task: Generate Contacts
[2025-05-24T10:17:23.111+0000] {data_generation.py:73} INFO - ‚úÖ contacts_2025-05-23.csv file generated
[2025-05-24T10:17:25.542+0000] {metadata.py:107} INFO - üìù Logged stage 'generated' for contacts_2025-05-23.csv at 2025-05-24T10:17:23.790161
[2025-05-24T10:17:25.622+0000] {main_pipeline_dag.py:27} INFO - ‚úÖ Completed task: Generate Contacts
[2025-05-24T10:17:25.898+0000] {python.py:201} INFO - Done. Returned value was: None
[2025-05-24T10:17:26.073+0000] {taskinstance.py:1138} INFO - Marking task as SUCCESS. dag_id=marketing_data_pipeline, task_id=generate_contacts, execution_date=20250523T000000, start_date=20250524T101657, end_date=20250524T101726
[2025-05-24T10:17:26.583+0000] {local_task_job_runner.py:234} INFO - Task exited with return code 0
[2025-05-24T10:17:26.973+0000] {taskinstance.py:3280} INFO - 1 downstream tasks scheduled from follow-on schedule check
