[2025-05-24T07:31:22.275+0000] {taskinstance.py:1956} INFO - Dependencies all met for dep_context=non-requeueable deps ti=<TaskInstance: marketing_data_pipeline.generate_contacts scheduled__2025-05-23T00:00:00+00:00 [queued]>
[2025-05-24T07:31:22.341+0000] {taskinstance.py:1956} INFO - Dependencies all met for dep_context=requeueable deps ti=<TaskInstance: marketing_data_pipeline.generate_contacts scheduled__2025-05-23T00:00:00+00:00 [queued]>
[2025-05-24T07:31:22.346+0000] {taskinstance.py:2170} INFO - Starting attempt 2 of 2
[2025-05-24T07:31:22.588+0000] {taskinstance.py:2191} INFO - Executing <Task(PythonOperator): generate_contacts> on 2025-05-23 00:00:00+00:00
[2025-05-24T07:31:22.612+0000] {standard_task_runner.py:60} INFO - Started process 807 to run task
[2025-05-24T07:31:22.644+0000] {standard_task_runner.py:87} INFO - Running: ['***', 'tasks', 'run', 'marketing_data_pipeline', 'generate_contacts', 'scheduled__2025-05-23T00:00:00+00:00', '--job-id', '18', '--raw', '--subdir', 'DAGS_FOLDER/main_pipeline_dag.py', '--cfg-path', '/tmp/tmpur7g6uzo']
[2025-05-24T07:31:22.678+0000] {standard_task_runner.py:88} INFO - Job 18: Subtask generate_contacts
[2025-05-24T07:31:23.366+0000] {task_command.py:423} INFO - Running <TaskInstance: marketing_data_pipeline.generate_contacts scheduled__2025-05-23T00:00:00+00:00 [running]> on host fcb3825e40cf
[2025-05-24T07:31:24.269+0000] {taskinstance.py:2480} INFO - Exporting env vars: AIRFLOW_CTX_DAG_EMAIL='yashbhawsar872@gmail.com' AIRFLOW_CTX_DAG_OWNER='Yash' AIRFLOW_CTX_DAG_ID='marketing_data_pipeline' AIRFLOW_CTX_TASK_ID='generate_contacts' AIRFLOW_CTX_EXECUTION_DATE='2025-05-23T00:00:00+00:00' AIRFLOW_CTX_TRY_NUMBER='2' AIRFLOW_CTX_DAG_RUN_ID='scheduled__2025-05-23T00:00:00+00:00'
[2025-05-24T07:31:24.274+0000] {main_pipeline_dag.py:25} INFO - ‚ñ∂Ô∏è Starting task: Generate Contacts
[2025-05-24T07:31:24.376+0000] {taskinstance.py:2698} ERROR - Task failed with exception
Traceback (most recent call last):
  File "/home/airflow/.local/lib/python3.10/site-packages/airflow/models/taskinstance.py", line 433, in _execute_task
    result = execute_callable(context=context, **execute_callable_kwargs)
  File "/home/airflow/.local/lib/python3.10/site-packages/airflow/operators/python.py", line 199, in execute
    return_value = self.execute_callable()
  File "/home/airflow/.local/lib/python3.10/site-packages/airflow/operators/python.py", line 216, in execute_callable
    return self.python_callable(*self.op_args, **self.op_kwargs)
  File "/opt/airflow/dags/main_pipeline_dag.py", line 26, in _wrapped
    fn(**kwargs)
  File "/opt/airflow/scripts/data_generation.py", line 25, in generate_contacts_if_needed
    if not check_stage_complete(file_name, "generated"):
  File "/opt/airflow/scripts/metadata.py", line 119, in check_stage_complete
    c.execute(f"SELECT {stage}_at FROM file_metadata WHERE file_name = ?", (file_name,))
sqlite3.OperationalError: no such column: generated_at
[2025-05-24T07:31:24.502+0000] {taskinstance.py:1138} INFO - Marking task as FAILED. dag_id=marketing_data_pipeline, task_id=generate_contacts, execution_date=20250523T000000, start_date=20250524T073122, end_date=20250524T073124
[2025-05-24T07:31:24.504+0000] {email_notification.py:54} WARNING - üìß Sending generic failure email [Airflow] Failure in marketing_data_pipeline.generate_contacts (Attempt 3/1)
[2025-05-24T07:31:24.564+0000] {logging_mixin.py:188} WARNING - /home/***/.local/lib/python3.10/site-packages/***/utils/email.py:154 RemovedInAirflow3Warning: Fetching SMTP credentials from configuration variables will be deprecated in a future release. Please set credentials using a connection instead.
[2025-05-24T07:31:24.566+0000] {email.py:270} INFO - Email alerting: attempt 1
[2025-05-24T07:31:26.446+0000] {email.py:281} INFO - Sent an alert email to ['yashbhawsar872@gmail.com']
[2025-05-24T07:31:28.687+0000] {standard_task_runner.py:107} ERROR - Failed to execute job 18 for task generate_contacts (no such column: generated_at; 807)
[2025-05-24T07:31:28.781+0000] {local_task_job_runner.py:234} INFO - Task exited with return code 1
[2025-05-24T07:31:29.207+0000] {taskinstance.py:3280} INFO - 0 downstream tasks scheduled from follow-on schedule check
